Workbook
Name InitialInvestment: Headlines!$B$5
Name PlanPrice: Headlines!$B$8
Name CAC: Headlines!$B$9
Name MonthlyChurn: Headlines!$B$10
Name PaymentFee: Headlines!$B$11
Name ProviderPay: Headlines!$B$12
Name OpsPerCustomer: Headlines!$B$13
Name MonthlyFixed: Headlines!$B$14
Name MarketingPerMonth: Headlines!$B$15
Name VATRate: Headlines!$B$18
Name VATThreshold: Headlines!$B$19
Name InflationRate: Headlines!$B$20
Name LaunchMonth: Headlines!$B$21
Name SeasonTable: Headlines!$A$41:$B$52
Name ChurnSeasonTable: Headlines!$A$41:$C$52

Sheet Headlines
A1: GardensSorted — Simplified Forecast
A2: Edit yellow cells below. Open in Excel or Google Sheets for live formulas.
A4: INPUTS
A5: Initial investment (£) | B5: 17000 | C5: Starting cash balance
A7: SUBSCRIPTION & UNIT ECONOMICS
A8: Monthly plan price (£/mo) | B8: 54.95 | C8: Single plan — monthly billing only
A9: Customer Acquisition Cost — CAC (£) | B9: 70 | C9: Paid acquisition per customer
A10: Monthly churn (%/mo) | B10: 0.055 | C10: Applied after 3-month minimum term
A11: Payment processing fee (%) | B11: 0.03 | C11: Stripe/card fees
A12: Provider pay per customer (£/mo) | B12: 20 | C12: Paid to service provider per visit (×1 visit/mo at launch offer)
A13: Ops cost per customer (£/mo) | B13: 5 | C13: Support, hosting, AI per active sub
A14: Flat platform cost (£/mo) | B14: 250 | C14: Hosting, tools — fixed overhead
A15: Marketing spend (£/mo) | B15: 3000 | C15: Flat monthly marketing budget
A17: VAT & INFLATION
A18: VAT rate (%) | B18: 0.2 | C18: Standard rate once registered
A19: VAT registration threshold (£) | B19: 90000 | C19: Rolling 12-month gross turnover
A20: Annual price increase / inflation (%) | B20: 0.025 | C20: Applied each model year
A21: Launch calendar month (1=Jan … 12=Dec) | B21: 3 | C21: March = pre-season launch
A23: KEY METRICS
A24: Metric | B24: Year 1 | C24: Year 2 | D24: Year 5
A25: End customers | B25: =Model!I16 | C25: =Model!I28 | D25: =Model!I64
A26: MRR | B26: =Model!J16 | C26: =Model!J28 | D26: =Model!J64
A27: ARR | B27: =Model!K16 | C27: =Model!K28 | D27: =Model!K64
A28: Gross revenue | B28: =SUM(Model!L5:L16) | C28: =SUM(Model!L17:L28) | D28: =SUM(Model!L53:L64)
A29: Net revenue | B29: =SUM(Model!O5:O16) | C29: =SUM(Model!O17:O28) | D29: =SUM(Model!O53:O64)
A30: Annual profit | B30: =SUM(Model!W5:W16) | C30: =SUM(Model!W17:W28) | D30: =SUM(Model!W53:W64)
A31: Cash balance | B31: =Model!X16 | C31: =Model!X28 | D31: =Model!X64
A32: Avg logo churn | B32: =AVERAGE(Model!Y6:Y16) | C32: =AVERAGE(Model!Y18:Y28) | D32: =AVERAGE(Model!Y54:Y64)
A34: MILESTONES
A35: VAT registration | B35: =IFERROR("Month "&MINIFS(Model!A5:A64,Model!N5:N64,1),"Not in 60 months")
A36: First profitable month | B36: =IFERROR("Month "&MINIFS(Model!A5:A64,Model!W5:W64,">0"),"Not in 60 months")
A37: Cash payback (initial investment) | B37: =IFERROR("Month "&MINIFS(Model!A5:A64,Model!X5:X64,">="&Headlines!$B$5),"Not reached")
A39: SEASONALITY (calendar month multipliers)
A40: Month | B40: Acq mult | C40: Churn mult | D40: Notes
A41: 1 | B41: 0.56 | C41: 1.37 | D41: Low
A42: 2 | B42: 0.66 | C42: 1.28 | D42: Pre-season
A43: 3 | B43: 0.87 | C43: 1.04 | D43: Spring
A44: 4 | B44: 1.07 | C44: 0.85 | D44: Ramp
A45: 5 | B45: 1.17 | C45: 0.76 | D45: Peak
A46: 6 | B46: 1.22 | C46: 0.71 | D46: Peak
...

Sheet Model
A1: 60-Month Model — Simplified (single plan, flat marketing)
A2: All inputs on Headlines tab
A4: Mo | B4: Cal | C4: CY | D4: Acq | E4: Infl | F4: ECh | G4: Mkt | H4: New | I4: Cust | J4: MRR | K4: ARR | L4: Gross | M4: R12 | N4: VAT? | O4: Net | P4: VAcc | Q4: VPay | R4: Fees | S4: Prov | T4: Ops | U4: Fixed | V4: Mkt$ | W4: Profit | X4: Cash | Y4: Chrn
A5: 1 | B5: =MOD(A5-1+Headlines!$B$21-1,12)+1 | C5: =INT((A5-1+Headlines!$B$21-1)/12)+1 | D5: =VLOOKUP(B5,Headlines!$A$41:$B$52,2,FALSE) | E5: =(1+Headlines!$B$20)^INT((A5-1)/12) | F5: =Headlines!$B$10*VLOOKUP(B5,Headlines!$A$41:$C$52,3,FALSE) | G5: =Headlines!$B$15 | H5: =IF(G5>0,MAX(1,ROUND(G5/Headlines!$B$9*D5,0)),0) | I5: =H5 | J5: =I5*Headlines!$B$8*E5 | K5: =J5*12 | L5: =J5 | M5: =SUM(L$5:L5) | N5: =IF(M5>=Headlines!$B$19,1,0) | O5: =IF(N5,L5/(1+Headlines!$B$18),L5) | P5: =L5-O5 | Q5: =IF(N5=0,0,IF(B5=1,SUMIFS(P$5:P5,C$5:C5,C5-1,B$5:B5,">=10",B$5:B5,"<=12"),IF(B5=4,SUMIFS(P$5:P5,C$5:C5,C5,B$5:B5,">=1",B$5:B5,"<=3"),IF(B5=7,SUMIFS(P$5:P5,C$5:C5,C5,B$5:B5,">=4",B$5:B5,"<=6"),IF(B5=10,SUMIFS(P$5:P5,C$5:C5,C5,B$5:B5,">=7",B$5:B5,"<=9"),0))))) | R5: =L5*Headlines!$B$11 | S5: =I5*Headlines!$B$12 | T5: =I5*Headlines!$B$13 | U5: =Headlines!$B$14 | V5: =G5 | W5: =O5-R5-S5-T5-U5-V5 | X5: =Headlines!$B$5+L5-(R5+S5+T5+U5+V5+Q5) | Y5: =F5
A6: 2 | B6: =MOD(A6-1+Headlines!$B$21-1,12)+1 | C6: =INT((A6-1+Headlines!$B$21-1)/12)+1 | D6: =VLOOKUP(B6,Headlines!$A$41:$B$52,2,FALSE) | E6: =(1+Headlines!$B$20)^INT((A6-1)/12) | F6: =Headlines!$B$10*VLOOKUP(B6,Headlines!$A$41:$C$52,3,FALSE) | G6: =Headlines!$B$15 | H6: =IF(G6>0,MAX(1,ROUND(G6/Headlines!$B$9*D6,0)),0) | I6: =H5+H6 | J6: =I6*Headlines!$B$8*E6 | K6: =J6*12 | L6: =J6 | M6: =SUM(L$5:L6) | N6: =IF(M6>=Headlines!$B$19,1,0) | O6: =IF(N6,L6/(1+Headlines!$B$18),L6) | P6: =L6-O6 | Q6: =IF(N6=0,0,IF(B6=1,SUMIFS(P$5:P6,C$5:C6,C6-1,B$5:B6,">=10",B$5:B6,"<=12"),IF(B6=4,SUMIFS(P$5:P6,C$5:C6,C6,B$5:B6,">=1",B$5:B6,"<=3"),IF(B6=7,SUMIFS(P$5:P6,C$5:C6,C6,B$5:B6,">=4",B$5:B6,"<=6"),IF(B6=10,SUMIFS(P$5:P6,C$5:C6,C6,B$5:B6,">=7",B$5:B6,"<=9"),0))))) | R6: =L6*Headlines!$B$11 | S6: =I6*Headlines!$B$12 | T6: =I6*Headlines!$B$13 | U6: =Headlines!$B$14 | V6: =G6 | W6: =O6-R6-S6-T6-U6-V6 | X6: =X5+L6-(R6+S6+T6+U6+V6+Q6) | Y6: =F6
A7: 3 | B7: =MOD(A7-1+Headlines!$B$21-1,12)+1 | C7: =INT((A7-1+Headlines!$B$21-1)/12)+1 | D7: =VLOOKUP(B7,Headlines!$A$41:$B$52,2,FALSE) | E7: =(1+Headlines!$B$20)^INT((A7-1)/12) | F7: =Headlines!$B$10*VLOOKUP(B7,Headlines!$A$41:$C$52,3,FALSE) | G7: =Headlines!$B$15 | H7: =IF(G7>0,MAX(1,ROUND(G7/Headlines!$B$9*D7,0)),0) | I7: =H5+H6+H7 | J7: =I7*Headlines!$B$8*E7 | K7: =J7*12 | L7: =J7 | M7: =SUM(L$5:L7) | N7: =IF(M7>=Headlines!$B$19,1,0) | O7: =IF(N7,L7/(1+Headlines!$B$18),L7) | P7: =L7-O7 | Q7: =IF(N7=0,0,IF(B7=1,SUMIFS(P$5:P7,C$5:C7,C7-1,B$5:B7,">=10",B$5:B7,"<=12"),IF(B7=4,SUMIFS(P$5:P7,C$5:C7,C7,B$5:B7,">=1",B$5:B7,"<=3"),IF(B7=7,SUMIFS(P$5:P7,C$5:C7,C7,B$5:B7,">=4",B$5:B7,"<=6"),IF(B7=10,SUMIFS(P$5:P7,C$5:C7,C7,B$5:B7,">=7",B$5:B7,"<=9"),0))))) | R7: =L7*Headlines!$B$11 | S7: =I7*Headlines!$B$12 | T7: =I7*Headlines!$B$13 | U7: =Headlines!$B$14 | V7: =G7 | W7: =O7-R7-S7-T7-U7-V7 | X7: =X6+L7-(R7+S7+T7+U7+V7+Q7) | Y7: =F7
A8: 4 | B8: =MOD(A8-1+Headlines!$B$21-1,12)+1 | C8: =INT((A8-1+Headlines!$B$21-1)/12)+1 | D8: =VLOOKUP(B8,Headlines!$A$41:$B$52,2,FALSE) | E8: =(1+Headlines!$B$20)^INT((A8-1)/12) | F8: =Headlines!$B$10*VLOOKUP(B8,Headlines!$A$41:$C$52,3,FALSE) | G8: =Headlines!$B$15 | H8: =IF(G8>0,MAX(1,ROUND(G8/Headlines!$B$9*D8,0)),0) | I8: =H8+H7+H6+MAX(0,I7-H7-H6)*(1-F8) | J8: =I8*Headlines!$B$8*E8 | K8: =J8*12 | L8: =J8 | M8: =SUM(L$5:L8) | N8: =IF(M8>=Headlines!$B$19,1,0) | O8: =IF(N8,L8/(1+Headlines!$B$18),L8) | P8: =L8-O8 | Q8: =IF(N8=0,0,IF(B8=1,SUMIFS(P$5:P8,C$5:C8,C8-1,B$5:B8,">=10",B$5:B8,"<=12"),IF(B8=4,SUMIFS(P$5:P8,C$5:C8,C8,B$5:B8,">=1",B$5:B8,"<=3"),IF(B8=7,SUMIFS(P$5:P8,C$5:C8,C8,B$5:B8,">=4",B$5:B8,"<=6"),IF(B8=10,SUMIFS(P$5:P8,C$5:C8,C8,B$5:B8,">=7",B$5:B8,"<=9"),0))))) | R8: =L8*Headlines!$B$11 | S8: =I8*Headlines!$B$12 | T8: =I8*Headlines!$B$13 | U8: =Headlines!$B$14 | V8: =G8 | W8: =O8-R8-S8-T8-U8-V8 | X8: =X7+L8-(R8+S8+T8+U8+V8+Q8) | Y8: =F8
A9: 5 | B9: =MOD(A9-1+Headlines!$B$21-1,12)+1 | C9: =INT((A9-1+Headlines!$B$21-1)/12)+1 | D9: =VLOOKUP(B9,Headlines!$A$41:$B$52,2,FALSE) | E9: =(1+Headlines!$B$20)^INT((A9-1)/12) | F9: =Headlines!$B$10*VLOOKUP(B9,Headlines!$A$41:$C$52,3,FALSE) | G9: =Headlines!$B$15 | H9: =IF(G9>0,MAX(1,ROUND(G9/Headlines!$B$9*D9,0)),0) | I9: =H9+H8+H7+MAX(0,I8-H8-H7)*(1-F9) | J9: =I9*Headlines!$B$8*E9 | K9: =J9*12 | L9: =J9 | M9: =SUM(L$5:L9) | N9: =IF(M9>=Headlines!$B$19,1,0) | O9: =IF(N9,L9/(1+Headlines!$B$18),L9) | P9: =L9-O9 | Q9: =IF(N9=0,0,IF(B9=1,SUMIFS(P$5:P9,C$5:C9,C9-1,B$5:B9,">=10",B$5:B9,"<=12"),IF(B9=4,SUMIFS(P$5:P9,C$5:C9,C9,B$5:B9,">=1",B$5:B9,"<=3"),IF(B9=7,SUMIFS(P$5:P9,C$5:C9,C9,B$5:B9,">=4",B$5:B9,"<=6"),IF(B9=10,SUMIFS(P$5:P9,C$5:C9,C9,B$5:B9,">=7",B$5:B9,"<=9"),0))))) | R9: =L9*Headlines!$B$11 | S9: =I9*Headlines!$B$12 | T9: =I9*Headlines!$B$13 | U9: =Headlines!$B$14 | V9: =G9 | W9: =O9-R9-S9-T9-U9-V9 | X9: =X8+L9-(R9+S9+T9+U9+V9+Q9) | Y9: =F9
A10: 6 | B10: =MOD(A10-1+Headlines!$B$21-1,12)+1 | C10: =INT((A10-1+Headlines!$B$21-1)/12)+1 | D10: =VLOOKUP(B10,Headlines!$A$41:$B$52,2,FALSE) | E10: =(1+Headlines!$B$20)^INT((A10-1)/12) | F10: =Headlines!$B$10*VLOOKUP(B10,Headlines!$A$41:$C$52,3,FALSE) | G10: =Headlines!$B$15 | H10: =IF(G10>0,MAX(1,ROUND(G10/Headlines!$B$9*D10,0)),0) | I10: =H10+H9+H8+MAX(0,I9-H9-H8)*(1-F10) | J10: =I10*Headlines!$B$8*E10 | K10: =J10*12 | L10: =J10 | M10: =SUM(L$5:L10) | N10: =IF(M10>=Headlines!$B$19,1,0) | O10: =IF(N10,L10/(1+Headlines!$B$18),L10) | P10: =L10-O10 | Q10: =IF(N10=0,0,IF(B10=1,SUMIFS(P$5:P10,C$5:C10,C10-1,B$5:B10,">=10",B$5:B10,"<=12"),IF(B10=4,SUMIFS(P$5:P10,C$5:C10,C10,B$5:B10,">=1",B$5:B10,"<=3"),IF(B10=7,SUMIFS(P$5:P10,C$5:C10,C10,B$5:B10,">=4",B$5:B10,"<=6"),IF(B10=10,SUMIFS(P$5:P10,C$5:C10,C10,B$5:B10,">=7",B$5:B10,"<=9"),0))))) | R10: =L10*Headlines!$B$11 | S10: =I10*Headlines!$B$12 | T10: =I10*Headlines!$B$13 | U10: =Headlines!$B$14 | V10: =G10 | W10: =O10-R10-S10-T10-U10-V10 | X10: =X9+L10-(R10+S10+T10+U10+V10+Q10) | Y10: =F10
A11: 7 | B11: =MOD(A11-1+Headlines!$B$21-1,12)+1 | C11: =INT((A11-1+Headlines!$B$21-1)/12)+1 | D11: =VLOOKUP(B11,Headlines!$A$41:$B$52,2,FALSE) | E11: =(1+Headlines!$B$20)^INT((A11-1)/12) | F11: =Headlines!$B$10*VLOOKUP(B11,Headlines!$A$41:$C$52,3,FALSE) | G11: =Headlines!$B$15 | H11: =IF(G11>0,MAX(1,ROUND(G11/Headlines!$B$9*D11,0)),0) | I11: =H11+H10+H9+MAX(0,I10-H10-H9)*(1-F11) | J11: =I11*Headlines!$B$8*E11 | K11: =J11*12 | L11: =J11 | M11: =SUM(L$5:L11) | N11: =IF(M11>=Headlines!$B$19,1,0) | O11: =IF(N11,L11/(1+Headlines!$B$18),L11) | P11: =L11-O11 | Q11: =IF(N11=0,0,IF(B11=1,SUMIFS(P$5:P11,C$5:C11,C11-1,B$5:B11,">=10",B$5:B11,"<=12"),IF(B11=4,SUMIFS(P$5:P11,C$5:C11,C11,B$5:B11,">=1",B$5:B11,"<=3"),IF(B11=7,SUMIFS(P$5:P11,C$5:C11,C11,B$5:B11,">=4",B$5:B11,"<=6"),IF(B11=10,SUMIFS(P$5:P11,C$5:C11,C11,B$5:B11,">=7",B$5:B11,"<=9"),0))))) | R11: =L11*Headlines!$B$11 | S11: =I11*Headlines!$B$12 | T11: =I11*Headlines!$B$13 | U11: =Headlines!$B$14 | V11: =G11 | W11: =O11-R11-S11-T11-U11-V11 | X11: =X10+L11-(R11+S11+T11+U11+V11+Q11) | Y11: =F11
A12: 8 | B12: =MOD(A12-1+Headlines!$B$21-1,12)+1 | C12: =INT((A12-1+Headlines!$B$21-1)/12)+1 | D12: =VLOOKUP(B12,Headlines!$A$41:$B$52,2,FALSE) | E12: =(1+Headlines!$B$20)^INT((A12-1)/12) | F12: =Headlines!$B$10*VLOOKUP(B12,Headlines!$A$41:$C$52,3,FALSE) | G12: =Headlines!$B$15 | H12: =IF(G12>0,MAX(1,ROUND(G12/Headlines!$B$9*D12,0)),0) | I12: =H12+H11+H10+MAX(0,I11-H11-H10)*(1-F12) | J12: =I12*Headlines!$B$8*E12 | K12: =J12*12 | L12: =J12 | M12: =SUM(L$5:L12) | N12: =IF(M12>=Headlines!$B$19,1,0) | O12: =IF(N12,L12/(1+Headlines!$B$18),L12) | P12: =L12-O12 | Q12: =IF(N12=0,0,IF(B12=1,SUMIFS(P$5:P12,C$5:C12,C12-1,B$5:B12,">=10",B$5:B12,"<=12"),IF(B12=4,SUMIFS(P$5:P12,C$5:C12,C12,B$5:B12,">=1",B$5:B12,"<=3"),IF(B12=7,SUMIFS(P$5:P12,C$5:C12,C12,B$5:B12,">=4",B$5:B12,"<=6"),IF(B12=10,SUMIFS(P$5:P12,C$5:C12,C12,B$5:B12,">=7",B$5:B12,"<=9"),0))))) | R12: =L12*Headlines!$B$11 | S12: =I12*Headlines!$B$12 | T12: =I12*Headlines!$B$13 | U12: =Headlines!$B$14 | V12: =G12 | W12: =O12-R12-S12-T12-U12-V12 | X12: =X11+L12-(R12+S12+T12+U12+V12+Q12) | Y12: =F12
A13: 9 | B13: =MOD(A13-1+Headlines!$B$21-1,12)+1 | C13: =INT((A13-1+Headlines!$B$21-1)/12)+1 | D13: =VLOOKUP(B13,Headlines!$A$41:$B$52,2,FALSE) | E13: =(1+Headlines!$B$20)^INT((A13-1)/12) | F13: =Headlines!$B$10*VLOOKUP(B13,Headlines!$A$41:$C$52,3,FALSE) | G13: =Headlines!$B$15 | H13: =IF(G13>0,MAX(1,ROUND(G13/Headlines!$B$9*D13,0)),0) | I13: =H13+H12+H11+MAX(0,I12-H12-H11)*(1-F13) | J13: =I13*Headlines!$B$8*E13 | K13: =J13*12 | L13: =J13 | M13: =SUM(L$5:L13) | N13: =IF(M13>=Headlines!$B$19,1,0) | O13: =IF(N13,L13/(1+Headlines!$B$18),L13) | P13: =L13-O13 | Q13: =IF(N13=0,0,IF(B13=1,SUMIFS(P$5:P13,C$5:C13,C13-1,B$5:B13,">=10",B$5:B13,"<=12"),IF(B13=4,SUMIFS(P$5:P13,C$5:C13,C13,B$5:B13,">=1",B$5:B13,"<=3"),IF(B13=7,SUMIFS(P$5:P13,C$5:C13,C13,B$5:B13,">=4",B$5:B13,"<=6"),IF(B13=10,SUMIFS(P$5:P13,C$5:C13,C13,B$5:B13,">=7",B$5:B13,"<=9"),0))))) | R13: =L13*Headlines!$B$11 | S13: =I13*Headlines!$B$12 | T13: =I13*Headlines!$B$13 | U13: =Headlines!$B$14 | V13: =G13 | W13: =O13-R13-S13-T13-U13-V13 | X13: =X12+L13-(R13+S13+T13+U13+V13+Q13) | Y13: =F13
A14: 10 | B14: =MOD(A14-1+Headlines!$B$21-1,12)+1 | C14: =INT((A14-1+Headlines!$B$21-1)/12)+1 | D14: =VLOOKUP(B14,Headlines!$A$41:$B$52,2,FALSE) | E14: =(1+Headlines!$B$20)^INT((A14-1)/12) | F14: =Headlines!$B$10*VLOOKUP(B14,Headlines!$A$41:$C$52,3,FALSE) | G14: =Headlines!$B$15 | H14: =IF(G14>0,MAX(1,ROUND(G14/Headlines!$B$9*D14,0)),0) | I14: =H14+H13+H12+MAX(0,I13-H13-H12)*(1-F14) | J14: =I14*Headlines!$B$8*E14 | K14: =J14*12 | L14: =J14 | M14: =SUM(L$5:L14) | N14: =IF(M14>=Headlines!$B$19,1,0) | O14: =IF(N14,L14/(1+Headlines!$B$18),L14) | P14: =L14-O14 | Q14: =IF(N14=0,0,IF(B14=1,SUMIFS(P$5:P14,C$5:C14,C14-1,B$5:B14,">=10",B$5:B14,"<=12"),IF(B14=4,SUMIFS(P$5:P14,C$5:C14,C14,B$5:B14,">=1",B$5:B14,"<=3"),IF(B14=7,SUMIFS(P$5:P14,C$5:C14,C14,B$5:B14,">=4",B$5:B14,"<=6"),IF(B14=10,SUMIFS(P$5:P14,C$5:C14,C14,B$5:B14,">=7",B$5:B14,"<=9"),0))))) | R14: =L14*Headlines!$B$11 | S14: =I14*Headlines!$B$12 | T14: =I14*Headlines!$B$13 | U14: =Headlines!$B$14 | V14: =G14 | W14: =O14-R14-S14-T14-U14-V14 | X14: =X13+L14-(R14+S14+T14+U14+V14+Q14) | Y14: =F14
A15: 11 | B15: =MOD(A15-1+Headlines!$B$21-1,12)+1 | C15: =INT((A15-1+Headlines!$B$21-1)/12)+1 | D15: =VLOOKUP(B15,Headlines!$A$41:$B$52,2,FALSE) | E15: =(1+Headlines!$B$20)^INT((A15-1)/12) | F15: =Headlines!$B$10*VLOOKUP(B15,Headlines!$A$41:$C$52,3,FALSE) | G15: =Headlines!$B$15 | H15: =IF(G15>0,MAX(1,ROUND(G15/Headlines!$B$9*D15,0)),0) | I15: =H15+H14+H13+MAX(0,I14-H14-H13)*(1-F15) | J15: =I15*Headlines!$B$8*E15 | K15: =J15*12 | L15: =J15 | M15: =SUM(L$5:L15) | N15: =IF(M15>=Headlines!$B$19,1,0) | O15: =IF(N15,L15/(1+Headlines!$B$18),L15) | P15: =L15-O15 | Q15: =IF(N15=0,0,IF(B15=1,SUMIFS(P$5:P15,C$5:C15,C15-1,B$5:B15,">=10",B$5:B15,"<=12"),IF(B15=4,SUMIFS(P$5:P15,C$5:C15,C15,B$5:B15,">=1",B$5:B15,"<=3"),IF(B15=7,SUMIFS(P$5:P15,C$5:C15,C15,B$5:B15,">=4",B$5:B15,"<=6"),IF(B15=10,SUMIFS(P$5:P15,C$5:C15,C15,B$5:B15,">=7",B$5:B15,"<=9"),0))))) | R15: =L15*Headlines!$B$11 | S15: =I15*Headlines!$B$12 | T15: =I15*Headlines!$B$13 | U15: =Headlines!$B$14 | V15: =G15 | W15: =O15-R15-S15-T15-U15-V15 | X15: =X14+L15-(R15+S15+T15+U15+V15+Q15) | Y15: =F15
A16: 12 | B16: =MOD(A16-1+Headlines!$B$21-1,12)+1 | C16: =INT((A16-1+Headlines!$B$21-1)/12)+1 | D16: =VLOOKUP(B16,Headlines!$A$41:$B$52,2,FALSE) | E16: =(1+Headlines!$B$20)^INT((A16-1)/12) | F16: =Headlines!$B$10*VLOOKUP(B16,Headlines!$A$41:$C$52,3,FALSE) | G16: =Headlines!$B$15 | H16: =IF(G16>0,MAX(1,ROUND(G16/Headlines!$B$9*D16,0)),0) | I16: =H16+H15+H14+MAX(0,I15-H15-H14)*(1-F16) | J16: =I16*Headlines!$B$8*E16 | K16: =J16*12 | L16: =J16 | M16: =SUM(L5:L16) | N16: =IF(M16>=Headlines!$B$19,1,0) | O16: =IF(N16,L16/(1+Headlines!$B$18),L16) | P16: =L16-O16 | Q16: =IF(N16=0,0,IF(B16=1,SUMIFS(P$5:P16,C$5:C16,C16-1,B$5:B16,">=10",B$5:B16,"<=12"),IF(B16=4,SUMIFS(P$5:P16,C$5:C16,C16,B$5:B16,">=1",B$5:B16,"<=3"),IF(B16=7,SUMIFS(P$5:P16,C$5:C16,C16,B$5:B16,">=4",B$5:B16,"<=6"),IF(B16=10,SUMIFS(P$5:P16,C$5:C16,C16,B$5:B16,">=7",B$5:B16,"<=9"),0))))) | R16: =L16*Headlines!$B$11 | S16: =I16*Headlines!$B$12 | T16: =I16*Headlines!$B$13 | U16: =Headlines!$B$14 | V16: =G16 | W16: =O16-R16-S16-T16-U16-V16 | X16: =X15+L16-(R16+S16+T16+U16+V16+Q16) | Y16: =F16
A17: 13 | B17: =MOD(A17-1+Headlines!$B$21-1,12)+1 | C17: =INT((A17-1+Headlines!$B$21-1)/12)+1 | D17: =VLOOKUP(B17,Headlines!$A$41:$B$52,2,FALSE) | E17: =(1+Headlines!$B$20)^INT((A17-1)/12) | F17: =Headlines!$B$10*VLOOKUP(B17,Headlines!$A$41:$C$52,3,FALSE) | G17: =Headlines!$B$15 | H17: =IF(G17>0,MAX(1,ROUND(G17/Headlines!$B$9*D17,0)),0) | I17: =H17+H16+H15+MAX(0,I16-H16-H15)*(1-F17) | J17: =I17*Headlines!$B$8*E17 | K17: =J17*12 | L17: =J17 | M17: =SUM(L6:L17) | N17: =IF(M17>=Headlines!$B$19,1,0) | O17: =IF(N17,L17/(1+Headlines!$B$18),L17) | P17: =L17-O17 | Q17: =IF(N17=0,0,IF(B17=1,SUMIFS(P$5:P17,C$5:C17,C17-1,B$5:B17,">=10",B$5:B17,"<=12"),IF(B17=4,SUMIFS(P$5:P17,C$5:C17,C17,B$5:B17,">=1",B$5:B17,"<=3"),IF(B17=7,SUMIFS(P$5:P17,C$5:C17,C17,B$5:B17,">=4",B$5:B17,"<=6"),IF(B17=10,SUMIFS(P$5:P17,C$5:C17,C17,B$5:B17,">=7",B$5:B17,"<=9"),0))))) | R17: =L17*Headlines!$B$11 | S17: =I17*Headlines!$B$12 | T17: =I17*Headlines!$B$13 | U17: =Headlines!$B$14 | V17: =G17 | W17: =O17-R17-S17-T17-U17-V17 | X17: =X16+L17-(R17+S17+T17+U17+V17+Q17) | Y17: =F17
A18: 14 | B18: =MOD(A18-1+Headlines!$B$21-1,12)+1 | C18: =INT((A18-1+Headlines!$B$21-1)/12)+1 | D18: =VLOOKUP(B18,Headlines!$A$41:$B$52,2,FALSE) | E18: =(1+Headlines!$B$20)^INT((A18-1)/12) | F18: =Headlines!$B$10*VLOOKUP(B18,Headlines!$A$41:$C$52,3,FALSE) | G18: =Headlines!$B$15 | H18: =IF(G18>0,MAX(1,ROUND(G18/Headlines!$B$9*D18,0)),0) | I18: =H18+H17+H16+MAX(0,I17-H17-H16)*(1-F18) | J18: =I18*Headlines!$B$8*E18 | K18: =J18*12 | L18: =J18 | M18: =SUM(L7:L18) | N18: =IF(M18>=Headlines!$B$19,1,0) | O18: =IF(N18,L18/(1+Headlines!$B$18),L18) | P18: =L18-O18 | Q18: =IF(N18=0,0,IF(B18=1,SUMIFS(P$5:P18,C$5:C18,C18-1,B$5:B18,">=10",B$5:B18,"<=12"),IF(B18=4,SUMIFS(P$5:P18,C$5:C18,C18,B$5:B18,">=1",B$5:B18,"<=3"),IF(B18=7,SUMIFS(P$5:P18,C$5:C18,C18,B$5:B18,">=4",B$5:B18,"<=6"),IF(B18=10,SUMIFS(P$5:P18,C$5:C18,C18,B$5:B18,">=7",B$5:B18,"<=9"),0))))) | R18: =L18*Headlines!$B$11 | S18: =I18*Headlines!$B$12 | T18: =I18*Headlines!$B$13 | U18: =Headlines!$B$14 | V18: =G18 | W18: =O18-R18-S18-T18-U18-V18 | X18: =X17+L18-(R18+S18+T18+U18+V18+Q18) | Y18: =F18
A19: 15 | B19: =MOD(A19-1+Headlines!$B$21-1,12)+1 | C19: =INT((A19-1+Headlines!$B$21-1)/12)+1 | D19: =VLOOKUP(B19,Headlines!$A$41:$B$52,2,FALSE) | E19: =(1+Headlines!$B$20)^INT((A19-1)/12) | F19: =Headlines!$B$10*VLOOKUP(B19,Headlines!$A$41:$C$52,3,FALSE) | G19: =Headlines!$B$15 | H19: =IF(G19>0,MAX(1,ROUND(G19/Headlines!$B$9*D19,0)),0) | I19: =H19+H18+H17+MAX(0,I18-H18-H17)*(1-F19) | J19: =I19*Headlines!$B$8*E19 | K19: =J19*12 | L19: =J19 | M19: =SUM(L8:L19) | N19: =IF(M19>=Headlines!$B$19,1,0) | O19: =IF(N19,L19/(1+Headlines!$B$18),L19) | P19: =L19-O19 | Q19: =IF(N19=0,0,IF(B19=1,SUMIFS(P$5:P19,C$5:C19,C19-1,B$5:B19,">=10",B$5:B19,"<=12"),IF(B19=4,SUMIFS(P$5:P19,C$5:C19,C19,B$5:B19,">=1",B$5:B19,"<=3"),IF(B19=7,SUMIFS(P$5:P19,C$5:C19,C19,B$5:B19,">=4",B$5:B19,"<=6"),IF(B19=10,SUMIFS(P$5:P19,C$5:C19,C19,B$5:B19,">=7",B$5:B19,"<=9"),0))))) | R19: =L19*Headlines!$B$11 | S19: =I19*Headlines!$B$12 | T19: =I19*Headlines!$B$13 | U19: =Headlines!$B$14 | V19: =G19 | W19: =O19-R19-S19-T19-U19-V19 | X19: =X18+L19-(R19+S19+T19+U19+V19+Q19) | Y19: =F19
A20: 16 | B20: =MOD(A20-1+Headlines!$B$21-1,12)+1 | C20: =INT((A20-1+Headlines!$B$21-1)/12)+1 | D20: =VLOOKUP(B20,Headlines!$A$41:$B$52,2,FALSE) | E20: =(1+Headlines!$B$20)^INT((A20-1)/12) | F20: =Headlines!$B$10*VLOOKUP(B20,Headlines!$A$41:$C$52,3,FALSE) | G20: =Headlines!$B$15 | H20: =IF(G20>0,MAX(1,ROUND(G20/Headlines!$B$9*D20,0)),0) | I20: =H20+H19+H18+MAX(0,I19-H19-H18)*(1-F20) | J20: =I20*Headlines!$B$8*E20 | K20: =J20*12 | L20: =J20 | M20: =SUM(L9:L20) | N20: =IF(M20>=Headlines!$B$19,1,0) | O20: =IF(N20,L20/(1+Headlines!$B$18),L20) | P20: =L20-O20 | Q20: =IF(N20=0,0,IF(B20=1,SUMIFS(P$5:P20,C$5:C20,C20-1,B$5:B20,">=10",B$5:B20,"<=12"),IF(B20=4,SUMIFS(P$5:P20,C$5:C20,C20,B$5:B20,">=1",B$5:B20,"<=3"),IF(B20=7,SUMIFS(P$5:P20,C$5:C20,C20,B$5:B20,">=4",B$5:B20,"<=6"),IF(B20=10,SUMIFS(P$5:P20,C$5:C20,C20,B$5:B20,">=7",B$5:B20,"<=9"),0))))) | R20: =L20*Headlines!$B$11 | S20: =I20*Headlines!$B$12 | T20: =I20*Headlines!$B$13 | U20: =Headlines!$B$14 | V20: =G20 | W20: =O20-R20-S20-T20-U20-V20 | X20: =X19+L20-(R20+S20+T20+U20+V20+Q20) | Y20: =F20
A21: 17 | B21: =MOD(A21-1+Headlines!$B$21-1,12)+1 | C21: =INT((A21-1+Headlines!$B$21-1)/12)+1 | D21: =VLOOKUP(B21,Headlines!$A$41:$B$52,2,FALSE) | E21: =(1+Headlines!$B$20)^INT((A21-1)/12) | F21: =Headlines!$B$10*VLOOKUP(B21,Headlines!$A$41:$C$52,3,FALSE) | G21: =Headlines!$B$15 | H21: =IF(G21>0,MAX(1,ROUND(G21/Headlines!$B$9*D21,0)),0) | I21: =H21+H20+H19+MAX(0,I20-H20-H19)*(1-F21) | J21: =I21*Headlines!$B$8*E21 | K21: =J21*12 | L21: =J21 | M21: =SUM(L10:L21) | N21: =IF(M21>=Headlines!$B$19,1,0) | O21: =IF(N21,L21/(1+Headlines!$B$18),L21) | P21: =L21-O21 | Q21: =IF(N21=0,0,IF(B21=1,SUMIFS(P$5:P21,C$5:C21,C21-1,B$5:B21,">=10",B$5:B21,"<=12"),IF(B21=4,SUMIFS(P$5:P21,C$5:C21,C21,B$5:B21,">=1",B$5:B21,"<=3"),IF(B21=7,SUMIFS(P$5:P21,C$5:C21,C21,B$5:B21,">=4",B$5:B21,"<=6"),IF(B21=10,SUMIFS(P$5:P21,C$5:C21,C21,B$5:B21,">=7",B$5:B21,"<=9"),0))))) | R21: =L21*Headlines!$B$11 | S21: =I21*Headlines!$B$12 | T21: =I21*Headlines!$B$13 | U21: =Headlines!$B$14 | V21: =G21 | W21: =O21-R21-S21-T21-U21-V21 | X21: =X20+L21-(R21+S21+T21+U21+V21+Q21) | Y21: =F21
A22: 18 | B22: =MOD(A22-1+Headlines!$B$21-1,12)+1 | C22: =INT((A22-1+Headlines!$B$21-1)/12)+1 | D22: =VLOOKUP(B22,Headlines!$A$41:$B$52,2,FALSE) | E22: =(1+Headlines!$B$20)^INT((A22-1)/12) | F22: =Headlines!$B$10*VLOOKUP(B22,Headlines!$A$41:$C$52,3,FALSE) | G22: =Headlines!$B$15 | H22: =IF(G22>0,MAX(1,ROUND(G22/Headlines!$B$9*D22,0)),0) | I22: =H22+H21+H20+MAX(0,I21-H21-H20)*(1-F22) | J22: =I22*Headlines!$B$8*E22 | K22: =J22*12 | L22: =J22 | M22: =SUM(L11:L22) | N22: =IF(M22>=Headlines!$B$19,1,0) | O22: =IF(N22,L22/(1+Headlines!$B$18),L22) | P22: =L22-O22 | Q22: =IF(N22=0,0,IF(B22=1,SUMIFS(P$5:P22,C$5:C22,C22-1,B$5:B22,">=10",B$5:B22,"<=12"),IF(B22=4,SUMIFS(P$5:P22,C$5:C22,C22,B$5:B22,">=1",B$5:B22,"<=3"),IF(B22=7,SUMIFS(P$5:P22,C$5:C22,C22,B$5:B22,">=4",B$5:B22,"<=6"),IF(B22=10,SUMIFS(P$5:P22,C$5:C22,C22,B$5:B22,">=7",B$5:B22,"<=9"),0))))) | R22: =L22*Headlines!$B$11 | S22: =I22*Headlines!$B$12 | T22: =I22*Headlines!$B$13 | U22: =Headlines!$B$14 | V22: =G22 | W22: =O22-R22-S22-T22-U22-V22 | X22: =X21+L22-(R22+S22+T22+U22+V22+Q22) | Y22: =F22
A23: 19 | B23: =MOD(A23-1+Headlines!$B$21-1,12)+1 | C23: =INT((A23-1+Headlines!$B$21-1)/12)+1 | D23: =VLOOKUP(B23,Headlines!$A$41:$B$52,2,FALSE) | E23: =(1+Headlines!$B$20)^INT((A23-1)/12) | F23: =Headlines!$B$10*VLOOKUP(B23,Headlines!$A$41:$C$52,3,FALSE) | G23: =Headlines!$B$15 | H23: =IF(G23>0,MAX(1,ROUND(G23/Headlines!$B$9*D23,0)),0) | I23: =H23+H22+H21+MAX(0,I22-H22-H21)*(1-F23) | J23: =I23*Headlines!$B$8*E23 | K23: =J23*12 | L23: =J23 | M23: =SUM(L12:L23) | N23: =IF(M23>=Headlines!$B$19,1,0) | O23: =IF(N23,L23/(1+Headlines!$B$18),L23) | P23: =L23-O23 | Q23: =IF(N23=0,0,IF(B23=1,SUMIFS(P$5:P23,C$5:C23,C23-1,B$5:B23,">=10",B$5:B23,"<=12"),IF(B23=4,SUMIFS(P$5:P23,C$5:C23,C23,B$5:B23,">=1",B$5:B23,"<=3"),IF(B23=7,SUMIFS(P$5:P23,C$5:C23,C23,B$5:B23,">=4",B$5:B23,"<=6"),IF(B23=10,SUMIFS(P$5:P23,C$5:C23,C23,B$5:B23,">=7",B$5:B23,"<=9"),0))))) | R23: =L23*Headlines!$B$11 | S23: =I23*Headlines!$B$12 | T23: =I23*Headlines!$B$13 | U23: =Headlines!$B$14 | V23: =G23 | W23: =O23-R23-S23-T23-U23-V23 | X23: =X22+L23-(R23+S23+T23+U23+V23+Q23) | Y23: =F23
A24: 20 | B24: =MOD(A24-1+Headlines!$B$21-1,12)+1 | C24: =INT((A24-1+Headlines!$B$21-1)/12)+1 | D24: =VLOOKUP(B24,Headlines!$A$41:$B$52,2,FALSE) | E24: =(1+Headlines!$B$20)^INT((A24-1)/12) | F24: =Headlines!$B$10*VLOOKUP(B24,Headlines!$A$41:$C$52,3,FALSE) | G24: =Headlines!$B$15 | H24: =IF(G24>0,MAX(1,ROUND(G24/Headlines!$B$9*D24,0)),0) | I24: =H24+H23+H22+MAX(0,I23-H23-H22)*(1-F24) | J24: =I24*Headlines!$B$8*E24 | K24: =J24*12 | L24: =J24 | M24: =SUM(L13:L24) | N24: =IF(M24>=Headlines!$B$19,1,0) | O24: =IF(N24,L24/(1+Headlines!$B$18),L24) | P24: =L24-O24 | Q24: =IF(N24=0,0,IF(B24=1,SUMIFS(P$5:P24,C$5:C24,C24-1,B$5:B24,">=10",B$5:B24,"<=12"),IF(B24=4,SUMIFS(P$5:P24,C$5:C24,C24,B$5:B24,">=1",B$5:B24,"<=3"),IF(B24=7,SUMIFS(P$5:P24,C$5:C24,C24,B$5:B24,">=4",B$5:B24,"<=6"),IF(B24=10,SUMIFS(P$5:P24,C$5:C24,C24,B$5:B24,">=7",B$5:B24,"<=9"),0))))) | R24: =L24*Headlines!$B$11 | S24: =I24*Headlines!$B$12 | T24: =I24*Headlines!$B$13 | U24: =Headlines!$B$14 | V24: =G24 | W24: =O24-R24-S24-T24-U24-V24 | X24: =X23+L24-(R24+S24+T24+U24+V24+Q24) | Y24: =F24
A25: 21 | B25: =MOD(A25-1+Headlines!$B$21-1,12)+1 | C25: =INT((A25-1+Headlines!$B$21-1)/12)+1 | D25: =VLOOKUP(B25,Headlines!$A$41:$B$52,2,FALSE) | E25: =(1+Headlines!$B$20)^INT((A25-1)/12) | F25: =Headlines!$B$10*VLOOKUP(B25,Headlines!$A$41:$C$52,3,FALSE) | G25: =Headlines!$B$15 | H25: =IF(G25>0,MAX(1,ROUND(G25/Headlines!$B$9*D25,0)),0) | I25: =H25+H24+H23+MAX(0,I24-H24-H23)*(1-F25) | J25: =I25*Headlines!$B$8*E25 | K25: =J25*12 | L25: =J25 | M25: =SUM(L14:L25) | N25: =IF(M25>=Headlines!$B$19,1,0) | O25: =IF(N25,L25/(1+Headlines!$B$18),L25) | P25: =L25-O25 | Q25: =IF(N25=0,0,IF(B25=1,SUMIFS(P$5:P25,C$5:C25,C25-1,B$5:B25,">=10",B$5:B25,"<=12"),IF(B25=4,SUMIFS(P$5:P25,C$5:C25,C25,B$5:B25,">=1",B$5:B25,"<=3"),IF(B25=7,SUMIFS(P$5:P25,C$5:C25,C25,B$5:B25,">=4",B$5:B25,"<=6"),IF(B25=10,SUMIFS(P$5:P25,C$5:C25,C25,B$5:B25,">=7",B$5:B25,"<=9"),0))))) | R25: =L25*Headlines!$B$11 | S25: =I25*Headlines!$B$12 | T25: =I25*Headlines!$B$13 | U25: =Headlines!$B$14 | V25: =G25 | W25: =O25-R25-S25-T25-U25-V25 | X25: =X24+L25-(R25+S25+T25+U25+V25+Q25) | Y25: =F25
A26: 22 | B26: =MOD(A26-1+Headlines!$B$21-1,12)+1 | C26: =INT((A26-1+Headlines!$B$21-1)/12)+1 | D26: =VLOOKUP(B26,Headlines!$A$41:$B$52,2,FALSE) | E26: =(1+Headlines!$B$20)^INT((A26-1)/12) | F26: =Headlines!$B$10*VLOOKUP(B26,Headlines!$A$41:$C$52,3,FALSE) | G26: =Headlines!$B$15 | H26: =IF(G26>0,MAX(1,ROUND(G26/Headlines!$B$9*D26,0)),0) | I26: =H26+H25+H24+MAX(0,I25-H25-H24)*(1-F26) | J26: =I26*Headlines!$B$8*E26 | K26: =J26*12 | L26: =J26 | M26: =SUM(L15:L26) | N26: =IF(M26>=Headlines!$B$19,1,0) | O26: =IF(N26,L26/(1+Headlines!$B$18),L26) | P26: =L26-O26 | Q26: =IF(N26=0,0,IF(B26=1,SUMIFS(P$5:P26,C$5:C26,C26-1,B$5:B26,">=10",B$5:B26,"<=12"),IF(B26=4,SUMIFS(P$5:P26,C$5:C26,C26,B$5:B26,">=1",B$5:B26,"<=3"),IF(B26=7,SUMIFS(P$5:P26,C$5:C26,C26,B$5:B26,">=4",B$5:B26,"<=6"),IF(B26=10,SUMIFS(P$5:P26,C$5:C26,C26,B$5:B26,">=7",B$5:B26,"<=9"),0))))) | R26: =L26*Headlines!$B$11 | S26: =I26*Headlines!$B$12 | T26: =I26*Headlines!$B$13 | U26: =Headlines!$B$14 | V26: =G26 | W26: =O26-R26-S26-T26-U26-V26 | X26: =X25+L26-(R26+S26+T26+U26+V26+Q26) | Y26: =F26
A27: 23 | B27: =MOD(A27-1+Headlines!$B$21-1,12)+1 | C27: =INT((A27-1+Headlines!$B$21-1)/12)+1 | D27: =VLOOKUP(B27,Headlines!$A$41:$B$52,2,FALSE) | E27: =(1+Headlines!$B$20)^INT((A27-1)/12) | F27: =Headlines!$B$10*VLOOKUP(B27,Headlines!$A$41:$C$52,3,FALSE) | G27: =Headlines!$B$15 | H27: =IF(G27>0,MAX(1,ROUND(G27/Headlines!$B$9*D27,0)),0) | I27: =H27+H26+H25+MAX(0,I26-H26-H25)*(1-F27) | J27: =I27*Headlines!$B$8*E27 | K27: =J27*12 | L27: =J27 | M27: =SUM(L16:L27) | N27: =IF(M27>=Headlines!$B$19,1,0) | O27: =IF(N27,L27/(1+Headlines!$B$18),L27) | P27: =L27-O27 | Q27: =IF(N27=0,0,IF(B27=1,SUMIFS(P$5:P27,C$5:C27,C27-1,B$5:B27,">=10",B$5:B27,"<=12"),IF(B27=4,SUMIFS(P$5:P27,C$5:C27,C27,B$5:B27,">=1",B$5:B27,"<=3"),IF(B27=7,SUMIFS(P$5:P27,C$5:C27,C27,B$5:B27,">=4",B$5:B27,"<=6"),IF(B27=10,SUMIFS(P$5:P27,C$5:C27,C27,B$5:B27,">=7",B$5:B27,"<=9"),0))))) | R27: =L27*Headlines!$B$11 | S27: =I27*Headlines!$B$12 | T27: =I27*Headlines!$B$13 | U27: =Headlines!$B$14 | V27: =G27 | W27: =O27-R27-S27-T27-U27-V27 | X27: =X26+L27-(R27+S27+T27+U27+V27+Q27) | Y27: =F27
... A64: 60 | B64: =MOD(A64-1+Headlines!$B$21-1,12)+1 | C64: =INT((A64-1+Headlines!$B$21-1)/12)+1 | D64: =VLOOKUP(B64,Headlines!$A$41:$B$52,2,FALSE) | E64: =(1+Headlines!$B$20)^INT((A64-1)/12) | F64: =Headlines!$B$10*VLOOKUP(B64,Headlines!$A$41:$C$52,3,FALSE) | G64: =Headlines!$B$15 | H64: =IF(G64>0,MAX(1,ROUND(G64/Headlines!$B$9*D64,0)),0) | I64: =H64+H63+H62+MAX(0,I63-H63-H62)*(1-F64) | J64: =I64*Headlines!$B$8*E64 | K64: =J64*12 | L64: =J64 | M64: =SUM(L53:L64) | N64: =IF(M64>=Headlines!$B$19,1,0) | O64: =IF(N64,L64/(1+Headlines!$B$18),L64) | P64: =L64-O64 | Q64: =IF(N64=0,0,IF(B64=1,SUMIFS(P$5:P64,C$5:C64,C64-1,B$5:B64,">=10",B$5:B64,"<=12"),IF(B64=4,SUMIFS(P$5:P64,C$5:C64,C64,B$5:B64,">=1",B$5:B64,"<=3"),IF(B64=7,SUMIFS(P$5:P64,C$5:C64,C64,B$5:B64,">=4",B$5:B64,"<=6"),IF(B64=10,SUMIFS(P$5:P64,C$5:C64,C64,B$5:B64,">=7",B$5:B64,"<=9"),0))))) | R64: =L64*Headlines!$B$11 | S64: =I64*Headlines!$B$12 | T64: =I64*Headlines!$B$13 | U64: =Headlines!$B$14 | V64: =G64 | W64: =O64-R64-S64-T64-U64-V64 | X64: =X63+L64-(R64+S64+T64+U64+V64+Q64) | Y64: =F64

Sheet 5 Year Summary
A1: 5-Year Summary
A3: Year | B3: Cust | C3: MRR | D3: ARR | E3: New | F3: Gross | G3: Net | H3: VAcc | I3: VPay | J3: Fees | K3: Prov | L3: Ops | M3: Fixed | N3: Mkt | O3: Profit | P3: Cash
A4: Year 1 | B4: =Model!I16 | C4: =Model!J16 | D4: =Model!K16 | E4: =SUM(Model!H5:H16) | F4: =SUM(Model!L5:L16) | G4: =SUM(Model!O5:O16) | H4: =SUM(Model!P5:P16) | I4: =SUM(Model!Q5:Q16) | J4: =SUM(Model!R5:R16) | K4: =SUM(Model!S5:S16) | L4: =SUM(Model!T5:T16) | M4: =SUM(Model!U5:U16) | N4: =SUM(Model!V5:V16) | O4: =SUM(Model!W5:W16) | P4: =Model!X16
A5: Year 2 | B5: =Model!I28 | C5: =Model!J28 | D5: =Model!K28 | E5: =SUM(Model!H17:H28) | F5: =SUM(Model!L17:L28) | G5: =SUM(Model!O17:O28) | H5: =SUM(Model!P17:P28) | I5: =SUM(Model!Q17:Q28) | J5: =SUM(Model!R17:R28) | K5: =SUM(Model!S17:S28) | L5: =SUM(Model!T17:T28) | M5: =SUM(Model!U17:U28) | N5: =SUM(Model!V17:V28) | O5: =SUM(Model!W17:W28) | P5: =Model!X28
A6: Year 3 | B6: =Model!I40 | C6: =Model!J40 | D6: =Model!K40 | E6: =SUM(Model!H29:H40) | F6: =SUM(Model!L29:L40) | G6: =SUM(Model!O29:O40) | H6: =SUM(Model!P29:P40) | I6: =SUM(Model!Q29:Q40) | J6: =SUM(Model!R29:R40) | K6: =SUM(Model!S29:S40) | L6: =SUM(Model!T29:T40) | M6: =SUM(Model!U29:U40) | N6: =SUM(Model!V29:V40) | O6: =SUM(Model!W29:W40) | P6: =Model!X40
A7: Year 4 | B7: =Model!I52 | C7: =Model!J52 | D7: =Model!K52 | E7: =SUM(Model!H41:H52) | F7: =SUM(Model!L41:L52) | G7: =SUM(Model!O41:O52) | H7: =SUM(Model!P41:P52) | I7: =SUM(Model!Q41:Q52) | J7: =SUM(Model!R41:R52) | K7: =SUM(Model!S41:S52) | L7: =SUM(Model!T41:T52) | M7: =SUM(Model!U41:U52) | N7: =SUM(Model!V41:V52) | O7: =SUM(Model!W41:W52) | P7: =Model!X52
A8: Year 5 | B8: =Model!I64 | C8: =Model!J64 | D8: =Model!K64 | E8: =SUM(Model!H53:H64) | F8: =SUM(Model!L53:L64) | G8: =SUM(Model!O53:O64) | H8: =SUM(Model!P53:P64) | I8: =SUM(Model!Q53:Q64) | J8: =SUM(Model!R53:R64) | K8: =SUM(Model!S53:S64) | L8: =SUM(Model!T53:T64) | M8: =SUM(Model!U53:U64) | N8: =SUM(Model!V53:V64) | O8: =SUM(Model!W53:W64) | P8: =Model!X64
A10: VAT registration | B10: =IFERROR("Month "&MINIFS(Model!A5:A64,Model!N5:N64,1),"Not in 60 months")
