Workbook
Name InitialInvestment: Inputs!$B$5
Name PriceEssMonthly: Inputs!$B$8
Name PricePremMonthly: Inputs!$B$9
Name PriceEliteMonthly: Inputs!$B$10
Name PriceEssAnnual: Inputs!$B$11
Name PricePremAnnual: Inputs!$B$12
Name PriceEliteAnnual: Inputs!$B$13
Name AnnualMix: Inputs!$B$16
Name EssentialMix: Inputs!$B$17
Name PremiumMix: Inputs!$B$18
Name EliteMix: Inputs!$B$19
Name GardenSmallMix: Inputs!$B$21
Name GardenMediumMix: Inputs!$B$22
Name GardenLargeMix: Inputs!$B$23
Name MonthlyChurn: Inputs!$B$25
Name AnnualChurn: Inputs!$B$26
Name CAC: Inputs!$B$29
Name ProvPayEss: Inputs!$B$30
Name ProvPayPrem: Inputs!$B$31
Name ProvPayElite: Inputs!$B$32
Name PaymentFee: Inputs!$B$33
Name OpsAI: Inputs!$B$34
Name ProviderDelay: Inputs!$B$37
Name MonthlyFixed: Inputs!$B$38
Name BlendedPriceEssMonthly: Inputs!$B$40
Name BlendedPricePremMonthly: Inputs!$B$41
Name BlendedPriceEliteMonthly: Inputs!$B$42
Name BlendedPriceEssAnnual: Inputs!$B$43
Name BlendedPricePremAnnual: Inputs!$B$44
Name BlendedPriceEliteAnnual: Inputs!$B$45
Name BlendedProvPayEss: Inputs!$B$46
Name BlendedProvPayPrem: Inputs!$B$47
Name BlendedProvPayElite: Inputs!$B$48
Name MktFixed1_3: Inputs!$B$51
Name MktFixed4_6: Inputs!$B$52
Name MktPct7_12: Inputs!$B$53
Name MktPct13_18: Inputs!$B$54
Name MktPct19plus: Inputs!$B$55
Name MktMin7_12: Inputs!$B$56
Name MktMin13_18: Inputs!$B$57
Name MktMin19plus: Inputs!$B$58
Name CashBuffer: Inputs!$B$59
Name InflationRate: Inputs!$B$60
Name ReferralMix: Inputs!$B$61
Name ReferralReward: Inputs!$B$62
Name LaunchMonth: Inputs!$B$63
Name VATRate: Inputs!$B$64
Name VATThreshold: Inputs!$B$65
Name VATAgentMode: Inputs!$B$66
Name SeasonTable: Inputs!$A$74:$B$85
Name AcqSeasonTable: Inputs!$A$74:$C$85
Name ChurnSeasonTable: Inputs!$A$74:$D$85
Name WinterPivotSeasonTable: Inputs!$A$74:$E$85
Name WinterPivotChurnTable: Inputs!$A$74:$F$85
Name MRR_Month12: Model!$Z$16
Name ARR_Month12: Model!$AA$16
Name Cust_Month12: Model!$Y$16
Name Cash_Month12: Model!$AS$16
Name MRR_Month24: Model!$Z$28
Name ARR_Month24: Model!$AA$28

Sheet Headlines
A1: GardensSorted — Financial Headlines (v4 visits + VAT modes)
A2: Calendar VAT quarters | seasonal churn | provider delay | referrals | inflation
A4: KEY METRICS
A5: Y1 ARR | C5: Y2 ARR | E5: Y5 ARR | G5: Cash Y5
A6: =Model!AA16 | C6: =Model!AA28 | E6: =Model!AA64 | G6: =Model!AS64
A8: SNAPSHOT
A9: Metric | B9: Year 1 | C9: Year 2 | D9: Year 5
A10: End customers | B10: =Model!Y16 | C10: =Model!Y28 | D10: =Model!Y64
A11: ARR | B11: =Model!AA16 | C11: =Model!AA28 | D11: =Model!AA64
A12: Gross revenue | B12: =SUM(Model!AE5:AE16) | C12: =SUM(Model!AE17:AE28) | D12: =SUM(Model!AE53:AE64)
A13: Net revenue | B13: =SUM(Model!AH5:AH16) | C13: =SUM(Model!AH17:AH28) | D13: =SUM(Model!AH53:AH64)
A14: VAT paid (calendar Q) | B14: =SUM(Model!AJ5:AJ16) | C14: =SUM(Model!AJ17:AJ28) | D14: =SUM(Model!AJ53:AJ64)
A15: Annual profit | B15: =SUM(Model!AR5:AR16) | C15: =SUM(Model!AR17:AR28) | D15: =SUM(Model!AR53:AR64)
A16: Cash balance | B16: =Model!AS16 | C16: =Model!AS28 | D16: =Model!AS64
A17: Avg logo churn | B17: =AVERAGE(Model!AU6:AU16) | C17: =AVERAGE(Model!AU18:AU28) | D17: =AVERAGE(Model!AU54:AU64)
A18: Platform margin | B18: ='5 Year Summary'!T4 | C18: ='5 Year Summary'!T5 | D18: ='5 Year Summary'!T8
A20: MILESTONES
A21: VAT registration | B21: =IFERROR("Month "&MATCH(TRUE,Model!AG5:Model!AG64,0),"Not in 60 mo")
A22: First profitable month | B22: =IFERROR("Month "&MATCH(1,IF(Model!AR5:AR64>0,1),0),"Not in 60 mo")
A23: Cash payback £17k | B23: =IFERROR("Month "&MATCH(1,IF(Model!AS5:AS64>=InitialInvestment,1),0),"Not in 60 mo")
A24: Provider payment delay | B24: =ProviderDelay&" month(s)"
A25: Fixed platform cost | B25: =MonthlyFixed
A27: MODEL COMPLETENESS
A28: ✓ SaaS cohorts — Essential / Premium / Elite tiers, monthly & annual subs, MRR/ARR
A29: ✓ Visit cadence — 10/20/30 visits per year (provider pay = visits/12 × per-visit rate)
A30: ✓ Garden size mix — customer price & provider pay uplifts for medium (+£10/+£3) and large (+£20/+£6)
A31: ✓ VAT — toggle Principal vs Agent on Inputs B66; see VAT Comparison sheet
A33: ✓ Per-customer ops/AI £5/mo | Marketing phased with cash cap | No salaries (AI ops)
A34: ✓ Sensitivity tabs — churn, mix, CAC, scenarios, winter pivot
A36: NOT MODELLED (by design or later)
A37: • Corporation tax (~19–25%) — add when consistently profitable
A38: • Route density / travel efficiency in clustered postcodes
A39: • Cross-sell to other Sorted brands | Geographic rollout phasing
A40: • HMRC exact deadline (+1 mo 7 days) — model pays in Jan/Apr/Jul/Oct cal months
... A43: WHERE TO GO NEXT
A44: Inputs | B44: All assumptions
A45: 5 Year Summary | B45: Annual P&L
A46: 24 Month Forecast | B46: Monthly detail
A47: Unit Economics | B47: LTV & CAC

Sheet VAT Comparison
A1: VAT — Principal vs Agent
A3: Parallel comparison using Model gross revenue and provider pay. Toggle live model on Inputs B66: 0 = Principal (VAT on gross), 1 = Agent (VAT on margin only).
A4: See docs/vat-principal-vs-agent.md — accountant review required before filing.
A6: Year | B6: Gross revenue | C6: Provider pay | D6: Platform margin | E6: VAT registered (P) | F6: VAT registered (A) | G6: VAT accrued (P) | H6: VAT accrued (A) | I6: Net revenue (P) | J6: Net revenue (A) | K6: Gross profit (P) | L6: Gross profit (A) | M6: GP uplift (A vs P)
A7: Year 1 | B7: =SUM('VAT Dual Calc'!B5:B16) | C7: =SUM('VAT Dual Calc'!C5:C16) | D7: =B7-C7 | E7: ='VAT Dual Calc'!G16 | F7: ='VAT Dual Calc'!H16 | G7: =SUM('VAT Dual Calc'!I5:I16) | H7: =SUM('VAT Dual Calc'!J5:J16) | I7: =SUM('VAT Dual Calc'!K5:K16) | J7: =SUM('VAT Dual Calc'!L5:L16) | K7: =SUM('VAT Dual Calc'!M5:M16) | L7: =SUM('VAT Dual Calc'!N5:N16) | M7: =L7-K7
A8: Year 2 | B8: =SUM('VAT Dual Calc'!B17:B28) | C8: =SUM('VAT Dual Calc'!C17:C28) | D8: =B8-C8 | E8: ='VAT Dual Calc'!G28 | F8: ='VAT Dual Calc'!H28 | G8: =SUM('VAT Dual Calc'!I17:I28) | H8: =SUM('VAT Dual Calc'!J17:J28) | I8: =SUM('VAT Dual Calc'!K17:K28) | J8: =SUM('VAT Dual Calc'!L17:L28) | K8: =SUM('VAT Dual Calc'!M17:M28) | L8: =SUM('VAT Dual Calc'!N17:N28) | M8: =L8-K8
A9: Year 3 | B9: =SUM('VAT Dual Calc'!B29:B40) | C9: =SUM('VAT Dual Calc'!C29:C40) | D9: =B9-C9 | E9: ='VAT Dual Calc'!G40 | F9: ='VAT Dual Calc'!H40 | G9: =SUM('VAT Dual Calc'!I29:I40) | H9: =SUM('VAT Dual Calc'!J29:J40) | I9: =SUM('VAT Dual Calc'!K29:K40) | J9: =SUM('VAT Dual Calc'!L29:L40) | K9: =SUM('VAT Dual Calc'!M29:M40) | L9: =SUM('VAT Dual Calc'!N29:N40) | M9: =L9-K9
A10: Year 4 | B10: =SUM('VAT Dual Calc'!B41:B52) | C10: =SUM('VAT Dual Calc'!C41:C52) | D10: =B10-C10 | E10: ='VAT Dual Calc'!G52 | F10: ='VAT Dual Calc'!H52 | G10: =SUM('VAT Dual Calc'!I41:I52) | H10: =SUM('VAT Dual Calc'!J41:J52) | I10: =SUM('VAT Dual Calc'!K41:K52) | J10: =SUM('VAT Dual Calc'!L41:L52) | K10: =SUM('VAT Dual Calc'!M41:M52) | L10: =SUM('VAT Dual Calc'!N41:N52) | M10: =L10-K10
A11: Year 5 | B11: =SUM('VAT Dual Calc'!B53:B64) | C11: =SUM('VAT Dual Calc'!C53:C64) | D11: =B11-C11 | E11: ='VAT Dual Calc'!G64 | F11: ='VAT Dual Calc'!H64 | G11: =SUM('VAT Dual Calc'!I53:I64) | H11: =SUM('VAT Dual Calc'!J53:J64) | I11: =SUM('VAT Dual Calc'!K53:K64) | J11: =SUM('VAT Dual Calc'!L53:L64) | K11: =SUM('VAT Dual Calc'!M53:M64) | L11: =SUM('VAT Dual Calc'!N53:N64) | M11: =L11-K11
A14: First VAT registration month (Principal) | B14: =IFERROR(MATCH(TRUE,'VAT Dual Calc'!G5:G64,0)+4,"Not in 60 mo")
A15: First VAT registration month (Agent) | B15: =IFERROR(MATCH(TRUE,'VAT Dual Calc'!H5:H64,0)+4,"Not in 60 mo")
A17: Current model mode | B17: =IF(VATAgentMode=1,"Agent (margin VAT)","Principal (gross VAT)")

Sheet Assumptions
A1: Assumptions & Methodology v4 (10/20/30 visits per year + VAT modes)
A2: Edit yellow cells on the Inputs sheet — all tabs update automatically.
A4: Parameter | B4: Live Value | C4: Notes
A5: Initial investment | B5: =InitialInvestment | C5: Total startup capital
A6: Essential Monthly | B6: =PriceEssMonthly | C6: 10 visits/yr — 3-month minimum
A7: Premium Monthly | B7: =PricePremMonthly | C7: 20 visits/yr — 3-month minimum
A8: Elite Monthly | B8: =PriceEliteMonthly | C8: 30 visits/yr + patio refresh — 3-month minimum
A9: Essential Annual | B9: =PriceEssAnnual | C9: 12-month commitment
A10: Premium Annual | B10: =PricePremAnnual | C10: 12-month commitment
A11: Elite Annual | B11: =PriceEliteAnnual | C11: 12-month commitment
A12: Annual plan mix | B12: =AnnualMix | C12: Industry B2C: 15–25%
A13: Essential tier mix | B13: =EssentialMix | C13: Share of new customers
A14: Premium tier mix | B14: =PremiumMix | C14: Share of new customers
A15: Elite tier mix | B15: =EliteMix | C15: Share of new customers
A16: Small garden mix | B16: =GardenSmallMix | C16: Customer & provider blend
A17: Medium garden mix | B17: =GardenMediumMix | C17: +£10/mo customer, +£3/visit provider
A18: Large garden mix | B18: =GardenLargeMix | C18: +£20/mo customer, +£6/visit provider
A19: Monthly churn (post min term) | B19: =MonthlyChurn | C19: Home services B2C: 4–7%/mo
A20: Annual churn (at renewal) | B20: =AnnualChurn | C20: B2C annual: 15–25%
A21: CAC | B21: =CAC | C21: Paid acquisition
A22: Provider pay — Essential (small) | B22: =ProvPayEss | C22: 10 visits/yr × £15/visit ÷ 12
A23: Provider pay — Premium (small) | B23: =ProvPayPrem | C23: 20 visits/yr × £15/visit ÷ 12
A24: Provider pay — Elite (small) | B24: =ProvPayElite | C24: 30 visits/yr × £15/visit ÷ 12
A25: Blended provider pay — Essential | B25: =BlendedProvPayEss | C25: Garden-size weighted
A26: Blended provider pay — Premium | B26: =BlendedProvPayPrem | C26: Garden-size weighted
A27: Blended provider pay — Elite | B27: =BlendedProvPayElite | C27: Garden-size weighted
A28: Payment fees | B28: =PaymentFee | C28: Stripe processing
A29: Ops + AI per customer | B29: =OpsAI | C29: Per active subscriber/month
A30: VAT agent mode | B30: =VATAgentMode | C30: 0=Principal (VAT on gross), 1=Agent (VAT on margin)

Sheet Inputs
A1: Sorted — SaaS Forecast v4 (10/20/30 visits per year + VAT principal/agent)
A2: All forecast sheets recalculate automatically when you change inputs below.
A3: Parameter | B3: Value | C3: Notes
A4: INITIAL INVESTMENT
A5: Initial investment (£) | B5: 17000 | C5: Total startup capital available
A7: SUBSCRIPTION PRICING
A8: Essential Monthly (£/mo, small) | B8: 29.95 | C8: 10 visits/yr — medium +£10, large +£20
A9: Premium Monthly (£/mo, small) | B9: 54.95 | C9: 20 visits/yr — medium +£10, large +£20
A10: Elite Monthly (£/mo, small) | B10: 89.95 | C10: 30 visits/yr + patio refresh — medium +£10, large +£20
A11: Essential Annual (£/yr, small) | B11: 299.95 | C11: medium +£100, large +£200
A12: Premium Annual (£/yr, small) | B12: 549.95 | C12: medium +£100, large +£200
A13: Elite Annual (£/yr, small) | B13: 899.95 | C13: medium +£100, large +£200
A15: PLAN MIX
A16: Annual plan mix (%) | B16: 0.2 | C16: Industry B2C benchmark: 15–25%
A17: Essential tier mix (%) | B17: 0.55 | C17: Share of new customers within billing type
A18: Premium tier mix (%) | B18: 0.32 | C18: Share of new customers within billing type
A19: Elite tier mix (%) | B19: 0.13 | C19: Share of new customers within billing type
A20: GARDEN SIZE MIX
A21: Small garden mix (%) | B21: 0.5 | C21: Up to 75 m²
A22: Medium garden mix (%) | B22: 0.35 | C22: 75–150 m² (+£10/mo customer, +£3/visit provider)
A23: Large garden mix (%) | B23: 0.15 | C23: 150+ m² (+£20/mo customer, +£6/visit provider)
A24: CHURN (edit for sensitivity)
A25: Monthly plan churn — post min term (%/mo) | B25: 0.055 | C25: Home services B2C: 4–7%. Applied after month 3.
A26: Annual plan churn — at renewal (%/yr) | B26: 0.2 | C26: B2C annual renewal: 15–25%
A28: UNIT ECONOMICS
A29: Customer Acquisition Cost — CAC (£) | B29: 70 | C29: Paid acquisition per customer
A30: Provider pay — Essential (£/mo, small garden) | B30: 12.5 | C30: 10 visits/yr × £15/visit ÷ 12
A31: Provider pay — Premium (£/mo, small garden) | B31: 25 | C31: 20 visits/yr × £15/visit ÷ 12
A32: Provider pay — Elite (£/mo, small garden) | B32: 37.5 | C32: 30 visits/yr × £15/visit ÷ 12
A33: Payment processing fee (%) | B33: 0.03 | C33: Stripe/card fees
A34: Ops + AI cost per customer (£/mo) | B34: 5 | C34: Support, hosting, AI per active sub
A35: CASH TIMING
A36: CASH TIMING | B36: 1 | C36: Providers invoiced ~30 days after service — cash float benefit
A37: Provider payment delay (months) | B37: 1 | C37: Hosting, AI base, tools — excludes per-customer ops
A38: Monthly fixed platform cost (£) | B38: 250 | C38: Jan/Apr/Jul/Oct for preceding calendar quarter (UK)
A39: BLENDED PRICING & PROVIDER PAY (calculated)
A40: Blended Essential monthly (£/mo) | B40: =$B$8*$B$21+($B$8+10)*$B$22+($B$8+20)*$B$23
A41: Blended Premium monthly (£/mo) | B41: =$B$9*$B$21+($B$9+10)*$B$22+($B$9+20)*$B$23
A42: Blended Elite monthly (£/mo) | B42: =$B$10*$B$21+($B$10+10)*$B$22+($B$10+20)*$B$23
A43: Blended Essential annual (£/yr) | B43: =$B$11*$B$21+($B$11+100)*$B$22+($B$11+200)*$B$23
...

Sheet 5 Year Summary
A1: 5-Year Summary
A3: Year | B3: Cust | C3: MRR | D3: ARR | E3: Paid | F3: Referrals | G3: Gross | H3: Net | I3: VAcc | J3: VPay | K3: VBal | L3: Prov | M3: Fees | N3: Ops | O3: Fixed | P3: Ref£ | Q3: Mkt | R3: Profit | S3: Cash | T3: Margin | U3: Prov# | V3: MRRGr | W3: Churn | X3: CumPft
A4: Year 1 | B4: =Model!Y16 | C4: =Model!Z16 | D4: =Model!AA16 | E4: =SUM(Model!H5:H16) | F4: =SUM(Model!I5:I16) | G4: =SUM(Model!AE5:AE16) | H4: =SUM(Model!AH5:AH16) | I4: =SUM(Model!AI5:AI16) | J4: =SUM(Model!AJ5:AJ16) | K4: =Model!AK16 | L4: =SUM(Model!AL5:AL16) | M4: =SUM(Model!AM5:AM16) | N4: =SUM(Model!AN5:AN16) | O4: =SUM(Model!AO5:AO16) | P4: =SUM(Model!AP5:AP16) | Q4: =SUM(Model!AQ5:AQ16) | R4: =SUM(Model!AR5:AR16) | S4: =Model!AS16 | T4: =IF(G4>0,(H4-L4-M4-N4-O4)/G4,0) | U4: =ROUNDUP(B4/140,0) | V4: — | W4: =AVERAGE(Model!AU6:AU16) | X4: =SUM($R$4:R4)
A5: Year 2 | B5: =Model!Y28 | C5: =Model!Z28 | D5: =Model!AA28 | E5: =SUM(Model!H17:H28) | F5: =SUM(Model!I17:I28) | G5: =SUM(Model!AE17:AE28) | H5: =SUM(Model!AH17:AH28) | I5: =SUM(Model!AI17:AI28) | J5: =SUM(Model!AJ17:AJ28) | K5: =Model!AK28 | L5: =SUM(Model!AL17:AL28) | M5: =SUM(Model!AM17:AM28) | N5: =SUM(Model!AN17:AN28) | O5: =SUM(Model!AO17:AO28) | P5: =SUM(Model!AP17:AP28) | Q5: =SUM(Model!AQ17:AQ28) | R5: =SUM(Model!AR17:AR28) | S5: =Model!AS28 | T5: =IF(G5>0,(H5-L5-M5-N5-O5)/G5,0) | U5: =ROUNDUP(B5/140,0) | V5: =(C5-C4)/C4 | W5: =AVERAGE(Model!AU18:AU28) | X5: =SUM($R$4:R5)
A6: Year 3 | B6: =Model!Y40 | C6: =Model!Z40 | D6: =Model!AA40 | E6: =SUM(Model!H29:H40) | F6: =SUM(Model!I29:I40) | G6: =SUM(Model!AE29:AE40) | H6: =SUM(Model!AH29:AH40) | I6: =SUM(Model!AI29:AI40) | J6: =SUM(Model!AJ29:AJ40) | K6: =Model!AK40 | L6: =SUM(Model!AL29:AL40) | M6: =SUM(Model!AM29:AM40) | N6: =SUM(Model!AN29:AN40) | O6: =SUM(Model!AO29:AO40) | P6: =SUM(Model!AP29:AP40) | Q6: =SUM(Model!AQ29:AQ40) | R6: =SUM(Model!AR29:AR40) | S6: =Model!AS40 | T6: =IF(G6>0,(H6-L6-M6-N6-O6)/G6,0) | U6: =ROUNDUP(B6/140,0) | V6: =(C6-C5)/C5 | W6: =AVERAGE(Model!AU30:AU40) | X6: =SUM($R$4:R6)
A7: Year 4 | B7: =Model!Y52 | C7: =Model!Z52 | D7: =Model!AA52 | E7: =SUM(Model!H41:H52) | F7: =SUM(Model!I41:I52) | G7: =SUM(Model!AE41:AE52) | H7: =SUM(Model!AH41:AH52) | I7: =SUM(Model!AI41:AI52) | J7: =SUM(Model!AJ41:AJ52) | K7: =Model!AK52 | L7: =SUM(Model!AL41:AL52) | M7: =SUM(Model!AM41:AM52) | N7: =SUM(Model!AN41:AN52) | O7: =SUM(Model!AO41:AO52) | P7: =SUM(Model!AP41:AP52) | Q7: =SUM(Model!AQ41:AQ52) | R7: =SUM(Model!AR41:AR52) | S7: =Model!AS52 | T7: =IF(G7>0,(H7-L7-M7-N7-O7)/G7,0) | U7: =ROUNDUP(B7/140,0) | V7: =(C7-C6)/C6 | W7: =AVERAGE(Model!AU42:AU52) | X7: =SUM($R$4:R7)
A8: Year 5 | B8: =Model!Y64 | C8: =Model!Z64 | D8: =Model!AA64 | E8: =SUM(Model!H53:H64) | F8: =SUM(Model!I53:I64) | G8: =SUM(Model!AE53:AE64) | H8: =SUM(Model!AH53:AH64) | I8: =SUM(Model!AI53:AI64) | J8: =SUM(Model!AJ53:AJ64) | K8: =Model!AK64 | L8: =SUM(Model!AL53:AL64) | M8: =SUM(Model!AM53:AM64) | N8: =SUM(Model!AN53:AN64) | O8: =SUM(Model!AO53:AO64) | P8: =SUM(Model!AP53:AP64) | Q8: =SUM(Model!AQ53:AQ64) | R8: =SUM(Model!AR53:AR64) | S8: =Model!AS64 | T8: =IF(G8>0,(H8-L8-M8-N8-O8)/G8,0) | U8: =ROUNDUP(B8/140,0) | V8: =(C8-C7)/C7 | W8: =AVERAGE(Model!AU54:AU64) | X8: =SUM($R$4:R8)
A10: VAT registration | B10: =IFERROR("Month "&MATCH(TRUE,Model!AG5:Model!AG64,0),"Not in 60 mo")
A11: VAT payments | B11: Calendar: Jan=Q4 prior yr, Apr=Q1, Jul=Q2, Oct=Q3

Sheet 24 Month Forecast
A1: 24-Month Forecast
A3: Month | B3: CalMo | C3: Paid | D3: Referral | E3: Total | F3: Cust | G3: EffChurn | H3: MRR | I3: ARR | J3: Gross | K3: Net | L3: VAcc | M3: VPay | N3: VBal | O3: Prov | P3: Fees | Q3: Ops | R3: Fixed | S3: Ref£ | T3: Mkt | U3: Pft | V3: Cash | W3: Churn
A4: Month 1 | B4: =Model!B5 | C4: =Model!H5 | D4: =Model!I5 | E4: =Model!J5 | F4: =Model!Y5 | G4: =Model!F5 | H4: =Model!Z5 | I4: =Model!AA5 | J4: =Model!AE5 | K4: =Model!AH5 | L4: =Model!AI5 | M4: =Model!AJ5 | N4: =Model!AK5 | O4: =Model!AL5 | P4: =Model!AM5 | Q4: =Model!AN5 | R4: =Model!AO5 | ... V4: =Model!AS5 | W4: =Model!AU5
A5: Month 2 | B5: =Model!B6 | C5: =Model!H6 | D5: =Model!I6 | E5: =Model!J6 | F5: =Model!Y6 | G5: =Model!F6 | H5: =Model!Z6 | I5: =Model!AA6 | J5: =Model!AE6 | K5: =Model!AH6 | L5: =Model!AI6 | M5: =Model!AJ6 | N5: =Model!AK6 | O5: =Model!AL6 | P5: =Model!AM6 | Q5: =Model!AN6 | R5: =Model!AO6 | ... V5: =Model!AS6 | W5: =Model!AU6
A6: Month 3 | B6: =Model!B7 | C6: =Model!H7 | D6: =Model!I7 | E6: =Model!J7 | F6: =Model!Y7 | G6: =Model!F7 | H6: =Model!Z7 | I6: =Model!AA7 | J6: =Model!AE7 | K6: =Model!AH7 | L6: =Model!AI7 | M6: =Model!AJ7 | N6: =Model!AK7 | O6: =Model!AL7 | P6: =Model!AM7 | Q6: =Model!AN7 | R6: =Model!AO7 | ... V6: =Model!AS7 | W6: =Model!AU7
A7: Month 4 | B7: =Model!B8 | C7: =Model!H8 | D7: =Model!I8 | E7: =Model!J8 | F7: =Model!Y8 | G7: =Model!F8 | H7: =Model!Z8 | I7: =Model!AA8 | J7: =Model!AE8 | K7: =Model!AH8 | L7: =Model!AI8 | M7: =Model!AJ8 | N7: =Model!AK8 | O7: =Model!AL8 | P7: =Model!AM8 | Q7: =Model!AN8 | R7: =Model!AO8 | ... V7: =Model!AS8 | W7: =Model!AU8
A8: Month 5 | B8: =Model!B9 | C8: =Model!H9 | D8: =Model!I9 | E8: =Model!J9 | F8: =Model!Y9 | G8: =Model!F9 | H8: =Model!Z9 | I8: =Model!AA9 | J8: =Model!AE9 | K8: =Model!AH9 | L8: =Model!AI9 | M8: =Model!AJ9 | N8: =Model!AK9 | O8: =Model!AL9 | P8: =Model!AM9 | Q8: =Model!AN9 | R8: =Model!AO9 | ... V8: =Model!AS9 | W8: =Model!AU9
A9: Month 6 | B9: =Model!B10 | C9: =Model!H10 | D9: =Model!I10 | E9: =Model!J10 | F9: =Model!Y10 | G9: =Model!F10 | H9: =Model!Z10 | I9: =Model!AA10 | J9: =Model!AE10 | K9: =Model!AH10 | L9: =Model!AI10 | M9: =Model!AJ10 | N9: =Model!AK10 | O9: =Model!AL10 | P9: =Model!AM10 | Q9: =Model!AN10 | R9: =Model!AO10 | ... V9: =Model!AS10 | W9: =Model!AU10
A10: Month 7 | B10: =Model!B11 | C10: =Model!H11 | D10: =Model!I11 | E10: =Model!J11 | F10: =Model!Y11 | G10: =Model!F11 | H10: =Model!Z11 | I10: =Model!AA11 | J10: =Model!AE11 | K10: =Model!AH11 | L10: =Model!AI11 | M10: =Model!AJ11 | N10: =Model!AK11 | O10: =Model!AL11 | P10: =Model!AM11 | Q10: =Model!AN11 | R10: =Model!AO11 | ... V10: =Model!AS11 | W10: =Model!AU11
A11: Month 8 | B11: =Model!B12 | C11: =Model!H12 | D11: =Model!I12 | E11: =Model!J12 | F11: =Model!Y12 | G11: =Model!F12 | H11: =Model!Z12 | I11: =Model!AA12 | J11: =Model!AE12 | K11: =Model!AH12 | L11: =Model!AI12 | M11: =Model!AJ12 | N11: =Model!AK12 | O11: =Model!AL12 | P11: =Model!AM12 | Q11: =Model!AN12 | R11: =Model!AO12 | ... V11: =Model!AS12 | W11: =Model!AU12
A12: Month 9 | B12: =Model!B13 | C12: =Model!H13 | D12: =Model!I13 | E12: =Model!J13 | F12: =Model!Y13 | G12: =Model!F13 | H12: =Model!Z13 | I12: =Model!AA13 | J12: =Model!AE13 | K12: =Model!AH13 | L12: =Model!AI13 | M12: =Model!AJ13 | N12: =Model!AK13 | O12: =Model!AL13 | P12: =Model!AM13 | Q12: =Model!AN13 | R12: =Model!AO13 | ... V12: =Model!AS13 | W12: =Model!AU13
A13: Month 10 | B13: =Model!B14 | C13: =Model!H14 | D13: =Model!I14 | E13: =Model!J14 | F13: =Model!Y14 | G13: =Model!F14 | H13: =Model!Z14 | I13: =Model!AA14 | J13: =Model!AE14 | K13: =Model!AH14 | L13: =Model!AI14 | M13: =Model!AJ14 | N13: =Model!AK14 | O13: =Model!AL14 | P13: =Model!AM14 | Q13: =Model!AN14 | R13: =Model!AO14 | ... V13: =Model!AS14 | W13: =Model!AU14
A14: Month 11 | B14: =Model!B15 | C14: =Model!H15 | D14: =Model!I15 | E14: =Model!J15 | F14: =Model!Y15 | G14: =Model!F15 | H14: =Model!Z15 | I14: =Model!AA15 | J14: =Model!AE15 | K14: =Model!AH15 | L14: =Model!AI15 | M14: =Model!AJ15 | N14: =Model!AK15 | O14: =Model!AL15 | P14: =Model!AM15 | Q14: =Model!AN15 | R14: =Model!AO15 | ... V14: =Model!AS15 | W14: =Model!AU15
A15: Month 12 | B15: =Model!B16 | C15: =Model!H16 | D15: =Model!I16 | E15: =Model!J16 | F15: =Model!Y16 | G15: =Model!F16 | H15: =Model!Z16 | I15: =Model!AA16 | J15: =Model!AE16 | K15: =Model!AH16 | L15: =Model!AI16 | M15: =Model!AJ16 | N15: =Model!AK16 | O15: =Model!AL16 | P15: =Model!AM16 | Q15: =Model!AN16 | R15: =Model!AO16 | ... V15: =Model!AS16 | W15: =Model!AU16
... A27: Month 24 | B27: =Model!B28 | C27: =Model!H28 | D27: =Model!I28 | E27: =Model!J28 | F27: =Model!Y28 | G27: =Model!F28 | H27: =Model!Z28 | I27: =Model!AA28 | J27: =Model!AE28 | K27: =Model!AH28 | L27: =Model!AI28 | M27: =Model!AJ28 | N27: =Model!AK28 | O27: =Model!AL28 | P27: =Model!AM28 | Q27: =Model!AN28 | R27: =Model!AO28 | ... V27: =Model!AS28 | W27: =Model!AU28

Sheet Unit Economics
A1: Unit Economics v4 (10/20/30 visits + garden-size blended)
A3: Metric | B3: Value | C3: Unit
A4: Blended ARPU (MRR per customer) | B4: =EssentialMix*(1-AnnualMix)*BlendedPriceEssMonthly+PremiumMix*(1-AnnualMix)*BlendedPricePremMonthly+EliteMix*(1-AnnualMix)*BlendedPriceEliteMonthly+EssentialMix*AnnualMix*BlendedPriceEssAnnual/12+PremiumMix*AnnualMix*BlendedPricePremAnnual/12+EliteMix*AnnualMix*BlendedPriceEliteAnnual/12 | C4: £/mo
A5: Monthly plan ARPU | B5: =EssentialMix*BlendedPriceEssMonthly+PremiumMix*BlendedPricePremMonthly+EliteMix*BlendedPriceEliteMonthly | C5: £/mo
A6: Annual plan ARPU (normalised) | B6: =EssentialMix*BlendedPriceEssAnnual/12+PremiumMix*BlendedPricePremAnnual/12+EliteMix*BlendedPriceEliteAnnual/12 | C6: £/mo
A8: Provider cost per customer (blended tier + garden size) | B8: =EssentialMix*BlendedProvPayEss+PremiumMix*BlendedProvPayPrem+EliteMix*BlendedProvPayElite | C8: £/mo
A9: Payment fees per customer | B9: =B4*PaymentFee | C9: £/mo
A10: Ops + AI per customer | B10: =OpsAI | C10: £/mo
A12: Gross margin per customer (pre-marketing) | B12: =B4-B8-B4*PaymentFee-OpsAI | C12: £/mo
A13: CAC | B13: =CAC | C13: £
A14: Months to recover CAC | B14: =B13/B12 | C14: months
A16: Customer lifetime — monthly plan (post min term) | B16: =1/MonthlyChurn | C16: months
A17: Expected annual renewals — annual plan | B17: =1/AnnualChurn | C17: renewals
A18: LTV — monthly plan (simplified) | B18: =B5*(1-PaymentFee)*ProvPayEss/PriceEssMonthly*(1/MonthlyChurn)*EssentialMix/(EssentialMix+PremiumMix+EliteMix) | C18: £
A19: LTV — annual plan (simplified) | B19: =B6*12*(1-PaymentFee)*(1/AnnualChurn) | C19: £
A20: LTV:CAC — monthly plan | B20: =B18/CAC | C20: x
A21: LTV:CAC — blended | B21: =B4*(1-PaymentFee)*((1-AnnualMix)/MonthlyChurn+AnnualMix*12/AnnualChurn)/CAC | C21: x
A22: Inflated ARPU (Year 2 prices) | B22: =B4*(1+InflationRate) | C22: £/mo
A23: Effective CAC (paid customers only) | B23: =CAC | C23: £
A24: Blended CAC (incl. referrals) | B24: =CAC*(1-ReferralMix) | C24: £/customer
A25: Monthly fixed platform cost | B25: =MonthlyFixed | C25: £/mo

Sheet Sens - Scenarios
A1: Scenario Comparison — Conservative / Base / Aggressive (v4)
A2: Edit yellow cells in Conservative & Aggressive columns. Base uses live Inputs (£70 CAC). Marketing spend: Inputs rows 31–39.
A4: Parameter | B4: Conservative | C4: Base (live Inputs) | D4: Aggressive
A5: Monthly churn (post min term) | B5: 0.07 | C5: =MonthlyChurn | D5: 0.04
A6: Annual churn (at renewal) | B6: 0.25 | C6: =AnnualChurn | D6: 0.15
A7: Annual plan mix | B7: 0.15 | C7: =AnnualMix | D7: 0.3
A8: CAC (£) | B8: 110 | C8: =CAC | D8: 40
A11: OUTPUT METRICS
A12: Metric | B12: Conservative | C12: Base | D12: Aggressive
A13: End Year 1 — Customers | B13: ='Scenario Engine'!Y$16 | C13: ='Scenario Engine'!BU$16 | D13: ='Scenario Engine'!DQ$16
A14: End Year 1 — MRR (£) | B14: ='Scenario Engine'!Z$16 | C14: ='Scenario Engine'!BV$16 | D14: ='Scenario Engine'!DR$16
A15: End Year 1 — ARR (£) | B15: ='Scenario Engine'!AA$16 | C15: ='Scenario Engine'!BW$16 | D15: ='Scenario Engine'!DS$16
A16: End Year 1 — Cash Balance (£) | B16: ='Scenario Engine'!AS$16 | C16: ='Scenario Engine'!CO$16 | D16: ='Scenario Engine'!EK$16
A17: Year 1 — Gross Revenue (£) | B17: =SUM('Scenario Engine'!AE$5:'Scenario Engine'!AE$16) | C17: =SUM('Scenario Engine'!CA$5:'Scenario Engine'!CA$16) | D17: =SUM('Scenario Engine'!DW$5:'Scenario Engine'!DW$16)
A18: Year 1 — Net Revenue (£) | B18: =SUM('Scenario Engine'!AH$5:'Scenario Engine'!AH$16) | C18: =SUM('Scenario Engine'!CD$5:'Scenario Engine'!CD$16) | D18: =SUM('Scenario Engine'!DZ$5:'Scenario Engine'!DZ$16)
A19: Year 1 — Profit (£) | B19: =SUM('Scenario Engine'!AR$5:'Scenario Engine'!AR$16) | C19: =SUM('Scenario Engine'!CN$5:'Scenario Engine'!CN$16) | D19: =SUM('Scenario Engine'!EJ$5:'Scenario Engine'!EJ$16)
A20: End Year 2 — Customers | B20: ='Scenario Engine'!Y$28 | C20: ='Scenario Engine'!BU$28 | D20: ='Scenario Engine'!DQ$28
A21: End Year 2 — MRR (£) | B21: ='Scenario Engine'!Z$28 | C21: ='Scenario Engine'!BV$28 | D21: ='Scenario Engine'!DR$28
A22: End Year 2 — ARR (£) | B22: ='Scenario Engine'!AA$28 | C22: ='Scenario Engine'!BW$28 | D22: ='Scenario Engine'!DS$28
A23: End Year 2 — Cash Balance (£) | B23: ='Scenario Engine'!AS$28 | C23: ='Scenario Engine'!CO$28 | D23: ='Scenario Engine'!EK$28
A24: Year 2 — Gross Revenue (£) | B24: =SUM('Scenario Engine'!AE$17:'Scenario Engine'!AE$28) | C24: =SUM('Scenario Engine'!CA$17:'Scenario Engine'!CA$28) | D24: =SUM('Scenario Engine'!DW$17:'Scenario Engine'!DW$28)
A25: End Year 5 — Customers | B25: ='Scenario Engine'!Y$64 | C25: ='Scenario Engine'!BU$64 | D25: ='Scenario Engine'!DQ$64
A26: End Year 5 — MRR (£) | B26: ='Scenario Engine'!Z$64 | C26: ='Scenario Engine'!BV$64 | D26: ='Scenario Engine'!DR$64
A27: End Year 5 — ARR (£) | B27: ='Scenario Engine'!AA$64 | C27: ='Scenario Engine'!BW$64 | D27: ='Scenario Engine'!DS$64
A28: End Year 5 — Cash Balance (£) | B28: ='Scenario Engine'!AS$64 | C28: ='Scenario Engine'!CO$64 | D28: ='Scenario Engine'!EK$64

Sheet Sens - Churn
A1: Churn Sensitivity — v3 Elite full model
A2: Edit churn in column A (yellow). Live model outputs in section below for comparison.
A4: Current Monthly Churn (Inputs) | B4: =MonthlyChurn
A5: Live Y1 MRR | B5: =Model!Z16
A6: Live Y2 MRR | B6: =Model!Z28
A7: Live Y2 ARR | B7: =Model!AA28
A8: Live Y5 ARR | B8: =Model!AA64
A9: Live Y5 Cash | B9: =Model!AS64
A12: Monthly Churn | B12: Y1 MRR | C12: Y1 Cust | D12: Y2 MRR | E12: Y2 ARR | F12: Y2 Cash | G12: Y5 ARR
A13: 0.03 | B13: ='Scenario Engine'!FN$16 | C13: ='Scenario Engine'!FM$16 | D13: ='Scenario Engine'!FN$28 | E13: ='Scenario Engine'!FO$28 | F13: ='Scenario Engine'!FQ$28 | G13: ='Scenario Engine'!EY$64
A14: 0.035 | B14: ='Scenario Engine'!HJ$16 | C14: ='Scenario Engine'!HI$16 | D14: ='Scenario Engine'!HJ$28 | E14: ='Scenario Engine'!HK$28 | F14: ='Scenario Engine'!HI$28 | G14: ='Scenario Engine'!GQ$64
A15: 0.04 | B15: ='Scenario Engine'!JF$16 | C15: ='Scenario Engine'!JE$16 | D15: ='Scenario Engine'!JF$28 | E15: ='Scenario Engine'!JG$28 | F15: ='Scenario Engine'!JA$28 | G15: ='Scenario Engine'!II$64
A16: 0.045 | B16: ='Scenario Engine'!LB$16 | C16: ='Scenario Engine'!LA$16 | D16: ='Scenario Engine'!LB$28 | E16: ='Scenario Engine'!LC$28 | F16: ='Scenario Engine'!KS$28 | G16: ='Scenario Engine'!KA$64
A17: 0.05 | B17: ='Scenario Engine'!MX$16 | C17: ='Scenario Engine'!MW$16 | D17: ='Scenario Engine'!MX$28 | E17: ='Scenario Engine'!MY$28 | F17: ='Scenario Engine'!MK$28 | G17: ='Scenario Engine'!LS$64
A18: 0.055 | B18: ='Scenario Engine'!OT$16 | C18: ='Scenario Engine'!OS$16 | D18: ='Scenario Engine'!OT$28 | E18: ='Scenario Engine'!OU$28 | F18: ='Scenario Engine'!OC$28 | G18: ='Scenario Engine'!NK$64
A19: 0.06 | B19: ='Scenario Engine'!QP$16 | C19: ='Scenario Engine'!QO$16 | D19: ='Scenario Engine'!QP$28 | E19: ='Scenario Engine'!QQ$28 | F19: ='Scenario Engine'!PU$28 | G19: ='Scenario Engine'!PC$64
A20: 0.065 | B20: ='Scenario Engine'!SL$16 | C20: ='Scenario Engine'!SK$16 | D20: ='Scenario Engine'!SL$28 | E20: ='Scenario Engine'!SM$28 | F20: ='Scenario Engine'!RM$28 | G20: ='Scenario Engine'!QU$64
A21: 0.07 | B21: ='Scenario Engine'!UH$16 | C21: ='Scenario Engine'!UG$16 | D21: ='Scenario Engine'!UH$28 | E21: ='Scenario Engine'!UI$28 | F21: ='Scenario Engine'!TE$28 | G21: ='Scenario Engine'!SM$64
A22: 0.07 | B22: ='Scenario Engine'!KZ$16 | C22: ='Scenario Engine'!KY$16 | D22: ='Scenario Engine'!KZ$28 | E22: ='Scenario Engine'!LA$28 | F22: ='Scenario Engine'!LK$28 | G22: ='Scenario Engine'!LA$64

Sheet Sens - Annual Mix
A1: Annual Plan Mix Sensitivity — v3 Elite engine
A2: Edit mix % in column A (yellow).
A4: Current (Inputs) | B4: =AnnualMix
A7: Annual Mix | B7: Y1 MRR | C7: Blended ARPU | D7: Y2 MRR | E7: Y2 ARR | F7: Y5 ARR | G7: Y5 Cash
A9: 0.1 | B9: ='Scenario Engine'!WD$16 | C9: =IF('Scenario Engine'!WC$16>0,'Scenario Engine'!WD$16/'Scenario Engine'!WC$16,0) | D9: ='Scenario Engine'!WD$28 | E9: ='Scenario Engine'!WE$28 | F9: ='Scenario Engine'!UE$64 | G9: ='Scenario Engine'!UW$64
A10: 0.15 | B10: ='Scenario Engine'!XZ$16 | C10: =IF('Scenario Engine'!XY$16>0,'Scenario Engine'!XZ$16/'Scenario Engine'!XY$16,0) | D10: ='Scenario Engine'!XZ$28 | E10: ='Scenario Engine'!YA$28 | F10: ='Scenario Engine'!VW$64 | G10: ='Scenario Engine'!WO$64
A11: 0.2 | B11: ='Scenario Engine'!ZV$16 | C11: =IF('Scenario Engine'!ZU$16>0,'Scenario Engine'!ZV$16/'Scenario Engine'!ZU$16,0) | D11: ='Scenario Engine'!ZV$28 | E11: ='Scenario Engine'!ZW$28 | F11: ='Scenario Engine'!XO$64 | G11: ='Scenario Engine'!YG$64
A12: 0.25 | B12: ='Scenario Engine'!ABR$16 | C12: =IF('Scenario Engine'!ABQ$16>0,'Scenario Engine'!ABR$16/'Scenario Engine'!ABQ$16,0) | D12: ='Scenario Engine'!ABR$28 | E12: ='Scenario Engine'!ABS$28 | F12: ='Scenario Engine'!ZG$64 | G12: ='Scenario Engine'!ZY$64
A13: 0.3 | B13: ='Scenario Engine'!ADN$16 | C13: =IF('Scenario Engine'!ADM$16>0,'Scenario Engine'!ADN$16/'Scenario Engine'!ADM$16,0) | D13: ='Scenario Engine'!ADN$28 | E13: ='Scenario Engine'!ADO$28 | F13: ='Scenario Engine'!AAY$64 | G13: ='Scenario Engine'!ABQ$64
A14: 0.35 | B14: ='Scenario Engine'!AFJ$16 | C14: =IF('Scenario Engine'!AFI$16>0,'Scenario Engine'!AFJ$16/'Scenario Engine'!AFI$16,0) | D14: ='Scenario Engine'!AFJ$28 | E14: ='Scenario Engine'!AFK$28 | F14: ='Scenario Engine'!ACQ$64 | G14: ='Scenario Engine'!ADI$64
A15: 0.4 | B15: ='Scenario Engine'!AHF$16 | C15: =IF('Scenario Engine'!AHE$16>0,'Scenario Engine'!AHF$16/'Scenario Engine'!AHE$16,0) | D15: ='Scenario Engine'!AHF$28 | E15: ='Scenario Engine'!AHG$28 | F15: ='Scenario Engine'!AEI$64 | G15: ='Scenario Engine'!AFA$64

Sheet Sens - CAC & Marketing
A1: CAC Sensitivity — v3 Elite full model engine
A2: Edit CAC in column A (yellow). Sweep spans optimistic (£40) to conservative (£120).
A4: Current (Inputs) | B4: =CAC
A7: CAC (£) | B7: Y1 New Cust | C7: Y1 End Cust | D7: Y1 MRR | E7: Y2 MRR | F7: Y2 Cash | G7: Y5 Cash
A9: 40 | B9: =SUM('Scenario Engine'!AIJ$5:'Scenario Engine'!AIJ$16) | C9: ='Scenario Engine'!AJA$16 | D9: ='Scenario Engine'!AJB$16 | E9: ='Scenario Engine'!AJB$28 | F9: ='Scenario Engine'!AJU$28 | G9: ='Scenario Engine'!AJU$64
A10: 50 | B10: =SUM('Scenario Engine'!AKF$5:'Scenario Engine'!AKF$16) | C10: ='Scenario Engine'!AKW$16 | D10: ='Scenario Engine'!AKX$16 | E10: ='Scenario Engine'!AKX$28 | F10: ='Scenario Engine'!ALQ$28 | G10: ='Scenario Engine'!ALQ$64
A11: 60 | B11: =SUM('Scenario Engine'!AMB$5:'Scenario Engine'!AMB$16) | C11: ='Scenario Engine'!AMS$16 | D11: ='Scenario Engine'!AMT$16 | E11: ='Scenario Engine'!AMT$28 | F11: ='Scenario Engine'!ANM$28 | G11: ='Scenario Engine'!ANM$64
A12: 70 | B12: =SUM('Scenario Engine'!ANX$5:'Scenario Engine'!ANX$16) | C12: ='Scenario Engine'!AOO$16 | D12: ='Scenario Engine'!AOP$16 | E12: ='Scenario Engine'!AOP$28 | F12: ='Scenario Engine'!API$28 | G12: ='Scenario Engine'!API$64
A13: 80 | B13: =SUM('Scenario Engine'!APT$5:'Scenario Engine'!APT$16) | C13: ='Scenario Engine'!AQK$16 | D13: ='Scenario Engine'!AQL$16 | E13: ='Scenario Engine'!AQL$28 | F13: ='Scenario Engine'!ARE$28 | G13: ='Scenario Engine'!ARE$64
A14: 100 | B14: =SUM('Scenario Engine'!ARP$5:'Scenario Engine'!ARP$16) | C14: ='Scenario Engine'!ASG$16 | D14: ='Scenario Engine'!ASH$16 | E14: ='Scenario Engine'!ASH$28 | F14: ='Scenario Engine'!ATA$28 | G14: ='Scenario Engine'!ATA$64
A15: 120 | B15: =SUM('Scenario Engine'!ATL$5:'Scenario Engine'!ATL$16) | C15: ='Scenario Engine'!AUC$16 | D15: ='Scenario Engine'!AUD$16 | E15: ='Scenario Engine'!AUD$28 | F15: ='Scenario Engine'!AUW$28 | G15: ='Scenario Engine'!AUW$64

Sheet Sens - Winter Pivot
A1: Winter Pivot — Property Care Scenario (v3 Elite)
A2: Compares base garden seasonality vs year-round property care. Edit yellow cells. Pivot seasonality: Inputs cols E & F.
A4: SCENARIO ASSUMPTIONS
A5: Positioning | B5: Year-round property care subscription (mowing pauses Dec–Feb; gutter, leaf & patio included on Premium)
A6: Essential tier mix | B6: 0.65
A7: Premium price uplift (£/mo) | B7: 10
A8: Same as base | B8: CAC, churn rates, marketing & pricing otherwise from Inputs
A11: SEASONALITY COMPARISON (calendar month)
A12: Month | B12: Base acq | C12: Pivot acq | D12: Δ acq | E12: Base churn× | F12: Pivot churn× | G12: Δ churn
A13: Jan | B13: =Inputs!B74 | C13: =Inputs!E74 | D13: =C13-B13 | E13: =Inputs!D74 | F13: =Inputs!F74 | G13: =F13-E13
A14: Feb | B14: =Inputs!B75 | C14: =Inputs!E75 | D14: =C14-B14 | E14: =Inputs!D75 | F14: =Inputs!F75 | G14: =F14-E14
A15: Mar | B15: =Inputs!B76 | C15: =Inputs!E76 | D15: =C15-B15 | E15: =Inputs!D76 | F15: =Inputs!F76 | G15: =F15-E15
A16: Apr | B16: =Inputs!B77 | C16: =Inputs!E77 | D16: =C16-B16 | E16: =Inputs!D77 | F16: =Inputs!F77 | G16: =F16-E16
A17: May | B17: =Inputs!B78 | C17: =Inputs!E78 | D17: =C17-B17 | E17: =Inputs!D78 | F17: =Inputs!F78 | G17: =F17-E17
A18: Jun | B18: =Inputs!B79 | C18: =Inputs!E79 | D18: =C18-B18 | E18: =Inputs!D79 | F18: =Inputs!F79 | G18: =F18-E18
A19: Jul | B19: =Inputs!B80 | C19: =Inputs!E80 | D19: =C19-B19 | E19: =Inputs!D80 | F19: =Inputs!F80 | G19: =F19-E19
A20: Aug | B20: =Inputs!B81 | C20: =Inputs!E81 | D20: =C20-B20 | E20: =Inputs!D81 | F20: =Inputs!F81 | G20: =F20-E20
A21: Sep | B21: =Inputs!B82 | C21: =Inputs!E82 | D21: =C21-B21 | E21: =Inputs!D82 | F21: =Inputs!F82 | G21: =F21-E21
A22: Oct | B22: =Inputs!B83 | C22: =Inputs!E83 | D22: =C22-B22 | E22: =Inputs!D83 | F22: =Inputs!F83 | G22: =F22-E22
A23: Nov | B23: =Inputs!B84 | C23: =Inputs!E84 | D23: =C23-B23 | E23: =Inputs!D84 | F23: =Inputs!F84 | G23: =F23-E23
A24: Dec | B24: =Inputs!B85 | C24: =Inputs!E85 | D24: =C24-B24 | E24: =Inputs!D85 | F24: =Inputs!F85 | G24: =F24-E24
A27: OUTPUT COMPARISON — Base vs Winter Pivot (full model engine)
A28: Base = standard seasonality (Inputs cols B & D). Winter Pivot = cols E & F + Premium property care bundle.
A30: Metric | B30: Base | C30: Winter Pivot | D30: Delta
A31: End Year 1 — Customers | B31: ='Scenario Engine'!BU$16 | C31: ='Scenario Engine'!AVY$16 | D31: =C31-B31
A32: End Year 1 — MRR (£) | B32: ='Scenario Engine'!BV$16 | C32: ='Scenario Engine'!AVZ$16 | D32: =C32-B32
A33: End Year 1 — ARR (£) | B33: ='Scenario Engine'!BW$16 | C33: ='Scenario Engine'!AWA$16 | D33: =C33-B33
A34: End Year 1 — Cash (£) | B34: ='Scenario Engine'!CO$16 | C34: ='Scenario Engine'!AWS$16 | D34: =C34-B34
A35: Year 1 — Gross Revenue (£) | B35: =SUM('Scenario Engine'!CA$5:'Scenario Engine'!CA$16) | C35: =SUM('Scenario Engine'!AWE$5:'Scenario Engine'!AWE$16) | D35: =C35-B35
A36: Year 1 — Profit (£) | B36: =SUM('Scenario Engine'!CN$5:'Scenario Engine'!CN$16) | C36: =SUM('Scenario Engine'!AWR$5:'Scenario Engine'!AWR$16) | D36: =C36-B36
A37: End Year 2 — Customers | B37: ='Scenario Engine'!BU$28 | C37: ='Scenario Engine'!AVY$28 | D37: =C37-B37
A38: End Year 2 — MRR (£) | B38: ='Scenario Engine'!BV$28 | C38: ='Scenario Engine'!AVZ$28 | D38: =C38-B38
A39: End Year 2 — Cash (£) | B39: ='Scenario Engine'!CO$28 | C39: ='Scenario Engine'!AWS$28 | D39: =C39-B39
A40: End Year 5 — Customers | B40: ='Scenario Engine'!BU$64 | C40: ='Scenario Engine'!AVY$64 | D40: =C40-B40
A41: End Year 5 — MRR (£) | B41: ='Scenario Engine'!BV$64 | C41: ='Scenario Engine'!AVZ$64 | D41: =C41-B41
A42: End Year 5 — Cash (£) | B42: ='Scenario Engine'!CO$64 | C42: ='Scenario Engine'!AWS$64 | D42: =C42-B42

Sheet Model
A1: 60-Month Model v4 — 10/20/30 visits per year + VAT principal/agent toggle
A4: Mo | B4: Cal | C4: CY | D4: Acq | E4: Infl | F4: ECh | G4: Mkt | H4: Paid | I4: Ref | J4: Tot | K4: NMo | L4: NAn | M4: NEsM | N4: NPrM | O4: NElM | P4: NEsA | Q4: NPrA | R4: NElA | S4: AEsM | T4: APrM | U4: AElM | V4: AEsA | W4: APrA | X4: AElA | Y4: Cust | Z4: MRR | AA4: ARR | AB4: Mo$ | AC4: NwAn | AD4: Ren | AE4: Gross | AF4: R12 | AG4: VAT | AH4: Net | AI4: VAcc | AJ4: VPay | AK4: VBal | AL4: Prov | AM4: Fee | AN4: Ops | AO4: Fix | AP4: Ref$ | AQ4: Mkt | AR4: Pft | AS4: Cash | AT4: ARPU | AU4: Chrn
A5: 1 | B5: =MOD(A5-1+LaunchMonth-1,12)+1 | C5: =INT((A5-1+LaunchMonth-1)/12)+1 | D5: =VLOOKUP(B5,SeasonTable,2,FALSE) | E5: =(1+InflationRate)^INT((A5-1)/12) | F5: =MonthlyChurn*VLOOKUP(B5,ChurnSeasonTable,4,FALSE) | G5: =MktFixed1_3 | H5: =IF(G5>0,MAX(1,ROUND(G5/CAC*D5,0)),0) | I5: =IF(H5>0,ROUND(H5*ReferralMix/(1-ReferralMix),0),0) | J5: =H5+I5 | K5: =ROUND(J5*(1-AnnualMix),0) | L5: =J5-K5 | M5: =ROUND(K5*EssentialMix,0) | N5: =ROUND(K5*PremiumMix,0) | O5: =K5-M5-N5 | P5: =ROUND(L5*EssentialMix,0) | Q5: =ROUND(L5*PremiumMix,0) | R5: =L5-P5-Q5 | S5: =M5 | T5: =N5 | U5: =O5 | V5: =P5 | W5: =Q5 | X5: =R5 | Y5: =S5+T5+U5+V5+W5+X5 | Z5: =S5*BlendedPriceEssMonthly*E5+T5*BlendedPricePremMonthly*E5+U5*BlendedPriceEliteMonthly*E5+V5*BlendedPriceEssAnnual*E5/12+W5*BlendedPricePremAnnual*E5/12+X5*BlendedPriceEliteAnnual*E5/12 | AA5: =Z5*12 | AB5: =S5*BlendedPriceEssMonthly*E5+T5*BlendedPricePremMonthly*E5+U5*BlendedPriceEliteMonthly*E5 | AC5: =P5*BlendedPriceEssAnnual*E5+Q5*BlendedPricePremAnnual*E5+R5*BlendedPriceEliteAnnual*E5 | AD5: =0+0+0 | AE5: =AB5+AC5+AD5 | AF5: =SUM(AE$5:AE5) | AG5: =IF(VATAgentMode,SUM($AE$5:$AE5)-SUM($AL$5:$AL5)>=VATThreshold,SUM($AE$5:$AE5)>=VATThreshold) | AH5: =IF(AG5,IF(VATAgentMode,AE5-((AE5-AL5)-(AE5-AL5)/(1+VATRate)),AE5/(1+VATRate)),AE5) | AI5: =AE5-AH5 | AJ5: =IF(AG5=0,0,IF(B5=1,SUMPRODUCT(--(($C$5:$C5=$C5-1)*($B$5:$B5>=10)*($B$5:$B5<=12)),$AI$5:$AI5),IF(B5=4,SUMPRODUCT(--(($C$5:$C5=$C5)*($B$5:$B5>=1)*($B$5:$B5<=3)),$AI$5:$AI5),IF(B5=7,SUMPRODUCT(--(($C$5:$C5=$C5)*($B$5:$B5>=4)*($B$5:$B5<=6)),$AI$5:$AI5),IF(B5=10,SUMPRODUCT(--(($C$5:$C5=$C5)*($B$5:$B5>=7)*($B$5:$B5<=9)),$AI$5:$AI5),0))))) | AK5: =AI5-AJ5 | AL5: =IF(ProviderDelay>=1,0,S5*BlendedProvPayEss+T5*BlendedProvPayPrem+U5*BlendedProvPayElite+V5*BlendedProvPayEss+W5*BlendedProvPayPrem+X5*BlendedProvPayElite) | AM5: =AE5*PaymentFee | AN5: =Y5*OpsAI | AO5: =MonthlyFixed | AP5: =I5*ReferralReward | AQ5: =G5 | AR5: =AH5-AL5-AM5-AN5-AO5-AP5-AQ5 | AS5: =InitialInvestment+AE5-(AL5+AM5+AN5+AO5+AP5+AQ5+AJ5) | AT5: =IF(Y5>0,Z5/Y5,0) | AU5: 0
A6: 2 | B6: =MOD(A6-1+LaunchMonth-1,12)+1 | C6: =INT((A6-1+LaunchMonth-1)/12)+1 | D6: =VLOOKUP(B6,SeasonTable,2,FALSE) | E6: =(1+InflationRate)^INT((A6-1)/12) | F6: =MonthlyChurn*VLOOKUP(B6,ChurnSeasonTable,4,FALSE) | G6: =MktFixed1_3 | H6: =IF(G6>0,MAX(1,ROUND(G6/CAC*D6,0)),0) | I6: =IF(H6>0,ROUND(H6*ReferralMix/(1-ReferralMix),0),0) | J6: =H6+I6 | K6: =ROUND(J6*(1-AnnualMix),0) | L6: =J6-K6 | M6: =ROUND(K6*EssentialMix,0) | N6: =ROUND(K6*PremiumMix,0) | O6: =K6-M6-N6 | P6: =ROUND(L6*EssentialMix,0) | Q6: =ROUND(L6*PremiumMix,0) | R6: =L6-P6-Q6 | S6: =M6+M5 | T6: =N6+N5 | U6: =O6+O5 | V6: =SUM(P$5:P6) | W6: =SUM(Q$5:Q6) | X6: =SUM(R$5:R6) | Y6: =S6+T6+U6+V6+W6+X6 | Z6: =S6*BlendedPriceEssMonthly*E6+T6*BlendedPricePremMonthly*E6+U6*BlendedPriceEliteMonthly*E6+V6*BlendedPriceEssAnnual*E6/12+W6*BlendedPricePremAnnual*E6/12+X6*BlendedPriceEliteAnnual*E6/12 | AA6: =Z6*12 | AB6: =S6*BlendedPriceEssMonthly*E6+T6*BlendedPricePremMonthly*E6+U6*BlendedPriceEliteMonthly*E6 | AC6: =P6*BlendedPriceEssAnnual*E6+Q6*BlendedPricePremAnnual*E6+R6*BlendedPriceEliteAnnual*E6 | AD6: =0+0+0 | AE6: =AB6+AC6+AD6 | AF6: =SUM(AE$5:AE6) | AG6: =OR(AG5,IF(VATAgentMode,SUM($AE$5:$AE6)-SUM($AL$5:$AL6)>=VATThreshold,SUM($AE$5:$AE6)>=VATThreshold)) | AH6: =IF(AG6,IF(VATAgentMode,AE6-((AE6-AL6)-(AE6-AL6)/(1+VATRate)),AE6/(1+VATRate)),AE6) | AI6: =AE6-AH6 | AJ6: =IF(AG6=0,0,IF(B6=1,SUMPRODUCT(--(($C$5:$C6=$C6-1)*($B$5:$B6>=10)*($B$5:$B6<=12)),$AI$5:$AI6),IF(B6=4,SUMPRODUCT(--(($C$5:$C6=$C6)*($B$5:$B6>=1)*($B$5:$B6<=3)),$AI$5:$AI6),IF(B6=7,SUMPRODUCT(--(($C$5:$C6=$C6)*($B$5:$B6>=4)*($B$5:$B6<=6)),$AI$5:$AI6),IF(B6=10,SUMPRODUCT(--(($C$5:$C6=$C6)*($B$5:$B6>=7)*($B$5:$B6<=9)),$AI$5:$AI6),0))))) | AK6: =AK5+AI6-AJ6 | AL6: =IF(ProviderDelay>=1,S5*BlendedProvPayEss+T5*BlendedProvPayPrem+U5*BlendedProvPayElite+V5*BlendedProvPayEss+W5*BlendedProvPayPrem+X5*BlendedProvPayElite,S6*BlendedProvPayEss+T6*BlendedProvPayPrem+U6*BlendedProvPayElite+V6*BlendedProvPayEss+W6*BlendedProvPayPrem+X6*BlendedProvPayElite) | AM6: =AE6*PaymentFee | AN6: =Y6*OpsAI | AO6: =MonthlyFixed | AP6: =I6*ReferralReward | AQ6: =G6 | AR6: =AH6-AL6-AM6-AN6-AO6-AP6-AQ6 | AS6: =AS5+AE6-(AL6+AM6+AN6+AO6+AP6+AQ6+AJ6) | AT6: =IF(Y6>0,Z6/Y6,0) | AU6: =IF(Y5>0,MAX(0,(Y5+J6-Y6)/Y5),0)
A7: 3 | B7: =MOD(A7-1+LaunchMonth-1,12)+1 | C7: =INT((A7-1+LaunchMonth-1)/12)+1 | D7: =VLOOKUP(B7,SeasonTable,2,FALSE) | E7: =(1+InflationRate)^INT((A7-1)/12) | F7: =MonthlyChurn*VLOOKUP(B7,ChurnSeasonTable,4,FALSE) | G7: =MktFixed1_3 | H7: =IF(G7>0,MAX(1,ROUND(G7/CAC*D7,0)),0) | I7: =IF(H7>0,ROUND(H7*ReferralMix/(1-ReferralMix),0),0) | J7: =H7+I7 | K7: =ROUND(J7*(1-AnnualMix),0) | L7: =J7-K7 | M7: =ROUND(K7*EssentialMix,0) | N7: =ROUND(K7*PremiumMix,0) | O7: =K7-M7-N7 | P7: =ROUND(L7*EssentialMix,0) | Q7: =ROUND(L7*PremiumMix,0) | R7: =L7-P7-Q7 | S7: =M7+M6+M5 | T7: =N7+N6+N5 | U7: =O7+O6+O5 | V7: =SUM(P$5:P7) | W7: =SUM(Q$5:Q7) | X7: =SUM(R$5:R7) | Y7: =S7+T7+U7+V7+W7+X7 | Z7: =S7*BlendedPriceEssMonthly*E7+T7*BlendedPricePremMonthly*E7+U7*BlendedPriceEliteMonthly*E7+V7*BlendedPriceEssAnnual*E7/12+W7*BlendedPricePremAnnual*E7/12+X7*BlendedPriceEliteAnnual*E7/12 | AA7: =Z7*12 | AB7: =S7*BlendedPriceEssMonthly*E7+T7*BlendedPricePremMonthly*E7+U7*BlendedPriceEliteMonthly*E7 | AC7: =P7*BlendedPriceEssAnnual*E7+Q7*BlendedPricePremAnnual*E7+R7*BlendedPriceEliteAnnual*E7 | AD7: =0+0+0 | AE7: =AB7+AC7+AD7 | AF7: =SUM(AE$5:AE7) | AG7: =OR(AG6,IF(VATAgentMode,SUM($AE$5:$AE7)-SUM($AL$5:$AL7)>=VATThreshold,SUM($AE$5:$AE7)>=VATThreshold)) | AH7: =IF(AG7,IF(VATAgentMode,AE7-((AE7-AL7)-(AE7-AL7)/(1+VATRate)),AE7/(1+VATRate)),AE7) | AI7: =AE7-AH7 | AJ7: =IF(AG7=0,0,IF(B7=1,SUMPRODUCT(--(($C$5:$C7=$C7-1)*($B$5:$B7>=10)*($B$5:$B7<=12)),$AI$5:$AI7),IF(B7=4,SUMPRODUCT(--(($C$5:$C7=$C7)*($B$5:$B7>=1)*($B$5:$B7<=3)),$AI$5:$AI7),IF(B7=7,SUMPRODUCT(--(($C$5:$C7=$C7)*($B$5:$B7>=4)*($B$5:$B7<=6)),$AI$5:$AI7),IF(B7=10,SUMPRODUCT(--(($C$5:$C7=$C7)*($B$5:$B7>=7)*($B$5:$B7<=9)),$AI$5:$AI7),0))))) | AK7: =AK6+AI7-AJ7 | AL7: =IF(ProviderDelay>=1,S6*BlendedProvPayEss+T6*BlendedProvPayPrem+U6*BlendedProvPayElite+V6*BlendedProvPayEss+W6*BlendedProvPayPrem+X6*BlendedProvPayElite,S7*BlendedProvPayEss+T7*BlendedProvPayPrem+U7*BlendedProvPayElite+V7*BlendedProvPayEss+W7*BlendedProvPayPrem+X7*BlendedProvPayElite) | AM7: =AE7*PaymentFee | AN7: =Y7*OpsAI | AO7: =MonthlyFixed | AP7: =I7*ReferralReward | AQ7: =G7 | AR7: =AH7-AL7-AM7-AN7-AO7-AP7-AQ7 | AS7: =AS6+AE7-(AL7+AM7+AN7+AO7+AP7+AQ7+AJ7) | AT7: =IF(Y7>0,Z7/Y7,0) | AU7: =IF(Y6>0,MAX(0,(Y6+J7-Y7)/Y6),0)
A8: 4 | B8: =MOD(A8-1+LaunchMonth-1,12)+1 | C8: =INT((A8-1+LaunchMonth-1)/12)+1 | D8: =VLOOKUP(B8,SeasonTable,2,FALSE) | E8: =(1+InflationRate)^INT((A8-1)/12) | F8: =MonthlyChurn*VLOOKUP(B8,ChurnSeasonTable,4,FALSE) | G8: =MIN(MktFixed4_6,MAX(0,AS7-CashBuffer)) | H8: =IF(G8>0,MAX(1,ROUND(G8/CAC*D8,0)),0) | I8: =IF(H8>0,ROUND(H8*ReferralMix/(1-ReferralMix),0),0) | J8: =H8+I8 | K8: =ROUND(J8*(1-AnnualMix),0) | L8: =J8-K8 | M8: =ROUND(K8*EssentialMix,0) | N8: =ROUND(K8*PremiumMix,0) | O8: =K8-M8-N8 | P8: =ROUND(L8*EssentialMix,0) | Q8: =ROUND(L8*PremiumMix,0) | R8: =L8-P8-Q8 | S8: =M8+M7+M6+MAX(0,S7-M7-M6)*(1-F8) | T8: =N8+N7+N6+MAX(0,T7-N7-N6)*(1-F8) | U8: =O8+O7+O6+MAX(0,U7-O7-O6)*(1-F8) | V8: =SUM(P$5:P8) | W8: =SUM(Q$5:Q8) | X8: =SUM(R$5:R8) | Y8: =S8+T8+U8+V8+W8+X8 | Z8: =S8*BlendedPriceEssMonthly*E8+T8*BlendedPricePremMonthly*E8+U8*BlendedPriceEliteMonthly*E8+V8*BlendedPriceEssAnnual*E8/12+W8*BlendedPricePremAnnual*E8/12+X8*BlendedPriceEliteAnnual*E8/12 | AA8: =Z8*12 | AB8: =S8*BlendedPriceEssMonthly*E8+T8*BlendedPricePremMonthly*E8+U8*BlendedPriceEliteMonthly*E8 | AC8: =P8*BlendedPriceEssAnnual*E8+Q8*BlendedPricePremAnnual*E8+R8*BlendedPriceEliteAnnual*E8 | AD8: =0+0+0 | AE8: =AB8+AC8+AD8 | AF8: =SUM(AE$5:AE8) | AG8: =OR(AG7,IF(VATAgentMode,SUM($AE$5:$AE8)-SUM($AL$5:$AL8)>=VATThreshold,SUM($AE$5:$AE8)>=VATThreshold)) | AH8: =IF(AG8,IF(VATAgentMode,AE8-((AE8-AL8)-(AE8-AL8)/(1+VATRate)),AE8/(1+VATRate)),AE8) | AI8: =AE8-AH8 | AJ8: =IF(AG8=0,0,IF(B8=1,SUMPRODUCT(--(($C$5:$C8=$C8-1)*($B$5:$B8>=10)*($B$5:$B8<=12)),$AI$5:$AI8),IF(B8=4,SUMPRODUCT(--(($C$5:$C8=$C8)*($B$5:$B8>=1)*($B$5:$B8<=3)),$AI$5:$AI8),IF(B8=7,SUMPRODUCT(--(($C$5:$C8=$C8)*($B$5:$B8>=4)*($B$5:$B8<=6)),$AI$5:$AI8),IF(B8=10,SUMPRODUCT(--(($C$5:$C8=$C8)*($B$5:$B8>=7)*($B$5:$B8<=9)),$AI$5:$AI8),0))))) | AK8: =AK7+AI8-AJ8 | AL8: =IF(ProviderDelay>=1,S7*BlendedProvPayEss+T7*BlendedProvPayPrem+U7*BlendedProvPayElite+V7*BlendedProvPayEss+W7*BlendedProvPayPrem+X7*BlendedProvPayElite,S8*BlendedProvPayEss+T8*BlendedProvPayPrem+U8*BlendedProvPayElite+V8*BlendedProvPayEss+W8*BlendedProvPayPrem+X8*BlendedProvPayElite) | AM8: =AE8*PaymentFee | AN8: =Y8*OpsAI | AO8: =MonthlyFixed | AP8: =I8*ReferralReward | AQ8: =G8 | AR8: =AH8-AL8-AM8-AN8-AO8-AP8-AQ8 | AS8: =AS7+AE8-(AL8+AM8+AN8+AO8+AP8+AQ8+AJ8) | AT8: =IF(Y8>0,Z8/Y8,0) | AU8: =IF(Y7>0,MAX(0,(Y7+J8-Y8)/Y7),0)
A9: 5 | B9: =MOD(A9-1+LaunchMonth-1,12)+1 | C9: =INT((A9-1+LaunchMonth-1)/12)+1 | D9: =VLOOKUP(B9,SeasonTable,2,FALSE) | E9: =(1+InflationRate)^INT((A9-1)/12) | F9: =MonthlyChurn*VLOOKUP(B9,ChurnSeasonTable,4,FALSE) | G9: =MIN(MktFixed4_6,MAX(0,AS8-CashBuffer)) | H9: =IF(G9>0,MAX(1,ROUND(G9/CAC*D9,0)),0) | I9: =IF(H9>0,ROUND(H9*ReferralMix/(1-ReferralMix),0),0) | J9: =H9+I9 | K9: =ROUND(J9*(1-AnnualMix),0) | L9: =J9-K9 | M9: =ROUND(K9*EssentialMix,0) | N9: =ROUND(K9*PremiumMix,0) | O9: =K9-M9-N9 | P9: =ROUND(L9*EssentialMix,0) | Q9: =ROUND(L9*PremiumMix,0) | R9: =L9-P9-Q9 | S9: =M9+M8+M7+MAX(0,S8-M8-M7)*(1-F9) | T9: =N9+N8+N7+MAX(0,T8-N8-N7)*(1-F9) | U9: =O9+O8+O7+MAX(0,U8-O8-O7)*(1-F9) | V9: =SUM(P$5:P9) | W9: =SUM(Q$5:Q9) | X9: =SUM(R$5:R9) | Y9: =S9+T9+U9+V9+W9+X9 | Z9: =S9*BlendedPriceEssMonthly*E9+T9*BlendedPricePremMonthly*E9+U9*BlendedPriceEliteMonthly*E9+V9*BlendedPriceEssAnnual*E9/12+W9*BlendedPricePremAnnual*E9/12+X9*BlendedPriceEliteAnnual*E9/12 | AA9: =Z9*12 | AB9: =S9*BlendedPriceEssMonthly*E9+T9*BlendedPricePremMonthly*E9+U9*BlendedPriceEliteMonthly*E9 | AC9: =P9*BlendedPriceEssAnnual*E9+Q9*BlendedPricePremAnnual*E9+R9*BlendedPriceEliteAnnual*E9 | AD9: =0+0+0 | AE9: =AB9+AC9+AD9 | AF9: =SUM(AE$5:AE9) | AG9: =OR(AG8,IF(VATAgentMode,SUM($AE$5:$AE9)-SUM($AL$5:$AL9)>=VATThreshold,SUM($AE$5:$AE9)>=VATThreshold)) | AH9: =IF(AG9,IF(VATAgentMode,AE9-((AE9-AL9)-(AE9-AL9)/(1+VATRate)),AE9/(1+VATRate)),AE9) | AI9: =AE9-AH9 | AJ9: =IF(AG9=0,0,IF(B9=1,SUMPRODUCT(--(($C$5:$C9=$C9-1)*($B$5:$B9>=10)*($B$5:$B9<=12)),$AI$5:$AI9),IF(B9=4,SUMPRODUCT(--(($C$5:$C9=$C9)*($B$5:$B9>=1)*($B$5:$B9<=3)),$AI$5:$AI9),IF(B9=7,SUMPRODUCT(--(($C$5:$C9=$C9)*($B$5:$B9>=4)*($B$5:$B9<=6)),$AI$5:$AI9),IF(B9=10,SUMPRODUCT(--(($C$5:$C9=$C9)*($B$5:$B9>=7)*($B$5:$B9<=9)),$AI$5:$AI9),0))))) | AK9: =AK8+AI9-AJ9 | AL9: =IF(ProviderDelay>=1,S8*BlendedProvPayEss+T8*BlendedProvPayPrem+U8*BlendedProvPayElite+V8*BlendedProvPayEss+W8*BlendedProvPayPrem+X8*BlendedProvPayElite,S9*BlendedProvPayEss+T9*BlendedProvPayPrem+U9*BlendedProvPayElite+V9*BlendedProvPayEss+W9*BlendedProvPayPrem+X9*BlendedProvPayElite) | AM9: =AE9*PaymentFee | AN9: =Y9*OpsAI | AO9: =MonthlyFixed | AP9: =I9*ReferralReward | AQ9: =G9 | AR9: =AH9-AL9-AM9-AN9-AO9-AP9-AQ9 | AS9: =AS8+AE9-(AL9+AM9+AN9+AO9+AP9+AQ9+AJ9) | AT9: =IF(Y9>0,Z9/Y9,0) | AU9: =IF(Y8>0,MAX(0,(Y8+J9-Y9)/Y8),0)
A10: 6 | B10: =MOD(A10-1+LaunchMonth-1,12)+1 | C10: =INT((A10-1+LaunchMonth-1)/12)+1 | D10: =VLOOKUP(B10,SeasonTable,2,FALSE) | E10: =(1+InflationRate)^INT((A10-1)/12) | F10: =MonthlyChurn*VLOOKUP(B10,ChurnSeasonTable,4,FALSE) | G10: =MIN(MktFixed4_6,MAX(0,AS9-CashBuffer)) | H10: =IF(G10>0,MAX(1,ROUND(G10/CAC*D10,0)),0) | I10: =IF(H10>0,ROUND(H10*ReferralMix/(1-ReferralMix),0),0) | J10: =H10+I10 | K10: =ROUND(J10*(1-AnnualMix),0) | L10: =J10-K10 | M10: =ROUND(K10*EssentialMix,0) | N10: =ROUND(K10*PremiumMix,0) | O10: =K10-M10-N10 | P10: =ROUND(L10*EssentialMix,0) | Q10: =ROUND(L10*PremiumMix,0) | R10: =L10-P10-Q10 | S10: =M10+M9+M8+MAX(0,S9-M9-M8)*(1-F10) | T10: =N10+N9+N8+MAX(0,T9-N9-N8)*(1-F10) | U10: =O10+O9+O8+MAX(0,U9-O9-O8)*(1-F10) | V10: =SUM(P$5:P10) | W10: =SUM(Q$5:Q10) | X10: =SUM(R$5:R10) | Y10: =S10+T10+U10+V10+W10+X10 | Z10: =S10*BlendedPriceEssMonthly*E10+T10*BlendedPricePremMonthly*E10+U10*BlendedPriceEliteMonthly*E10+V10*BlendedPriceEssAnnual*E10/12+W10*BlendedPricePremAnnual*E10/12+X10*BlendedPriceEliteAnnual*E10/12 | AA10: =Z10*12 | AB10: =S10*BlendedPriceEssMonthly*E10+T10*BlendedPricePremMonthly*E10+U10*BlendedPriceEliteMonthly*E10 | AC10: =P10*BlendedPriceEssAnnual*E10+Q10*BlendedPricePremAnnual*E10+R10*BlendedPriceEliteAnnual*E10 | AD10: =0+0+0 | AE10: =AB10+AC10+AD10 | AF10: =SUM(AE$5:AE10) | AG10: =OR(AG9,IF(VATAgentMode,SUM($AE$5:$AE10)-SUM($AL$5:$AL10)>=VATThreshold,SUM($AE$5:$AE10)>=VATThreshold)) | AH10: =IF(AG10,IF(VATAgentMode,AE10-((AE10-AL10)-(AE10-AL10)/(1+VATRate)),AE10/(1+VATRate)),AE10) | AI10: =AE10-AH10 | AJ10: =IF(AG10=0,0,IF(B10=1,SUMPRODUCT(--(($C$5:$C10=$C10-1)*($B$5:$B10>=10)*($B$5:$B10<=12)),$AI$5:$AI10),IF(B10=4,SUMPRODUCT(--(($C$5:$C10=$C10)*($B$5:$B10>=1)*($B$5:$B10<=3)),$AI$5:$AI10),IF(B10=7,SUMPRODUCT(--(($C$5:$C10=$C10)*($B$5:$B10>=4)*($B$5:$B10<=6)),$AI$5:$AI10),IF(B10=10,SUMPRODUCT(--(($C$5:$C10=$C10)*($B$5:$B10>=7)*($B$5:$B10<=9)),$AI$5:$AI10),0))))) | AK10: =AK9+AI10-AJ10 | AL10: =IF(ProviderDelay>=1,S9*BlendedProvPayEss+T9*BlendedProvPayPrem+U9*BlendedProvPayElite+V9*BlendedProvPayEss+W9*BlendedProvPayPrem+X9*BlendedProvPayElite,S10*BlendedProvPayEss+T10*BlendedProvPayPrem+U10*BlendedProvPayElite+V10*BlendedProvPayEss+W10*BlendedProvPayPrem+X10*BlendedProvPayElite) | AM10: =AE10*PaymentFee | AN10: =Y10*OpsAI | AO10: =MonthlyFixed | AP10: =I10*ReferralReward | AQ10: =G10 | AR10: =AH10-AL10-AM10-AN10-AO10-AP10-AQ10 | AS10: =AS9+AE10-(AL10+AM10+AN10+AO10+AP10+AQ10+AJ10) | AT10: =IF(Y10>0,Z10/Y10,0) | AU10: =IF(Y9>0,MAX(0,(Y9+J10-Y10)/Y9),0)
A11: 7 | B11: =MOD(A11-1+LaunchMonth-1,12)+1 | C11: =INT((A11-1+LaunchMonth-1)/12)+1 | D11: =VLOOKUP(B11,SeasonTable,2,FALSE) | E11: =(1+InflationRate)^INT((A11-1)/12) | F11: =MonthlyChurn*VLOOKUP(B11,ChurnSeasonTable,4,FALSE) | G11: =MIN(MAX(MktMin7_12,AE10*MktPct7_12),MAX(0,AS10-CashBuffer)) | H11: =IF(G11>0,MAX(1,ROUND(G11/CAC*D11,0)),0) | I11: =IF(H11>0,ROUND(H11*ReferralMix/(1-ReferralMix),0),0) | J11: =H11+I11 | K11: =ROUND(J11*(1-AnnualMix),0) | L11: =J11-K11 | M11: =ROUND(K11*EssentialMix,0) | N11: =ROUND(K11*PremiumMix,0) | O11: =K11-M11-N11 | P11: =ROUND(L11*EssentialMix,0) | Q11: =ROUND(L11*PremiumMix,0) | R11: =L11-P11-Q11 | S11: =M11+M10+M9+MAX(0,S10-M10-M9)*(1-F11) | T11: =N11+N10+N9+MAX(0,T10-N10-N9)*(1-F11) | U11: =O11+O10+O9+MAX(0,U10-O10-O9)*(1-F11) | V11: =SUM(P$5:P11) | W11: =SUM(Q$5:Q11) | X11: =SUM(R$5:R11) | Y11: =S11+T11+U11+V11+W11+X11 | Z11: =S11*BlendedPriceEssMonthly*E11+T11*BlendedPricePremMonthly*E11+U11*BlendedPriceEliteMonthly*E11+V11*BlendedPriceEssAnnual*E11/12+W11*BlendedPricePremAnnual*E11/12+X11*BlendedPriceEliteAnnual*E11/12 | AA11: =Z11*12 | AB11: =S11*BlendedPriceEssMonthly*E11+T11*BlendedPricePremMonthly*E11+U11*BlendedPriceEliteMonthly*E11 | AC11: =P11*BlendedPriceEssAnnual*E11+Q11*BlendedPricePremAnnual*E11+R11*BlendedPriceEliteAnnual*E11 | AD11: =0+0+0 | AE11: =AB11+AC11+AD11 | AF11: =SUM(AE$5:AE11) | AG11: =OR(AG10,IF(VATAgentMode,SUM($AE$5:$AE11)-SUM($AL$5:$AL11)>=VATThreshold,SUM($AE$5:$AE11)>=VATThreshold)) | AH11: =IF(AG11,IF(VATAgentMode,AE11-((AE11-AL11)-(AE11-AL11)/(1+VATRate)),AE11/(1+VATRate)),AE11) | AI11: =AE11-AH11 | AJ11: =IF(AG11=0,0,IF(B11=1,SUMPRODUCT(--(($C$5:$C11=$C11-1)*($B$5:$B11>=10)*($B$5:$B11<=12)),$AI$5:$AI11),IF(B11=4,SUMPRODUCT(--(($C$5:$C11=$C11)*($B$5:$B11>=1)*($B$5:$B11<=3)),$AI$5:$AI11),IF(B11=7,SUMPRODUCT(--(($C$5:$C11=$C11)*($B$5:$B11>=4)*($B$5:$B11<=6)),$AI$5:$AI11),IF(B11=10,SUMPRODUCT(--(($C$5:$C11=$C11)*($B$5:$B11>=7)*($B$5:$B11<=9)),$AI$5:$AI11),0))))) | AK11: =AK10+AI11-AJ11 | AL11: =IF(ProviderDelay>=1,S10*BlendedProvPayEss+T10*BlendedProvPayPrem+U10*BlendedProvPayElite+V10*BlendedProvPayEss+W10*BlendedProvPayPrem+X10*BlendedProvPayElite,S11*BlendedProvPayEss+T11*BlendedProvPayPrem+U11*BlendedProvPayElite+V11*BlendedProvPayEss+W11*BlendedProvPayPrem+X11*BlendedProvPayElite) | AM11: =AE11*PaymentFee | AN11: =Y11*OpsAI | AO11: =MonthlyFixed | AP11: =I11*ReferralReward | AQ11: =G11 | AR11: =AH11-AL11-AM11-AN11-AO11-AP11-AQ11 | AS11: =AS10+AE11-(AL11+AM11+AN11+AO11+AP11+AQ11+AJ11) | AT11: =IF(Y11>0,Z11/Y11,0) | AU11: =IF(Y10>0,MAX(0,(Y10+J11-Y11)/Y10),0)
A12: 8 | B12: =MOD(A12-1+LaunchMonth-1,12)+1 | C12: =INT((A12-1+LaunchMonth-1)/12)+1 | D12: =VLOOKUP(B12,SeasonTable,2,FALSE) | E12: =(1+InflationRate)^INT((A12-1)/12) | F12: =MonthlyChurn*VLOOKUP(B12,ChurnSeasonTable,4,FALSE) | G12: =MIN(MAX(MktMin7_12,AE11*MktPct7_12),MAX(0,AS11-CashBuffer)) | H12: =IF(G12>0,MAX(1,ROUND(G12/CAC*D12,0)),0) | I12: =IF(H12>0,ROUND(H12*ReferralMix/(1-ReferralMix),0),0) | J12: =H12+I12 | K12: =ROUND(J12*(1-AnnualMix),0) | L12: =J12-K12 | M12: =ROUND(K12*EssentialMix,0) | N12: =ROUND(K12*PremiumMix,0) | O12: =K12-M12-N12 | P12: =ROUND(L12*EssentialMix,0) | Q12: =ROUND(L12*PremiumMix,0) | R12: =L12-P12-Q12 | S12: =M12+M11+M10+MAX(0,S11-M11-M10)*(1-F12) | T12: =N12+N11+N10+MAX(0,T11-N11-N10)*(1-F12) | U12: =O12+O11+O10+MAX(0,U11-O11-O10)*(1-F12) | V12: =SUM(P$5:P12) | W12: =SUM(Q$5:Q12) | X12: =SUM(R$5:R12) | Y12: =S12+T12+U12+V12+W12+X12 | Z12: =S12*BlendedPriceEssMonthly*E12+T12*BlendedPricePremMonthly*E12+U12*BlendedPriceEliteMonthly*E12+V12*BlendedPriceEssAnnual*E12/12+W12*BlendedPricePremAnnual*E12/12+X12*BlendedPriceEliteAnnual*E12/12 | AA12: =Z12*12 | AB12: =S12*BlendedPriceEssMonthly*E12+T12*BlendedPricePremMonthly*E12+U12*BlendedPriceEliteMonthly*E12 | AC12: =P12*BlendedPriceEssAnnual*E12+Q12*BlendedPricePremAnnual*E12+R12*BlendedPriceEliteAnnual*E12 | AD12: =0+0+0 | AE12: =AB12+AC12+AD12 | AF12: =SUM(AE$5:AE12) | AG12: =OR(AG11,IF(VATAgentMode,SUM($AE$5:$AE12)-SUM($AL$5:$AL12)>=VATThreshold,SUM($AE$5:$AE12)>=VATThreshold)) | AH12: =IF(AG12,IF(VATAgentMode,AE12-((AE12-AL12)-(AE12-AL12)/(1+VATRate)),AE12/(1+VATRate)),AE12) | AI12: =AE12-AH12 | AJ12: =IF(AG12=0,0,IF(B12=1,SUMPRODUCT(--(($C$5:$C12=$C12-1)*($B$5:$B12>=10)*($B$5:$B12<=12)),$AI$5:$AI12),IF(B12=4,SUMPRODUCT(--(($C$5:$C12=$C12)*($B$5:$B12>=1)*($B$5:$B12<=3)),$AI$5:$AI12),IF(B12=7,SUMPRODUCT(--(($C$5:$C12=$C12)*($B$5:$B12>=4)*($B$5:$B12<=6)),$AI$5:$AI12),IF(B12=10,SUMPRODUCT(--(($C$5:$C12=$C12)*($B$5:$B12>=7)*($B$5:$B12<=9)),$AI$5:$AI12),0))))) | AK12: =AK11+AI12-AJ12 | AL12: =IF(ProviderDelay>=1,S11*BlendedProvPayEss+T11*BlendedProvPayPrem+U11*BlendedProvPayElite+V11*BlendedProvPayEss+W11*BlendedProvPayPrem+X11*BlendedProvPayElite,S12*BlendedProvPayEss+T12*BlendedProvPayPrem+U12*BlendedProvPayElite+V12*BlendedProvPayEss+W12*BlendedProvPayPrem+X12*BlendedProvPayElite) | AM12: =AE12*PaymentFee | AN12: =Y12*OpsAI | AO12: =MonthlyFixed | AP12: =I12*ReferralReward | AQ12: =G12 | AR12: =AH12-AL12-AM12-AN12-AO12-AP12-AQ12 | AS12: =AS11+AE12-(AL12+AM12+AN12+AO12+AP12+AQ12+AJ12) | AT12: =IF(Y12>0,Z12/Y12,0) | AU12: =IF(Y11>0,MAX(0,(Y11+J12-Y12)/Y11),0)
A13: 9 | B13: =MOD(A13-1+LaunchMonth-1,12)+1 | C13: =INT((A13-1+LaunchMonth-1)/12)+1 | D13: =VLOOKUP(B13,SeasonTable,2,FALSE) | E13: =(1+InflationRate)^INT((A13-1)/12) | F13: =MonthlyChurn*VLOOKUP(B13,ChurnSeasonTable,4,FALSE) | G13: =MIN(MAX(MktMin7_12,AE12*MktPct7_12),MAX(0,AS12-CashBuffer)) | H13: =IF(G13>0,MAX(1,ROUND(G13/CAC*D13,0)),0) | I13: =IF(H13>0,ROUND(H13*ReferralMix/(1-ReferralMix),0),0) | J13: =H13+I13 | K13: =ROUND(J13*(1-AnnualMix),0) | L13: =J13-K13 | M13: =ROUND(K13*EssentialMix,0) | N13: =ROUND(K13*PremiumMix,0) | O13: =K13-M13-N13 | P13: =ROUND(L13*EssentialMix,0) | Q13: =ROUND(L13*PremiumMix,0) | R13: =L13-P13-Q13 | S13: =M13+M12+M11+MAX(0,S12-M12-M11)*(1-F13) | T13: =N13+N12+N11+MAX(0,T12-N12-N11)*(1-F13) | U13: =O13+O12+O11+MAX(0,U12-O12-O11)*(1-F13) | V13: =SUM(P$5:P13) | W13: =SUM(Q$5:Q13) | X13: =SUM(R$5:R13) | Y13: =S13+T13+U13+V13+W13+X13 | Z13: =S13*BlendedPriceEssMonthly*E13+T13*BlendedPricePremMonthly*E13+U13*BlendedPriceEliteMonthly*E13+V13*BlendedPriceEssAnnual*E13/12+W13*BlendedPricePremAnnual*E13/12+X13*BlendedPriceEliteAnnual*E13/12 | AA13: =Z13*12 | AB13: =S13*BlendedPriceEssMonthly*E13+T13*BlendedPricePremMonthly*E13+U13*BlendedPriceEliteMonthly*E13 | AC13: =P13*BlendedPriceEssAnnual*E13+Q13*BlendedPricePremAnnual*E13+R13*BlendedPriceEliteAnnual*E13 | AD13: =0+0+0 | AE13: =AB13+AC13+AD13 | AF13: =SUM(AE$5:AE13) | AG13: =OR(AG12,IF(VATAgentMode,SUM($AE$5:$AE13)-SUM($AL$5:$AL13)>=VATThreshold,SUM($AE$5:$AE13)>=VATThreshold)) | AH13: =IF(AG13,IF(VATAgentMode,AE13-((AE13-AL13)-(AE13-AL13)/(1+VATRate)),AE13/(1+VATRate)),AE13) | AI13: =AE13-AH13 | AJ13: =IF(AG13=0,0,IF(B13=1,SUMPRODUCT(--(($C$5:$C13=$C13-1)*($B$5:$B13>=10)*($B$5:$B13<=12)),$AI$5:$AI13),IF(B13=4,SUMPRODUCT(--(($C$5:$C13=$C13)*($B$5:$B13>=1)*($B$5:$B13<=3)),$AI$5:$AI13),IF(B13=7,SUMPRODUCT(--(($C$5:$C13=$C13)*($B$5:$B13>=4)*($B$5:$B13<=6)),$AI$5:$AI13),IF(B13=10,SUMPRODUCT(--(($C$5:$C13=$C13)*($B$5:$B13>=7)*($B$5:$B13<=9)),$AI$5:$AI13),0))))) | AK13: =AK12+AI13-AJ13 | AL13: =IF(ProviderDelay>=1,S12*BlendedProvPayEss+T12*BlendedProvPayPrem+U12*BlendedProvPayElite+V12*BlendedProvPayEss+W12*BlendedProvPayPrem+X12*BlendedProvPayElite,S13*BlendedProvPayEss+T13*BlendedProvPayPrem+U13*BlendedProvPayElite+V13*BlendedProvPayEss+W13*BlendedProvPayPrem+X13*BlendedProvPayElite) | AM13: =AE13*PaymentFee | AN13: =Y13*OpsAI | AO13: =MonthlyFixed | AP13: =I13*ReferralReward | AQ13: =G13 | AR13: =AH13-AL13-AM13-AN13-AO13-AP13-AQ13 | AS13: =AS12+AE13-(AL13+AM13+AN13+AO13+AP13+AQ13+AJ13) | AT13: =IF(Y13>0,Z13/Y13,0) | AU13: =IF(Y12>0,MAX(0,(Y12+J13-Y13)/Y12),0)
