Workbook
Name InitialInvestment: Inputs!$B$5
Name PriceEssMonthly: Inputs!$B$8
Name PricePremMonthly: Inputs!$B$9
Name PriceEssAnnual: Inputs!$B$10
Name PricePremAnnual: Inputs!$B$11
Name AnnualMix: Inputs!$B$14
Name EssentialMix: Inputs!$B$15
Name MonthlyChurn: Inputs!$B$18
Name AnnualChurn: Inputs!$B$19
Name CAC: Inputs!$B$22
Name ProviderShare: Inputs!$B$23
Name PaymentFee: Inputs!$B$24
Name OpsAI: Inputs!$B$25
Name ProviderDelay: Inputs!$B$27
Name MonthlyFixed: Inputs!$B$28
Name MktFixed1_3: Inputs!$B$31
Name MktFixed4_6: Inputs!$B$32
Name MktPct7_12: Inputs!$B$33
Name MktPct13_18: Inputs!$B$34
Name MktPct19plus: Inputs!$B$35
Name MktMin7_12: Inputs!$B$36
Name MktMin13_18: Inputs!$B$37
Name MktMin19plus: Inputs!$B$38
Name CashBuffer: Inputs!$B$39
Name InflationRate: Inputs!$B$48
Name ReferralMix: Inputs!$B$49
Name ReferralReward: Inputs!$B$50
Name LaunchMonth: Inputs!$B$51
Name AcqSeasonTable: Inputs!$A$55:$C$66
Name ChurnSeasonTable: Inputs!$A$55:$D$66
Name SeasonTable: Inputs!$A$55:$B$66
Name VATRate: Inputs!$B$42
Name VATThreshold: Inputs!$B$43
Name MRR_Month12: Model!$V$16
Name ARR_Month12: Model!$W$16
Name Cust_Month12: Model!$U$16
Name Cash_Month12: Model!$AO$16
Name MRR_Month24: Model!$V$28
Name ARR_Month24: Model!$W$28
Name Cust_Month24: Model!$U$28
Name Cash_Month24: Model!$AO$28
Name MRR_Month60: Model!$V$64
Name ARR_Month60: Model!$W$64
Name Cust_Month60: Model!$U$64
Name Cash_Month60: Model!$AO$64
Name WinterPivotSeasonTable: Inputs!$A$55:$E$66
Name WinterPivotChurnTable: Inputs!$A$55:$F$66

Sheet Headlines
A1: GardensSorted — Financial Headlines
A2: Calendar VAT quarters | seasonal churn | provider delay | referrals | inflation
A4: KEY METRICS
A5: Y1 ARR | C5: Y2 ARR | E5: Y5 ARR | G5: Cash Y5
A6: =Model!W16 | C6: =Model!W28 | E6: =Model!W64 | G6: =Model!AO64
A8: SNAPSHOT
A9: Metric | B9: Year 1 | C9: Year 2 | D9: Year 5
A10: End customers | B10: =Model!U16 | C10: =Model!U28 | D10: =Model!U64
A11: ARR | B11: =Model!W16 | C11: =Model!W28 | D11: =Model!W64
A12: Gross revenue | B12: =SUM(Model!AA5:AA16) | C12: =SUM(Model!AA17:AA28) | D12: =SUM(Model!AA53:AA64)
A13: Net revenue | B13: =SUM(Model!AD5:AD16) | C13: =SUM(Model!AD17:AD28) | D13: =SUM(Model!AD53:AD64)
A14: VAT paid (calendar Q) | B14: =SUM(Model!AF5:AF16) | C14: =SUM(Model!AF17:AF28) | D14: =SUM(Model!AF53:AF64)
A15: Annual profit | B15: =SUM(Model!AN5:AN16) | C15: =SUM(Model!AN17:AN28) | D15: =SUM(Model!AN53:AN64)
A16: Cash balance | B16: =Model!AO16 | C16: =Model!AO28 | D16: =Model!AO64
A17: Avg logo churn | B17: =AVERAGE(Model!AQ6:AQ16) | C17: =AVERAGE(Model!AQ18:AQ28) | D17: =AVERAGE(Model!AQ54:AQ64)
A18: Platform margin | B18: ='5 Year Summary'!T4 | C18: ='5 Year Summary'!T5 | D18: ='5 Year Summary'!T8
A20: MILESTONES
A21: VAT registration | B21: =IFERROR("Month "&MATCH(TRUE,Model!AC5:Model!AC64,0),"Not in 60 mo")
A22: First profitable month | B22: =IFERROR("Month "&MATCH(1,IF(Model!AN5:AN64>0,1),0),"Not in 60 mo")
A23: Cash payback £17k | B23: =IFERROR("Month "&MATCH(1,IF(Model!AO5:AO64>=InitialInvestment,1),0),"Not in 60 mo")
A24: Provider payment delay | B24: =ProviderDelay&" month(s)"
A25: Fixed platform cost | B25: =MonthlyFixed
A27: MODEL COMPLETENESS
A28: ✓ SaaS cohorts — monthly (3-mo min) & annual (12-mo) subs, MRR/ARR, tier pricing
A29: ✓ VAT at £90k threshold — calendar quarter payments (Jan/Apr/Jul/Oct)
A30: ✓ Seasonal acquisition (col B) & churn (col D) — gardening seasonality
A31: ✓ Referrals 15% / £15 | Inflation 2.5%/yr | Upfront billing | £17k startup
A32: ✓ Provider delay 1 mo (customer upfront → cash float) | Fixed platform £250/mo
A33: ✓ Per-customer ops/AI £5/mo | Marketing phased with cash cap | No salaries (AI ops)
A34: ✓ Sensitivity tabs — churn, mix, CAC, scenarios, winter pivot
A36: NOT MODELLED (by design or later)
A37: • Corporation tax (~19–25%) — add when consistently profitable
A38: • Route density / travel efficiency in clustered postcodes
A39: • Cross-sell to other Sorted brands | Geographic rollout phasing
... A43: WHERE TO GO NEXT
A44: Inputs | B44: All assumptions
A45: 5 Year Summary | B45: Annual P&L
A46: 24 Month Forecast | B46: Monthly detail
A47: Unit Economics | B47: LTV & CAC

Sheet Assumptions
A1: Assumptions & Methodology (values linked to Inputs sheet)
A2: Edit yellow cells on the Inputs sheet — all tabs update automatically.
A4: Parameter | B4: Live Value | C4: Notes
A5: Initial investment | B5: =InitialInvestment | C5: Total startup capital
A6: Essential Monthly | B6: =PriceEssMonthly | C6: 3-month minimum term
A7: Premium Monthly | B7: =PricePremMonthly | C7: 3-month minimum term
A8: Essential Annual | B8: =PriceEssAnnual | C8: 12-month commitment
A9: Premium Annual | B9: =PricePremAnnual | C9: 12-month commitment
A10: Annual plan mix | B10: =AnnualMix | C10: Industry B2C: 15–25%
A11: Essential tier mix | B11: =EssentialMix | C11: Within each billing type
A12: Monthly churn (post min term) | B12: =MonthlyChurn | C12: Home services B2C: 4–7%/mo
A13: Annual churn (at renewal) | B13: =AnnualChurn | C13: B2C annual: 15–25%
A14: CAC | B14: =CAC | C14: Paid acquisition; base £70 (industry £50–80 paid, £100–120 conservative)
A15: Provider share | B15: =ProviderShare | C15: Contractor payout
A16: Payment fees | B16: =PaymentFee | C16: Stripe processing
A17: Ops + AI per customer | B17: =OpsAI | C17: Per active subscriber/month
A18: Months 1–3 marketing | B18: =MktFixed1_3 | C18: Soft launch
A19: Months 4–6 marketing | B19: =MktFixed4_6 | C19: Ramp phase
A20: Cash buffer | B20: =CashBuffer | C20: Marketing cap reserve
A21: VAT rate | B21: =VATRate | C21: Once registered
A22: VAT threshold | B22: =VATThreshold | C22: Rolling 12-mo gross
A23: Inflation | B23: =InflationRate | C23: Annual price uplift
A24: Referral mix | B24: =ReferralMix | C24: Zero-CAC channel
A25: Referral reward | B25: =ReferralReward | C25: Per referral
A26: Launch month | B26: =LaunchMonth | C26: Seasonality anchor
A27: Seasonal churn table | B27: Inputs col D
A28: VAT payment | B28: Calendar quarters (Jan/Apr/Jul/Oct) | C28: Preceding calendar quarter
A29: Winter pivot seasonality | B29: Inputs cols E & F | C29: Sens - Winter Pivot tab — gutter/leaf/patio Oct–Feb

Sheet Inputs
A1: Sorted — SaaS Forecast Inputs (edit yellow cells)
A2: All forecast sheets recalculate automatically when you change inputs below.
A3: Parameter | B3: Value | C3: Notes
A4: INITIAL INVESTMENT
A5: Initial investment (£) | B5: 17000 | C5: Total startup capital available
A7: SUBSCRIPTION PRICING
A8: Essential Monthly (£/mo) | B8: 29.95 | C8: 3-month minimum term
A9: Premium Monthly (£/mo) | B9: 49.95 | C9: 3-month minimum term
A10: Essential Annual (£/yr) | B10: 299.95 | C10: 12-month commitment
A11: Premium Annual (£/yr) | B11: 499.95 | C11: 12-month commitment
A13: PLAN MIX
A14: Annual plan mix (%) | B14: 0.2 | C14: Industry B2C benchmark: 15–25%
A15: Essential tier mix (%) | B15: 0.7 | C15: Within each billing type
A17: CHURN (edit for sensitivity)
A18: Monthly plan churn — post min term (%/mo) | B18: 0.055 | C18: Home services B2C: 4–7%. Applied after month 3.
A19: Annual plan churn — at renewal (%/yr) | B19: 0.2 | C19: B2C annual renewal: 15–25%
A21: UNIT ECONOMICS
A22: Customer Acquisition Cost — CAC (£) | B22: 70 | C22: Paid acquisition per customer. Base £50–80 (B2C home services); ~⅓ yr-1 revenue ≈ £100–120 conservative
A23: Provider payout share (%) | B23: 0.6 | C23: Contractor share of revenue
A24: Payment processing fee (%) | B24: 0.03 | C24: Stripe/card fees
A25: Ops + AI cost per customer (£/mo) | B25: 5 | C25: Support, hosting, AI per active sub
A26: CASH TIMING
A27: Provider payment delay (months) | B27: 1 | C27: Providers invoiced ~30 days after service — cash float benefit
A28: Monthly fixed platform cost (£) | B28: 250 | C28: Hosting, AI base, tools — excludes per-customer ops
A29: VAT payment timing | B29: Calendar quarters | C29: Jan/Apr/Jul/Oct for preceding calendar quarter (UK)
A30: MARKETING SPEND
A31: Months 1–3 fixed spend (£/mo) | B31: 1500 | C31: Soft launch phase
A32: Months 4–6 fixed spend (£/mo) | B32: 2500 | C32: Ramp phase — capped by cash buffer from month 4
A33: Months 7–12 — % of prior month revenue | B33: 0.12 | C33: Scales with revenue
A34: Months 13–18 — % of prior month revenue | B34: 0.1
A35: Months 19+ — % of prior month revenue | B35: 0.08
A36: Min marketing months 7–12 (£/mo) | B36: 3000 | C36: Floor spend
A37: Min marketing months 13–18 (£/mo) | B37: 4000 | C37: Floor spend
A38: Min marketing months 19+ (£/mo) | B38: 5000 | C38: Floor spend
A39: Cash buffer retained (£) | B39: 2000 | C39: Min cash kept before marketing cap
A41: VAT
A42: VAT rate (%) | B42: 0.2 | C42: Standard rate once registered
A43: VAT registration threshold (£) | B43: 90000 | C43: Rolling 12-month gross turnover
A44: Prices are VAT-inclusive | B44: Yes | C44: B2C VAT-inclusive pricing; VAT paid quarterly to HMRC
A47: GROWTH & PRICING
...

Sheet 5 Year Summary
A1: 5-Year Summary
A3: Year | B3: Cust | C3: MRR | D3: ARR | E3: Paid | F3: Referrals | G3: Gross | H3: Net | I3: VAcc | J3: VPay | K3: VBal | L3: Prov | M3: Fees | N3: Ops | O3: Fixed | P3: Ref£ | Q3: Mkt | R3: Profit | S3: Cash | T3: Margin | U3: Prov# | V3: MRRGr | W3: Churn | X3: CumPft
A4: Year 1 | B4: =Model!U16 | C4: =Model!V16 | D4: =Model!W16 | E4: =SUM(Model!H5:H16) | F4: =SUM(Model!I5:I16) | G4: =SUM(Model!AA5:AA16) | H4: =SUM(Model!AD5:AD16) | I4: =SUM(Model!AE5:AE16) | J4: =SUM(Model!AF5:AF16) | K4: =Model!AG16 | L4: =SUM(Model!AH5:AH16) | M4: =SUM(Model!AI5:AI16) | N4: =SUM(Model!AJ5:AJ16) | O4: =SUM(Model!AK5:AK16) | P4: =SUM(Model!AL5:AL16) | Q4: =SUM(Model!AM5:AM16) | R4: =SUM(Model!AN5:AN16) | S4: =Model!AO16 | T4: =IF(G4>0,(H4-L4-M4-N4-O4)/G4,0) | U4: =ROUNDUP(B4/140,0) | V4: — | W4: =AVERAGE(Model!AQ6:AQ16) | X4: =SUM($R$4:R4)
A5: Year 2 | B5: =Model!U28 | C5: =Model!V28 | D5: =Model!W28 | E5: =SUM(Model!H17:H28) | F5: =SUM(Model!I17:I28) | G5: =SUM(Model!AA17:AA28) | H5: =SUM(Model!AD17:AD28) | I5: =SUM(Model!AE17:AE28) | J5: =SUM(Model!AF17:AF28) | K5: =Model!AG28 | L5: =SUM(Model!AH17:AH28) | M5: =SUM(Model!AI17:AI28) | N5: =SUM(Model!AJ17:AJ28) | O5: =SUM(Model!AK17:AK28) | P5: =SUM(Model!AL17:AL28) | Q5: =SUM(Model!AM17:AM28) | R5: =SUM(Model!AN17:AN28) | S5: =Model!AO28 | T5: =IF(G5>0,(H5-L5-M5-N5-O5)/G5,0) | U5: =ROUNDUP(B5/140,0) | V5: =(C5-C4)/C4 | W5: =AVERAGE(Model!AQ18:AQ28) | X5: =SUM($R$4:R5)
A6: Year 3 | B6: =Model!U40 | C6: =Model!V40 | D6: =Model!W40 | E6: =SUM(Model!H29:H40) | F6: =SUM(Model!I29:I40) | G6: =SUM(Model!AA29:AA40) | H6: =SUM(Model!AD29:AD40) | I6: =SUM(Model!AE29:AE40) | J6: =SUM(Model!AF29:AF40) | K6: =Model!AG40 | L6: =SUM(Model!AH29:AH40) | M6: =SUM(Model!AI29:AI40) | N6: =SUM(Model!AJ29:AJ40) | O6: =SUM(Model!AK29:AK40) | P6: =SUM(Model!AL29:AL40) | Q6: =SUM(Model!AM29:AM40) | R6: =SUM(Model!AN29:AN40) | S6: =Model!AO40 | T6: =IF(G6>0,(H6-L6-M6-N6-O6)/G6,0) | U6: =ROUNDUP(B6/140,0) | V6: =(C6-C5)/C5 | W6: =AVERAGE(Model!AQ30:AQ40) | X6: =SUM($R$4:R6)
A7: Year 4 | B7: =Model!U52 | C7: =Model!V52 | D7: =Model!W52 | E7: =SUM(Model!H41:H52) | F7: =SUM(Model!I41:I52) | G7: =SUM(Model!AA41:AA52) | H7: =SUM(Model!AD41:AD52) | I7: =SUM(Model!AE41:AE52) | J7: =SUM(Model!AF41:AF52) | K7: =Model!AG52 | L7: =SUM(Model!AH41:AH52) | M7: =SUM(Model!AI41:AI52) | N7: =SUM(Model!AJ41:AJ52) | O7: =SUM(Model!AK41:AK52) | P7: =SUM(Model!AL41:AL52) | Q7: =SUM(Model!AM41:AM52) | R7: =SUM(Model!AN41:AN52) | S7: =Model!AO52 | T7: =IF(G7>0,(H7-L7-M7-N7-O7)/G7,0) | U7: =ROUNDUP(B7/140,0) | V7: =(C7-C6)/C6 | W7: =AVERAGE(Model!AQ42:AQ52) | X7: =SUM($R$4:R7)
A8: Year 5 | B8: =Model!U64 | C8: =Model!V64 | D8: =Model!W64 | E8: =SUM(Model!H53:H64) | F8: =SUM(Model!I53:I64) | G8: =SUM(Model!AA53:AA64) | H8: =SUM(Model!AD53:AD64) | I8: =SUM(Model!AE53:AE64) | J8: =SUM(Model!AF53:AF64) | K8: =Model!AG64 | L8: =SUM(Model!AH53:AH64) | M8: =SUM(Model!AI53:AI64) | N8: =SUM(Model!AJ53:AJ64) | O8: =SUM(Model!AK53:AK64) | P8: =SUM(Model!AL53:AL64) | Q8: =SUM(Model!AM53:AM64) | R8: =SUM(Model!AN53:AN64) | S8: =Model!AO64 | T8: =IF(G8>0,(H8-L8-M8-N8-O8)/G8,0) | U8: =ROUNDUP(B8/140,0) | V8: =(C8-C7)/C7 | W8: =AVERAGE(Model!AQ54:AQ64) | X8: =SUM($R$4:R8)
A10: VAT registration | B10: =IFERROR("Month "&MATCH(TRUE,Model!AC5:Model!AC64,0),"Not in 60 mo")
A11: VAT payments | B11: Calendar: Jan=Q4 prior yr, Apr=Q1, Jul=Q2, Oct=Q3

Sheet 24 Month Forecast
A1: 24-Month Forecast
A3: Month | B3: CalMo | C3: Paid | D3: Referral | E3: Total | F3: Cust | G3: EffChurn | H3: MRR | I3: ARR | J3: Gross | K3: Net | L3: VAcc | M3: VPay | N3: VBal | O3: Prov | P3: Fees | Q3: Ops | R3: Fixed | S3: Ref£ | T3: Mkt | U3: Pft | V3: Cash | W3: Churn
A4: Month 1 | B4: =Model!B5 | C4: =Model!H5 | D4: =Model!I5 | E4: =Model!J5 | F4: =Model!U5 | G4: =Model!F5 | H4: =Model!V5 | I4: =Model!W5 | J4: =Model!AA5 | K4: =Model!AD5 | L4: =Model!AE5 | M4: =Model!AF5 | N4: =Model!AG5 | O4: =Model!AH5 | P4: =Model!AI5 | Q4: =Model!AJ5 | R4: =Model!AK5 | ... V4: =Model!AO5 | W4: =Model!AQ5
A5: Month 2 | B5: =Model!B6 | C5: =Model!H6 | D5: =Model!I6 | E5: =Model!J6 | F5: =Model!U6 | G5: =Model!F6 | H5: =Model!V6 | I5: =Model!W6 | J5: =Model!AA6 | K5: =Model!AD6 | L5: =Model!AE6 | M5: =Model!AF6 | N5: =Model!AG6 | O5: =Model!AH6 | P5: =Model!AI6 | Q5: =Model!AJ6 | R5: =Model!AK6 | ... V5: =Model!AO6 | W5: =Model!AQ6
A6: Month 3 | B6: =Model!B7 | C6: =Model!H7 | D6: =Model!I7 | E6: =Model!J7 | F6: =Model!U7 | G6: =Model!F7 | H6: =Model!V7 | I6: =Model!W7 | J6: =Model!AA7 | K6: =Model!AD7 | L6: =Model!AE7 | M6: =Model!AF7 | N6: =Model!AG7 | O6: =Model!AH7 | P6: =Model!AI7 | Q6: =Model!AJ7 | R6: =Model!AK7 | ... V6: =Model!AO7 | W6: =Model!AQ7
A7: Month 4 | B7: =Model!B8 | C7: =Model!H8 | D7: =Model!I8 | E7: =Model!J8 | F7: =Model!U8 | G7: =Model!F8 | H7: =Model!V8 | I7: =Model!W8 | J7: =Model!AA8 | K7: =Model!AD8 | L7: =Model!AE8 | M7: =Model!AF8 | N7: =Model!AG8 | O7: =Model!AH8 | P7: =Model!AI8 | Q7: =Model!AJ8 | R7: =Model!AK8 | ... V7: =Model!AO8 | W7: =Model!AQ8
A8: Month 5 | B8: =Model!B9 | C8: =Model!H9 | D8: =Model!I9 | E8: =Model!J9 | F8: =Model!U9 | G8: =Model!F9 | H8: =Model!V9 | I8: =Model!W9 | J8: =Model!AA9 | K8: =Model!AD9 | L8: =Model!AE9 | M8: =Model!AF9 | N8: =Model!AG9 | O8: =Model!AH9 | P8: =Model!AI9 | Q8: =Model!AJ9 | R8: =Model!AK9 | ... V8: =Model!AO9 | W8: =Model!AQ9
A9: Month 6 | B9: =Model!B10 | C9: =Model!H10 | D9: =Model!I10 | E9: =Model!J10 | F9: =Model!U10 | G9: =Model!F10 | H9: =Model!V10 | I9: =Model!W10 | J9: =Model!AA10 | K9: =Model!AD10 | L9: =Model!AE10 | M9: =Model!AF10 | N9: =Model!AG10 | O9: =Model!AH10 | P9: =Model!AI10 | Q9: =Model!AJ10 | R9: =Model!AK10 | ... V9: =Model!AO10 | W9: =Model!AQ10
A10: Month 7 | B10: =Model!B11 | C10: =Model!H11 | D10: =Model!I11 | E10: =Model!J11 | F10: =Model!U11 | G10: =Model!F11 | H10: =Model!V11 | I10: =Model!W11 | J10: =Model!AA11 | K10: =Model!AD11 | L10: =Model!AE11 | M10: =Model!AF11 | N10: =Model!AG11 | O10: =Model!AH11 | P10: =Model!AI11 | Q10: =Model!AJ11 | R10: =Model!AK11 | ... V10: =Model!AO11 | W10: =Model!AQ11
A11: Month 8 | B11: =Model!B12 | C11: =Model!H12 | D11: =Model!I12 | E11: =Model!J12 | F11: =Model!U12 | G11: =Model!F12 | H11: =Model!V12 | I11: =Model!W12 | J11: =Model!AA12 | K11: =Model!AD12 | L11: =Model!AE12 | M11: =Model!AF12 | N11: =Model!AG12 | O11: =Model!AH12 | P11: =Model!AI12 | Q11: =Model!AJ12 | R11: =Model!AK12 | ... V11: =Model!AO12 | W11: =Model!AQ12
A12: Month 9 | B12: =Model!B13 | C12: =Model!H13 | D12: =Model!I13 | E12: =Model!J13 | F12: =Model!U13 | G12: =Model!F13 | H12: =Model!V13 | I12: =Model!W13 | J12: =Model!AA13 | K12: =Model!AD13 | L12: =Model!AE13 | M12: =Model!AF13 | N12: =Model!AG13 | O12: =Model!AH13 | P12: =Model!AI13 | Q12: =Model!AJ13 | R12: =Model!AK13 | ... V12: =Model!AO13 | W12: =Model!AQ13
A13: Month 10 | B13: =Model!B14 | C13: =Model!H14 | D13: =Model!I14 | E13: =Model!J14 | F13: =Model!U14 | G13: =Model!F14 | H13: =Model!V14 | I13: =Model!W14 | J13: =Model!AA14 | K13: =Model!AD14 | L13: =Model!AE14 | M13: =Model!AF14 | N13: =Model!AG14 | O13: =Model!AH14 | P13: =Model!AI14 | Q13: =Model!AJ14 | R13: =Model!AK14 | ... V13: =Model!AO14 | W13: =Model!AQ14
A14: Month 11 | B14: =Model!B15 | C14: =Model!H15 | D14: =Model!I15 | E14: =Model!J15 | F14: =Model!U15 | G14: =Model!F15 | H14: =Model!V15 | I14: =Model!W15 | J14: =Model!AA15 | K14: =Model!AD15 | L14: =Model!AE15 | M14: =Model!AF15 | N14: =Model!AG15 | O14: =Model!AH15 | P14: =Model!AI15 | Q14: =Model!AJ15 | R14: =Model!AK15 | ... V14: =Model!AO15 | W14: =Model!AQ15
A15: Month 12 | B15: =Model!B16 | C15: =Model!H16 | D15: =Model!I16 | E15: =Model!J16 | F15: =Model!U16 | G15: =Model!F16 | H15: =Model!V16 | I15: =Model!W16 | J15: =Model!AA16 | K15: =Model!AD16 | L15: =Model!AE16 | M15: =Model!AF16 | N15: =Model!AG16 | O15: =Model!AH16 | P15: =Model!AI16 | Q15: =Model!AJ16 | R15: =Model!AK16 | ... V15: =Model!AO16 | W15: =Model!AQ16
... A27: Month 24 | B27: =Model!B28 | C27: =Model!H28 | D27: =Model!I28 | E27: =Model!J28 | F27: =Model!U28 | G27: =Model!F28 | H27: =Model!V28 | I27: =Model!W28 | J27: =Model!AA28 | K27: =Model!AD28 | L27: =Model!AE28 | M27: =Model!AF28 | N27: =Model!AG28 | O27: =Model!AH28 | P27: =Model!AI28 | Q27: =Model!AJ28 | R27: =Model!AK28 | ... V27: =Model!AO28 | W27: =Model!AQ28

Sheet Unit Economics
A1: Unit Economics (calculated from Inputs)
A3: Metric | B3: Value | C3: Unit
A4: Blended ARPU (MRR per customer) | B4: =EssentialMix*(1-AnnualMix)*PriceEssMonthly+(1-EssentialMix)*(1-AnnualMix)*PricePremMonthly+EssentialMix*AnnualMix*PriceEssAnnual/12+(1-EssentialMix)*AnnualMix*PricePremAnnual/12 | C4: £/mo
A5: Monthly plan ARPU | B5: =EssentialMix*PriceEssMonthly+(1-EssentialMix)*PricePremMonthly | C5: £/mo
A6: Annual plan ARPU (normalised) | B6: =EssentialMix*PriceEssAnnual/12+(1-EssentialMix)*PricePremAnnual/12 | C6: £/mo
A8: Provider cost per customer | B8: =B4*ProviderShare | C8: £/mo
A9: Payment fees per customer | B9: =B4*PaymentFee | C9: £/mo
A10: Ops + AI per customer | B10: =OpsAI | C10: £/mo
A12: Gross margin per customer (pre-marketing) | B12: =B4*(1-ProviderShare-PaymentFee)-OpsAI | C12: £/mo
A13: CAC | B13: =CAC | C13: £
A14: Months to recover CAC | B14: =B13/B12 | C14: months
A16: Customer lifetime — monthly plan (post min term) | B16: =1/MonthlyChurn | C16: months
A17: Expected annual renewals — annual plan | B17: =1/AnnualChurn | C17: renewals
A18: LTV — monthly plan (simplified) | B18: =B5*(1-ProviderShare-PaymentFee)*(1/MonthlyChurn) | C18: £
A19: LTV — annual plan (simplified) | B19: =B6*12*(1-ProviderShare-PaymentFee)*(1/AnnualChurn) | C19: £
A20: LTV:CAC — monthly plan | B20: =B18/CAC | C20: x
A21: LTV:CAC — blended | B21: =B4*(1-ProviderShare-PaymentFee)*((1-AnnualMix)/MonthlyChurn+AnnualMix*12/AnnualChurn)/CAC | C21: x
A22: Inflated ARPU (Year 2 prices) | B22: =B4*(1+InflationRate) | C22: £/mo
A23: Effective CAC (paid customers only) | B23: =CAC | C23: £
A24: Blended CAC (incl. referrals) | B24: =CAC*(1-ReferralMix) | C24: £/customer
A25: Monthly fixed platform cost | B25: =MonthlyFixed | C25: £/mo

Sheet Sens - Scenarios
A1: Scenario Comparison — Conservative / Base / Aggressive (full model engine)
A2: Edit yellow cells in Conservative & Aggressive columns. Base uses live Inputs (£70 CAC). Marketing spend: Inputs rows 31–39.
A4: Parameter | B4: Conservative | C4: Base (live Inputs) | D4: Aggressive
A5: Monthly churn (post min term) | B5: 0.07 | C5: =MonthlyChurn | D5: 0.04
A6: Annual churn (at renewal) | B6: 0.25 | C6: =AnnualChurn | D6: 0.15
A7: Annual plan mix | B7: 0.15 | C7: =AnnualMix | D7: 0.3
A8: CAC (£) | B8: 110 | C8: =CAC | D8: 40
A11: OUTPUT METRICS
A12: Metric | B12: Conservative | C12: Base | D12: Aggressive
A13: End Year 1 — Customers | B13: ='Scenario Engine'!U$16 | C13: ='Scenario Engine'!BM$16 | D13: ='Scenario Engine'!DE$16
A14: End Year 1 — MRR (£) | B14: ='Scenario Engine'!V$16 | C14: ='Scenario Engine'!BN$16 | D14: ='Scenario Engine'!DF$16
A15: End Year 1 — ARR (£) | B15: ='Scenario Engine'!W$16 | C15: ='Scenario Engine'!BO$16 | D15: ='Scenario Engine'!DG$16
A16: End Year 1 — Cash Balance (£) | B16: ='Scenario Engine'!AO$16 | C16: ='Scenario Engine'!CG$16 | D16: ='Scenario Engine'!DY$16
A17: Year 1 — Gross Revenue (£) | B17: =SUM('Scenario Engine'!AA$5:'Scenario Engine'!AA$16) | C17: =SUM('Scenario Engine'!BS$5:'Scenario Engine'!BS$16) | D17: =SUM('Scenario Engine'!DK$5:'Scenario Engine'!DK$16)
A18: Year 1 — Net Revenue (£) | B18: =SUM('Scenario Engine'!AD$5:'Scenario Engine'!AD$16) | C18: =SUM('Scenario Engine'!BV$5:'Scenario Engine'!BV$16) | D18: =SUM('Scenario Engine'!DN$5:'Scenario Engine'!DN$16)
A19: Year 1 — Profit (£) | B19: =SUM('Scenario Engine'!AN$5:'Scenario Engine'!AN$16) | C19: =SUM('Scenario Engine'!CF$5:'Scenario Engine'!CF$16) | D19: =SUM('Scenario Engine'!DX$5:'Scenario Engine'!DX$16)
A20: End Year 2 — Customers | B20: ='Scenario Engine'!U$28 | C20: ='Scenario Engine'!BM$28 | D20: ='Scenario Engine'!DE$28
A21: End Year 2 — MRR (£) | B21: ='Scenario Engine'!V$28 | C21: ='Scenario Engine'!BN$28 | D21: ='Scenario Engine'!DF$28
A22: End Year 2 — ARR (£) | B22: ='Scenario Engine'!W$28 | C22: ='Scenario Engine'!BO$28 | D22: ='Scenario Engine'!DG$28
A23: End Year 2 — Cash Balance (£) | B23: ='Scenario Engine'!AO$28 | C23: ='Scenario Engine'!CG$28 | D23: ='Scenario Engine'!DY$28
A24: Year 2 — Gross Revenue (£) | B24: =SUM('Scenario Engine'!AA$17:'Scenario Engine'!AA$28) | C24: =SUM('Scenario Engine'!BS$17:'Scenario Engine'!BS$28) | D24: =SUM('Scenario Engine'!DK$17:'Scenario Engine'!DK$28)
A25: End Year 5 — Customers | B25: ='Scenario Engine'!U$64 | C25: ='Scenario Engine'!BM$64 | D25: ='Scenario Engine'!DE$64
A26: End Year 5 — MRR (£) | B26: ='Scenario Engine'!V$64 | C26: ='Scenario Engine'!BN$64 | D26: ='Scenario Engine'!DF$64
A27: End Year 5 — ARR (£) | B27: ='Scenario Engine'!W$64 | C27: ='Scenario Engine'!BO$64 | D27: ='Scenario Engine'!DG$64
A28: End Year 5 — Cash Balance (£) | B28: ='Scenario Engine'!AO$64 | C28: ='Scenario Engine'!CG$64 | D28: ='Scenario Engine'!DY$64

Sheet Sens - Churn
A1: Churn Sensitivity — full model (seasonal churn, VAT, referrals)
A2: Edit churn in column A (yellow). Live model outputs in section below for comparison.
A4: Current Monthly Churn (Inputs) | B4: =MonthlyChurn
A5: Live Y1 MRR | B5: =Model!V16
A6: Live Y2 MRR | B6: =Model!V28
A7: Live Y2 ARR | B7: =Model!W28
A8: Live Y5 ARR | B8: =Model!W64
A9: Live Y5 Cash | B9: =Model!AO64
A12: Monthly Churn | B12: Y1 MRR | C12: Y1 Cust | D12: Y2 MRR | E12: Y2 ARR | F12: Y2 Cash | G12: Y5 ARR
A13: 0.03 | B13: ='Scenario Engine'!EX$16 | C13: ='Scenario Engine'!EW$16 | D13: ='Scenario Engine'!EX$28 | E13: ='Scenario Engine'!EY$28 | F13: ='Scenario Engine'!FQ$28 | G13: ='Scenario Engine'!EY$64
A14: 0.035 | B14: ='Scenario Engine'!GP$16 | C14: ='Scenario Engine'!GO$16 | D14: ='Scenario Engine'!GP$28 | E14: ='Scenario Engine'!GQ$28 | F14: ='Scenario Engine'!HI$28 | G14: ='Scenario Engine'!GQ$64
A15: 0.04 | B15: ='Scenario Engine'!IH$16 | C15: ='Scenario Engine'!IG$16 | D15: ='Scenario Engine'!IH$28 | E15: ='Scenario Engine'!II$28 | F15: ='Scenario Engine'!JA$28 | G15: ='Scenario Engine'!II$64
A16: 0.045 | B16: ='Scenario Engine'!JZ$16 | C16: ='Scenario Engine'!JY$16 | D16: ='Scenario Engine'!JZ$28 | E16: ='Scenario Engine'!KA$28 | F16: ='Scenario Engine'!KS$28 | G16: ='Scenario Engine'!KA$64
A17: 0.05 | B17: ='Scenario Engine'!LR$16 | C17: ='Scenario Engine'!LQ$16 | D17: ='Scenario Engine'!LR$28 | E17: ='Scenario Engine'!LS$28 | F17: ='Scenario Engine'!MK$28 | G17: ='Scenario Engine'!LS$64
A18: 0.055 | B18: ='Scenario Engine'!NJ$16 | C18: ='Scenario Engine'!NI$16 | D18: ='Scenario Engine'!NJ$28 | E18: ='Scenario Engine'!NK$28 | F18: ='Scenario Engine'!OC$28 | G18: ='Scenario Engine'!NK$64
A19: 0.06 | B19: ='Scenario Engine'!PB$16 | C19: ='Scenario Engine'!PA$16 | D19: ='Scenario Engine'!PB$28 | E19: ='Scenario Engine'!PC$28 | F19: ='Scenario Engine'!PU$28 | G19: ='Scenario Engine'!PC$64
A20: 0.065 | B20: ='Scenario Engine'!QT$16 | C20: ='Scenario Engine'!QS$16 | D20: ='Scenario Engine'!QT$28 | E20: ='Scenario Engine'!QU$28 | F20: ='Scenario Engine'!RM$28 | G20: ='Scenario Engine'!QU$64
A21: 0.07 | B21: ='Scenario Engine'!SL$16 | C21: ='Scenario Engine'!SK$16 | D21: ='Scenario Engine'!SL$28 | E21: ='Scenario Engine'!SM$28 | F21: ='Scenario Engine'!TE$28 | G21: ='Scenario Engine'!SM$64
A22: 0.07 | B22: ='Scenario Engine'!KZ$16 | C22: ='Scenario Engine'!KY$16 | D22: ='Scenario Engine'!KZ$28 | E22: ='Scenario Engine'!LA$28 | F22: ='Scenario Engine'!LK$28 | G22: ='Scenario Engine'!LA$64

Sheet Sens - Annual Mix
A1: Annual Plan Mix Sensitivity — full model engine
A2: Edit mix % in column A (yellow).
A4: Current (Inputs) | B4: =AnnualMix
A7: Annual Mix | B7: Y1 MRR | C7: Blended ARPU | D7: Y2 MRR | E7: Y2 ARR | F7: Y5 ARR | G7: Y5 Cash
A9: 0.1 | B9: ='Scenario Engine'!UD$16 | C9: =IF('Scenario Engine'!UC$16>0,'Scenario Engine'!UD$16/'Scenario Engine'!UC$16,0) | D9: ='Scenario Engine'!UD$28 | E9: ='Scenario Engine'!UE$28 | F9: ='Scenario Engine'!UE$64 | G9: ='Scenario Engine'!UW$64
A10: 0.15 | B10: ='Scenario Engine'!VV$16 | C10: =IF('Scenario Engine'!VU$16>0,'Scenario Engine'!VV$16/'Scenario Engine'!VU$16,0) | D10: ='Scenario Engine'!VV$28 | E10: ='Scenario Engine'!VW$28 | F10: ='Scenario Engine'!VW$64 | G10: ='Scenario Engine'!WO$64
A11: 0.2 | B11: ='Scenario Engine'!XN$16 | C11: =IF('Scenario Engine'!XM$16>0,'Scenario Engine'!XN$16/'Scenario Engine'!XM$16,0) | D11: ='Scenario Engine'!XN$28 | E11: ='Scenario Engine'!XO$28 | F11: ='Scenario Engine'!XO$64 | G11: ='Scenario Engine'!YG$64
A12: 0.25 | B12: ='Scenario Engine'!ZF$16 | C12: =IF('Scenario Engine'!ZE$16>0,'Scenario Engine'!ZF$16/'Scenario Engine'!ZE$16,0) | D12: ='Scenario Engine'!ZF$28 | E12: ='Scenario Engine'!ZG$28 | F12: ='Scenario Engine'!ZG$64 | G12: ='Scenario Engine'!ZY$64
A13: 0.3 | B13: ='Scenario Engine'!AAX$16 | C13: =IF('Scenario Engine'!AAW$16>0,'Scenario Engine'!AAX$16/'Scenario Engine'!AAW$16,0) | D13: ='Scenario Engine'!AAX$28 | E13: ='Scenario Engine'!AAY$28 | F13: ='Scenario Engine'!AAY$64 | G13: ='Scenario Engine'!ABQ$64
A14: 0.35 | B14: ='Scenario Engine'!ACP$16 | C14: =IF('Scenario Engine'!ACO$16>0,'Scenario Engine'!ACP$16/'Scenario Engine'!ACO$16,0) | D14: ='Scenario Engine'!ACP$28 | E14: ='Scenario Engine'!ACQ$28 | F14: ='Scenario Engine'!ACQ$64 | G14: ='Scenario Engine'!ADI$64
A15: 0.4 | B15: ='Scenario Engine'!AEH$16 | C15: =IF('Scenario Engine'!AEG$16>0,'Scenario Engine'!AEH$16/'Scenario Engine'!AEG$16,0) | D15: ='Scenario Engine'!AEH$28 | E15: ='Scenario Engine'!AEI$28 | F15: ='Scenario Engine'!AEI$64 | G15: ='Scenario Engine'!AFA$64

Sheet Sens - CAC & Marketing
A1: CAC Sensitivity — full model engine (home services benchmarks)
A2: Edit CAC in column A (yellow). Sweep spans optimistic (£40) to conservative (£120).
A4: Current (Inputs) | B4: =CAC
A7: CAC (£) | B7: Y1 New Cust | C7: Y1 End Cust | D7: Y1 MRR | E7: Y2 MRR | F7: Y2 Cash | G7: Y5 Cash
A9: 40 | B9: =SUM('Scenario Engine'!AFL$5:'Scenario Engine'!AFL$16) | C9: ='Scenario Engine'!AFY$16 | D9: ='Scenario Engine'!AFZ$16 | E9: ='Scenario Engine'!AFZ$28 | F9: ='Scenario Engine'!AGS$28 | G9: ='Scenario Engine'!AGS$64
A10: 50 | B10: =SUM('Scenario Engine'!AHD$5:'Scenario Engine'!AHD$16) | C10: ='Scenario Engine'!AHQ$16 | D10: ='Scenario Engine'!AHR$16 | E10: ='Scenario Engine'!AHR$28 | F10: ='Scenario Engine'!AIK$28 | G10: ='Scenario Engine'!AIK$64
A11: 60 | B11: =SUM('Scenario Engine'!AIV$5:'Scenario Engine'!AIV$16) | C11: ='Scenario Engine'!AJI$16 | D11: ='Scenario Engine'!AJJ$16 | E11: ='Scenario Engine'!AJJ$28 | F11: ='Scenario Engine'!AKC$28 | G11: ='Scenario Engine'!AKC$64
A12: 70 | B12: =SUM('Scenario Engine'!AKN$5:'Scenario Engine'!AKN$16) | C12: ='Scenario Engine'!ALA$16 | D12: ='Scenario Engine'!ALB$16 | E12: ='Scenario Engine'!ALB$28 | F12: ='Scenario Engine'!ALU$28 | G12: ='Scenario Engine'!ALU$64
A13: 80 | B13: =SUM('Scenario Engine'!AMF$5:'Scenario Engine'!AMF$16) | C13: ='Scenario Engine'!AMS$16 | D13: ='Scenario Engine'!AMT$16 | E13: ='Scenario Engine'!AMT$28 | F13: ='Scenario Engine'!ANM$28 | G13: ='Scenario Engine'!ANM$64
A14: 100 | B14: =SUM('Scenario Engine'!ANX$5:'Scenario Engine'!ANX$16) | C14: ='Scenario Engine'!AOK$16 | D14: ='Scenario Engine'!AOL$16 | E14: ='Scenario Engine'!AOL$28 | F14: ='Scenario Engine'!APE$28 | G14: ='Scenario Engine'!APE$64
A15: 120 | B15: =SUM('Scenario Engine'!APP$5:'Scenario Engine'!APP$16) | C15: ='Scenario Engine'!AQC$16 | D15: ='Scenario Engine'!AQD$16 | E15: ='Scenario Engine'!AQD$28 | F15: ='Scenario Engine'!AQW$28 | G15: ='Scenario Engine'!AQW$64

Sheet Sens - Winter Pivot
A1: Winter Pivot — Property Care Scenario (gutter, leaf, patio)
A2: Compares base garden seasonality vs year-round property care. Edit yellow cells. Pivot seasonality: Inputs cols E & F.
A4: SCENARIO ASSUMPTIONS
A5: Positioning | B5: Year-round property care subscription (mowing pauses Dec–Feb; gutter, leaf & patio included on Premium)
A6: Essential tier mix | B6: 0.65
A7: Premium price uplift (£/mo) | B7: 10
A8: Same as base | B8: CAC, churn rates, marketing & pricing otherwise from Inputs
A11: SEASONALITY COMPARISON (calendar month)
A12: Month | B12: Base acq | C12: Pivot acq | D12: Δ acq | E12: Base churn× | F12: Pivot churn× | G12: Δ churn
A13: Jan | B13: =Inputs!B55 | C13: =Inputs!E55 | D13: =C13-B13 | E13: =Inputs!D55 | F13: =Inputs!F55 | G13: =F13-E13
A14: Feb | B14: =Inputs!B56 | C14: =Inputs!E56 | D14: =C14-B14 | E14: =Inputs!D56 | F14: =Inputs!F56 | G14: =F14-E14
A15: Mar | B15: =Inputs!B57 | C15: =Inputs!E57 | D15: =C15-B15 | E15: =Inputs!D57 | F15: =Inputs!F57 | G15: =F15-E15
A16: Apr | B16: =Inputs!B58 | C16: =Inputs!E58 | D16: =C16-B16 | E16: =Inputs!D58 | F16: =Inputs!F58 | G16: =F16-E16
A17: May | B17: =Inputs!B59 | C17: =Inputs!E59 | D17: =C17-B17 | E17: =Inputs!D59 | F17: =Inputs!F59 | G17: =F17-E17
A18: Jun | B18: =Inputs!B60 | C18: =Inputs!E60 | D18: =C18-B18 | E18: =Inputs!D60 | F18: =Inputs!F60 | G18: =F18-E18
A19: Jul | B19: =Inputs!B61 | C19: =Inputs!E61 | D19: =C19-B19 | E19: =Inputs!D61 | F19: =Inputs!F61 | G19: =F19-E19
A20: Aug | B20: =Inputs!B62 | C20: =Inputs!E62 | D20: =C20-B20 | E20: =Inputs!D62 | F20: =Inputs!F62 | G20: =F20-E20
A21: Sep | B21: =Inputs!B63 | C21: =Inputs!E63 | D21: =C21-B21 | E21: =Inputs!D63 | F21: =Inputs!F63 | G21: =F21-E21
A22: Oct | B22: =Inputs!B64 | C22: =Inputs!E64 | D22: =C22-B22 | E22: =Inputs!D64 | F22: =Inputs!F64 | G22: =F22-E22
A23: Nov | B23: =Inputs!B65 | C23: =Inputs!E65 | D23: =C23-B23 | E23: =Inputs!D65 | F23: =Inputs!F65 | G23: =F23-E23
A24: Dec | B24: =Inputs!B66 | C24: =Inputs!E66 | D24: =C24-B24 | E24: =Inputs!D66 | F24: =Inputs!F66 | G24: =F24-E24
A27: OUTPUT COMPARISON — Base vs Winter Pivot (full model engine)
A28: Base = standard seasonality (Inputs cols B & D). Winter Pivot = cols E & F + Premium property care bundle.
A30: Metric | B30: Base | C30: Winter Pivot | D30: Delta
A31: End Year 1 — Customers | B31: ='Scenario Engine'!BM$16 | C31: ='Scenario Engine'!ARU$16 | D31: =C31-B31
A32: End Year 1 — MRR (£) | B32: ='Scenario Engine'!BN$16 | C32: ='Scenario Engine'!ARV$16 | D32: =C32-B32
A33: End Year 1 — ARR (£) | B33: ='Scenario Engine'!BO$16 | C33: ='Scenario Engine'!ARW$16 | D33: =C33-B33
A34: End Year 1 — Cash (£) | B34: ='Scenario Engine'!CG$16 | C34: ='Scenario Engine'!ASO$16 | D34: =C34-B34
A35: Year 1 — Gross Revenue (£) | B35: =SUM('Scenario Engine'!BS$5:'Scenario Engine'!BS$16) | C35: =SUM('Scenario Engine'!ASA$5:'Scenario Engine'!ASA$16) | D35: =C35-B35
A36: Year 1 — Profit (£) | B36: =SUM('Scenario Engine'!CF$5:'Scenario Engine'!CF$16) | C36: =SUM('Scenario Engine'!ASN$5:'Scenario Engine'!ASN$16) | D36: =C36-B36
A37: End Year 2 — Customers | B37: ='Scenario Engine'!BM$28 | C37: ='Scenario Engine'!ARU$28 | D37: =C37-B37
A38: End Year 2 — MRR (£) | B38: ='Scenario Engine'!BN$28 | C38: ='Scenario Engine'!ARV$28 | D38: =C38-B38
A39: End Year 2 — Cash (£) | B39: ='Scenario Engine'!CG$28 | C39: ='Scenario Engine'!ASO$28 | D39: =C39-B39
A40: End Year 5 — Customers | B40: ='Scenario Engine'!BM$64 | C40: ='Scenario Engine'!ARU$64 | D40: =C40-B40
A41: End Year 5 — MRR (£) | B41: ='Scenario Engine'!BN$64 | C41: ='Scenario Engine'!ARV$64 | D41: =C41-B41
A42: End Year 5 — Cash (£) | B42: ='Scenario Engine'!CG$64 | C42: ='Scenario Engine'!ASO$64 | D42: =C42-B42

Sheet Model
A1: 60-Month Model — hover row 4 headers for column descriptions
A2: Hover any column header in row 4 for a full description.
A4: Mo | B4: Cal | C4: CY | D4: Acq | E4: Infl | F4: ECh | G4: Mkt | H4: Paid | I4: Ref | J4: Tot | K4: NMo | L4: NAn | M4: NEsM | N4: NPrM | O4: NEsA | P4: NPrA | Q4: AEsM | R4: APrM | S4: AEsA | T4: APrA | U4: Cust | V4: MRR | W4: ARR | X4: Mo$ | Y4: NwAn | Z4: Ren | AA4: Gross | AB4: R12 | AC4: VAT | AD4: Net | AE4: VAcc | AF4: VPay | AG4: VBal | AH4: Prov | AI4: Fee | AJ4: Ops | AK4: Fix | AL4: Ref$ | AM4: Mkt | AN4: Pft | AO4: Cash | AP4: ARPU | AQ4: Chrn
A5: 1 | B5: =MOD(A5-1+LaunchMonth-1,12)+1 | C5: =INT((A5-1+LaunchMonth-1)/12)+1 | D5: =VLOOKUP(B5,SeasonTable,2,FALSE) | E5: =(1+InflationRate)^INT((A5-1)/12) | F5: =MonthlyChurn*VLOOKUP(B5,ChurnSeasonTable,4,FALSE) | G5: =MktFixed1_3 | H5: =IF(G5>0,MAX(1,ROUND(G5/CAC*D5,0)),0) | I5: =IF(H5>0,ROUND(H5*ReferralMix/(1-ReferralMix),0),0) | J5: =H5+I5 | K5: =ROUND(J5*(1-AnnualMix),0) | L5: =J5-K5 | M5: =ROUND(K5*EssentialMix,0) | N5: =K5-M5 | O5: =ROUND(L5*EssentialMix,0) | P5: =L5-O5 | Q5: =M5 | R5: =N5 | S5: =O5 | T5: =P5 | U5: =Q5+R5+S5+T5 | V5: =Q5*PriceEssMonthly*E5+R5*PricePremMonthly*E5+S5*PriceEssAnnual*E5/12+T5*PricePremAnnual*E5/12 | W5: =V5*12 | X5: =Q5*PriceEssMonthly*E5+R5*PricePremMonthly*E5 | Y5: =O5*PriceEssAnnual*E5+P5*PricePremAnnual*E5 | Z5: =0+0 | AA5: =X5+Y5+Z5 | AB5: =SUM(AA$5:AA5) | AC5: =AB5>=VATThreshold | AD5: =IF(AC5,AA5/(1+VATRate),AA5) | AE5: =AA5-AD5 | AF5: =IF(AC5=0,0,IF(B5=1,SUMPRODUCT(--(($C$5:$C5=$C5-1)*($B$5:$B5>=10)*($B$5:$B5<=12)),$AE$5:$AE5),IF(B5=4,SUMPRODUCT(--(($C$5:$C5=$C5)*($B$5:$B5>=1)*($B$5:$B5<=3)),$AE$5:$AE5),IF(B5=7,SUMPRODUCT(--(($C$5:$C5=$C5)*($B$5:$B5>=4)*($B$5:$B5<=6)),$AE$5:$AE5),IF(B5=10,SUMPRODUCT(--(($C$5:$C5=$C5)*($B$5:$B5>=7)*($B$5:$B5<=9)),$AE$5:$AE5),0))))) | AG5: =AE5-AF5 | AH5: =IF(ProviderDelay>=1,0,AD5*ProviderShare) | AI5: =AA5*PaymentFee | AJ5: =U5*OpsAI | AK5: =MonthlyFixed | AL5: =I5*ReferralReward | AM5: =G5 | AN5: =AD5-AH5-AI5-AJ5-AK5-AL5-AM5 | AO5: =InitialInvestment+AA5-(AH5+AI5+AJ5+AK5+AL5+AM5+AF5) | AP5: =IF(U5>0,V5/U5,0) | AQ5: 0
A6: 2 | B6: =MOD(A6-1+LaunchMonth-1,12)+1 | C6: =INT((A6-1+LaunchMonth-1)/12)+1 | D6: =VLOOKUP(B6,SeasonTable,2,FALSE) | E6: =(1+InflationRate)^INT((A6-1)/12) | F6: =MonthlyChurn*VLOOKUP(B6,ChurnSeasonTable,4,FALSE) | G6: =MktFixed1_3 | H6: =IF(G6>0,MAX(1,ROUND(G6/CAC*D6,0)),0) | I6: =IF(H6>0,ROUND(H6*ReferralMix/(1-ReferralMix),0),0) | J6: =H6+I6 | K6: =ROUND(J6*(1-AnnualMix),0) | L6: =J6-K6 | M6: =ROUND(K6*EssentialMix,0) | N6: =K6-M6 | O6: =ROUND(L6*EssentialMix,0) | P6: =L6-O6 | Q6: =M6+M5 | R6: =N6+N5 | S6: =SUM(O$5:O6) | T6: =SUM(P$5:P6) | U6: =Q6+R6+S6+T6 | V6: =Q6*PriceEssMonthly*E6+R6*PricePremMonthly*E6+S6*PriceEssAnnual*E6/12+T6*PricePremAnnual*E6/12 | W6: =V6*12 | X6: =Q6*PriceEssMonthly*E6+R6*PricePremMonthly*E6 | Y6: =O6*PriceEssAnnual*E6+P6*PricePremAnnual*E6 | Z6: =0+0 | AA6: =X6+Y6+Z6 | AB6: =SUM(AA$5:AA6) | AC6: =OR(AC5,AB6>=VATThreshold) | AD6: =IF(AC6,AA6/(1+VATRate),AA6) | AE6: =AA6-AD6 | AF6: =IF(AC6=0,0,IF(B6=1,SUMPRODUCT(--(($C$5:$C6=$C6-1)*($B$5:$B6>=10)*($B$5:$B6<=12)),$AE$5:$AE6),IF(B6=4,SUMPRODUCT(--(($C$5:$C6=$C6)*($B$5:$B6>=1)*($B$5:$B6<=3)),$AE$5:$AE6),IF(B6=7,SUMPRODUCT(--(($C$5:$C6=$C6)*($B$5:$B6>=4)*($B$5:$B6<=6)),$AE$5:$AE6),IF(B6=10,SUMPRODUCT(--(($C$5:$C6=$C6)*($B$5:$B6>=7)*($B$5:$B6<=9)),$AE$5:$AE6),0))))) | AG6: =AG5+AE6-AF6 | AH6: =IF(ProviderDelay>=1,AD5*ProviderShare,AD6*ProviderShare) | AI6: =AA6*PaymentFee | AJ6: =U6*OpsAI | AK6: =MonthlyFixed | AL6: =I6*ReferralReward | AM6: =G6 | AN6: =AD6-AH6-AI6-AJ6-AK6-AL6-AM6 | AO6: =AO5+AA6-(AH6+AI6+AJ6+AK6+AL6+AM6+AF6) | AP6: =IF(U6>0,V6/U6,0) | AQ6: =IF(U5>0,MAX(0,(U5+J6-U6)/U5),0)
A7: 3 | B7: =MOD(A7-1+LaunchMonth-1,12)+1 | C7: =INT((A7-1+LaunchMonth-1)/12)+1 | D7: =VLOOKUP(B7,SeasonTable,2,FALSE) | E7: =(1+InflationRate)^INT((A7-1)/12) | F7: =MonthlyChurn*VLOOKUP(B7,ChurnSeasonTable,4,FALSE) | G7: =MktFixed1_3 | H7: =IF(G7>0,MAX(1,ROUND(G7/CAC*D7,0)),0) | I7: =IF(H7>0,ROUND(H7*ReferralMix/(1-ReferralMix),0),0) | J7: =H7+I7 | K7: =ROUND(J7*(1-AnnualMix),0) | L7: =J7-K7 | M7: =ROUND(K7*EssentialMix,0) | N7: =K7-M7 | O7: =ROUND(L7*EssentialMix,0) | P7: =L7-O7 | Q7: =M7+M6+M5 | R7: =N7+N6+N5 | S7: =SUM(O$5:O7) | T7: =SUM(P$5:P7) | U7: =Q7+R7+S7+T7 | V7: =Q7*PriceEssMonthly*E7+R7*PricePremMonthly*E7+S7*PriceEssAnnual*E7/12+T7*PricePremAnnual*E7/12 | W7: =V7*12 | X7: =Q7*PriceEssMonthly*E7+R7*PricePremMonthly*E7 | Y7: =O7*PriceEssAnnual*E7+P7*PricePremAnnual*E7 | Z7: =0+0 | AA7: =X7+Y7+Z7 | AB7: =SUM(AA$5:AA7) | AC7: =OR(AC6,AB7>=VATThreshold) | AD7: =IF(AC7,AA7/(1+VATRate),AA7) | AE7: =AA7-AD7 | AF7: =IF(AC7=0,0,IF(B7=1,SUMPRODUCT(--(($C$5:$C7=$C7-1)*($B$5:$B7>=10)*($B$5:$B7<=12)),$AE$5:$AE7),IF(B7=4,SUMPRODUCT(--(($C$5:$C7=$C7)*($B$5:$B7>=1)*($B$5:$B7<=3)),$AE$5:$AE7),IF(B7=7,SUMPRODUCT(--(($C$5:$C7=$C7)*($B$5:$B7>=4)*($B$5:$B7<=6)),$AE$5:$AE7),IF(B7=10,SUMPRODUCT(--(($C$5:$C7=$C7)*($B$5:$B7>=7)*($B$5:$B7<=9)),$AE$5:$AE7),0))))) | AG7: =AG6+AE7-AF7 | AH7: =IF(ProviderDelay>=1,AD6*ProviderShare,AD7*ProviderShare) | AI7: =AA7*PaymentFee | AJ7: =U7*OpsAI | AK7: =MonthlyFixed | AL7: =I7*ReferralReward | AM7: =G7 | AN7: =AD7-AH7-AI7-AJ7-AK7-AL7-AM7 | AO7: =AO6+AA7-(AH7+AI7+AJ7+AK7+AL7+AM7+AF7) | AP7: =IF(U7>0,V7/U7,0) | AQ7: =IF(U6>0,MAX(0,(U6+J7-U7)/U6),0)
A8: 4 | B8: =MOD(A8-1+LaunchMonth-1,12)+1 | C8: =INT((A8-1+LaunchMonth-1)/12)+1 | D8: =VLOOKUP(B8,SeasonTable,2,FALSE) | E8: =(1+InflationRate)^INT((A8-1)/12) | F8: =MonthlyChurn*VLOOKUP(B8,ChurnSeasonTable,4,FALSE) | G8: =MIN(MktFixed4_6,MAX(0,AO7-CashBuffer)) | H8: =IF(G8>0,MAX(1,ROUND(G8/CAC*D8,0)),0) | I8: =IF(H8>0,ROUND(H8*ReferralMix/(1-ReferralMix),0),0) | J8: =H8+I8 | K8: =ROUND(J8*(1-AnnualMix),0) | L8: =J8-K8 | M8: =ROUND(K8*EssentialMix,0) | N8: =K8-M8 | O8: =ROUND(L8*EssentialMix,0) | P8: =L8-O8 | Q8: =M8+M7+M6+MAX(0,Q7-M7-M6)*(1-F8) | R8: =N8+N7+N6+MAX(0,R7-N7-N6)*(1-F8) | S8: =SUM(O$5:O8) | T8: =SUM(P$5:P8) | U8: =Q8+R8+S8+T8 | V8: =Q8*PriceEssMonthly*E8+R8*PricePremMonthly*E8+S8*PriceEssAnnual*E8/12+T8*PricePremAnnual*E8/12 | W8: =V8*12 | X8: =Q8*PriceEssMonthly*E8+R8*PricePremMonthly*E8 | Y8: =O8*PriceEssAnnual*E8+P8*PricePremAnnual*E8 | Z8: =0+0 | AA8: =X8+Y8+Z8 | AB8: =SUM(AA$5:AA8) | AC8: =OR(AC7,AB8>=VATThreshold) | AD8: =IF(AC8,AA8/(1+VATRate),AA8) | AE8: =AA8-AD8 | AF8: =IF(AC8=0,0,IF(B8=1,SUMPRODUCT(--(($C$5:$C8=$C8-1)*($B$5:$B8>=10)*($B$5:$B8<=12)),$AE$5:$AE8),IF(B8=4,SUMPRODUCT(--(($C$5:$C8=$C8)*($B$5:$B8>=1)*($B$5:$B8<=3)),$AE$5:$AE8),IF(B8=7,SUMPRODUCT(--(($C$5:$C8=$C8)*($B$5:$B8>=4)*($B$5:$B8<=6)),$AE$5:$AE8),IF(B8=10,SUMPRODUCT(--(($C$5:$C8=$C8)*($B$5:$B8>=7)*($B$5:$B8<=9)),$AE$5:$AE8),0))))) | AG8: =AG7+AE8-AF8 | AH8: =IF(ProviderDelay>=1,AD7*ProviderShare,AD8*ProviderShare) | AI8: =AA8*PaymentFee | AJ8: =U8*OpsAI | AK8: =MonthlyFixed | AL8: =I8*ReferralReward | AM8: =G8 | AN8: =AD8-AH8-AI8-AJ8-AK8-AL8-AM8 | AO8: =AO7+AA8-(AH8+AI8+AJ8+AK8+AL8+AM8+AF8) | AP8: =IF(U8>0,V8/U8,0) | AQ8: =IF(U7>0,MAX(0,(U7+J8-U8)/U7),0)
A9: 5 | B9: =MOD(A9-1+LaunchMonth-1,12)+1 | C9: =INT((A9-1+LaunchMonth-1)/12)+1 | D9: =VLOOKUP(B9,SeasonTable,2,FALSE) | E9: =(1+InflationRate)^INT((A9-1)/12) | F9: =MonthlyChurn*VLOOKUP(B9,ChurnSeasonTable,4,FALSE) | G9: =MIN(MktFixed4_6,MAX(0,AO8-CashBuffer)) | H9: =IF(G9>0,MAX(1,ROUND(G9/CAC*D9,0)),0) | I9: =IF(H9>0,ROUND(H9*ReferralMix/(1-ReferralMix),0),0) | J9: =H9+I9 | K9: =ROUND(J9*(1-AnnualMix),0) | L9: =J9-K9 | M9: =ROUND(K9*EssentialMix,0) | N9: =K9-M9 | O9: =ROUND(L9*EssentialMix,0) | P9: =L9-O9 | Q9: =M9+M8+M7+MAX(0,Q8-M8-M7)*(1-F9) | R9: =N9+N8+N7+MAX(0,R8-N8-N7)*(1-F9) | S9: =SUM(O$5:O9) | T9: =SUM(P$5:P9) | U9: =Q9+R9+S9+T9 | V9: =Q9*PriceEssMonthly*E9+R9*PricePremMonthly*E9+S9*PriceEssAnnual*E9/12+T9*PricePremAnnual*E9/12 | W9: =V9*12 | X9: =Q9*PriceEssMonthly*E9+R9*PricePremMonthly*E9 | Y9: =O9*PriceEssAnnual*E9+P9*PricePremAnnual*E9 | Z9: =0+0 | AA9: =X9+Y9+Z9 | AB9: =SUM(AA$5:AA9) | AC9: =OR(AC8,AB9>=VATThreshold) | AD9: =IF(AC9,AA9/(1+VATRate),AA9) | AE9: =AA9-AD9 | AF9: =IF(AC9=0,0,IF(B9=1,SUMPRODUCT(--(($C$5:$C9=$C9-1)*($B$5:$B9>=10)*($B$5:$B9<=12)),$AE$5:$AE9),IF(B9=4,SUMPRODUCT(--(($C$5:$C9=$C9)*($B$5:$B9>=1)*($B$5:$B9<=3)),$AE$5:$AE9),IF(B9=7,SUMPRODUCT(--(($C$5:$C9=$C9)*($B$5:$B9>=4)*($B$5:$B9<=6)),$AE$5:$AE9),IF(B9=10,SUMPRODUCT(--(($C$5:$C9=$C9)*($B$5:$B9>=7)*($B$5:$B9<=9)),$AE$5:$AE9),0))))) | AG9: =AG8+AE9-AF9 | AH9: =IF(ProviderDelay>=1,AD8*ProviderShare,AD9*ProviderShare) | AI9: =AA9*PaymentFee | AJ9: =U9*OpsAI | AK9: =MonthlyFixed | AL9: =I9*ReferralReward | AM9: =G9 | AN9: =AD9-AH9-AI9-AJ9-AK9-AL9-AM9 | AO9: =AO8+AA9-(AH9+AI9+AJ9+AK9+AL9+AM9+AF9) | AP9: =IF(U9>0,V9/U9,0) | AQ9: =IF(U8>0,MAX(0,(U8+J9-U9)/U8),0)
A10: 6 | B10: =MOD(A10-1+LaunchMonth-1,12)+1 | C10: =INT((A10-1+LaunchMonth-1)/12)+1 | D10: =VLOOKUP(B10,SeasonTable,2,FALSE) | E10: =(1+InflationRate)^INT((A10-1)/12) | F10: =MonthlyChurn*VLOOKUP(B10,ChurnSeasonTable,4,FALSE) | G10: =MIN(MktFixed4_6,MAX(0,AO9-CashBuffer)) | H10: =IF(G10>0,MAX(1,ROUND(G10/CAC*D10,0)),0) | I10: =IF(H10>0,ROUND(H10*ReferralMix/(1-ReferralMix),0),0) | J10: =H10+I10 | K10: =ROUND(J10*(1-AnnualMix),0) | L10: =J10-K10 | M10: =ROUND(K10*EssentialMix,0) | N10: =K10-M10 | O10: =ROUND(L10*EssentialMix,0) | P10: =L10-O10 | Q10: =M10+M9+M8+MAX(0,Q9-M9-M8)*(1-F10) | R10: =N10+N9+N8+MAX(0,R9-N9-N8)*(1-F10) | S10: =SUM(O$5:O10) | T10: =SUM(P$5:P10) | U10: =Q10+R10+S10+T10 | V10: =Q10*PriceEssMonthly*E10+R10*PricePremMonthly*E10+S10*PriceEssAnnual*E10/12+T10*PricePremAnnual*E10/12 | W10: =V10*12 | X10: =Q10*PriceEssMonthly*E10+R10*PricePremMonthly*E10 | Y10: =O10*PriceEssAnnual*E10+P10*PricePremAnnual*E10 | Z10: =0+0 | AA10: =X10+Y10+Z10 | AB10: =SUM(AA$5:AA10) | AC10: =OR(AC9,AB10>=VATThreshold) | AD10: =IF(AC10,AA10/(1+VATRate),AA10) | AE10: =AA10-AD10 | AF10: =IF(AC10=0,0,IF(B10=1,SUMPRODUCT(--(($C$5:$C10=$C10-1)*($B$5:$B10>=10)*($B$5:$B10<=12)),$AE$5:$AE10),IF(B10=4,SUMPRODUCT(--(($C$5:$C10=$C10)*($B$5:$B10>=1)*($B$5:$B10<=3)),$AE$5:$AE10),IF(B10=7,SUMPRODUCT(--(($C$5:$C10=$C10)*($B$5:$B10>=4)*($B$5:$B10<=6)),$AE$5:$AE10),IF(B10=10,SUMPRODUCT(--(($C$5:$C10=$C10)*($B$5:$B10>=7)*($B$5:$B10<=9)),$AE$5:$AE10),0))))) | AG10: =AG9+AE10-AF10 | AH10: =IF(ProviderDelay>=1,AD9*ProviderShare,AD10*ProviderShare) | AI10: =AA10*PaymentFee | AJ10: =U10*OpsAI | AK10: =MonthlyFixed | AL10: =I10*ReferralReward | AM10: =G10 | AN10: =AD10-AH10-AI10-AJ10-AK10-AL10-AM10 | AO10: =AO9+AA10-(AH10+AI10+AJ10+AK10+AL10+AM10+AF10) | AP10: =IF(U10>0,V10/U10,0) | AQ10: =IF(U9>0,MAX(0,(U9+J10-U10)/U9),0)
A11: 7 | B11: =MOD(A11-1+LaunchMonth-1,12)+1 | C11: =INT((A11-1+LaunchMonth-1)/12)+1 | D11: =VLOOKUP(B11,SeasonTable,2,FALSE) | E11: =(1+InflationRate)^INT((A11-1)/12) | F11: =MonthlyChurn*VLOOKUP(B11,ChurnSeasonTable,4,FALSE) | G11: =MIN(MAX(MktMin7_12,AA10*MktPct7_12),MAX(0,AO10-CashBuffer)) | H11: =IF(G11>0,MAX(1,ROUND(G11/CAC*D11,0)),0) | I11: =IF(H11>0,ROUND(H11*ReferralMix/(1-ReferralMix),0),0) | J11: =H11+I11 | K11: =ROUND(J11*(1-AnnualMix),0) | L11: =J11-K11 | M11: =ROUND(K11*EssentialMix,0) | N11: =K11-M11 | O11: =ROUND(L11*EssentialMix,0) | P11: =L11-O11 | Q11: =M11+M10+M9+MAX(0,Q10-M10-M9)*(1-F11) | R11: =N11+N10+N9+MAX(0,R10-N10-N9)*(1-F11) | S11: =SUM(O$5:O11) | T11: =SUM(P$5:P11) | U11: =Q11+R11+S11+T11 | V11: =Q11*PriceEssMonthly*E11+R11*PricePremMonthly*E11+S11*PriceEssAnnual*E11/12+T11*PricePremAnnual*E11/12 | W11: =V11*12 | X11: =Q11*PriceEssMonthly*E11+R11*PricePremMonthly*E11 | Y11: =O11*PriceEssAnnual*E11+P11*PricePremAnnual*E11 | Z11: =0+0 | AA11: =X11+Y11+Z11 | AB11: =SUM(AA$5:AA11) | AC11: =OR(AC10,AB11>=VATThreshold) | AD11: =IF(AC11,AA11/(1+VATRate),AA11) | AE11: =AA11-AD11 | AF11: =IF(AC11=0,0,IF(B11=1,SUMPRODUCT(--(($C$5:$C11=$C11-1)*($B$5:$B11>=10)*($B$5:$B11<=12)),$AE$5:$AE11),IF(B11=4,SUMPRODUCT(--(($C$5:$C11=$C11)*($B$5:$B11>=1)*($B$5:$B11<=3)),$AE$5:$AE11),IF(B11=7,SUMPRODUCT(--(($C$5:$C11=$C11)*($B$5:$B11>=4)*($B$5:$B11<=6)),$AE$5:$AE11),IF(B11=10,SUMPRODUCT(--(($C$5:$C11=$C11)*($B$5:$B11>=7)*($B$5:$B11<=9)),$AE$5:$AE11),0))))) | AG11: =AG10+AE11-AF11 | AH11: =IF(ProviderDelay>=1,AD10*ProviderShare,AD11*ProviderShare) | AI11: =AA11*PaymentFee | AJ11: =U11*OpsAI | AK11: =MonthlyFixed | AL11: =I11*ReferralReward | AM11: =G11 | AN11: =AD11-AH11-AI11-AJ11-AK11-AL11-AM11 | AO11: =AO10+AA11-(AH11+AI11+AJ11+AK11+AL11+AM11+AF11) | AP11: =IF(U11>0,V11/U11,0) | AQ11: =IF(U10>0,MAX(0,(U10+J11-U11)/U10),0)
A12: 8 | B12: =MOD(A12-1+LaunchMonth-1,12)+1 | C12: =INT((A12-1+LaunchMonth-1)/12)+1 | D12: =VLOOKUP(B12,SeasonTable,2,FALSE) | E12: =(1+InflationRate)^INT((A12-1)/12) | F12: =MonthlyChurn*VLOOKUP(B12,ChurnSeasonTable,4,FALSE) | G12: =MIN(MAX(MktMin7_12,AA11*MktPct7_12),MAX(0,AO11-CashBuffer)) | H12: =IF(G12>0,MAX(1,ROUND(G12/CAC*D12,0)),0) | I12: =IF(H12>0,ROUND(H12*ReferralMix/(1-ReferralMix),0),0) | J12: =H12+I12 | K12: =ROUND(J12*(1-AnnualMix),0) | L12: =J12-K12 | M12: =ROUND(K12*EssentialMix,0) | N12: =K12-M12 | O12: =ROUND(L12*EssentialMix,0) | P12: =L12-O12 | Q12: =M12+M11+M10+MAX(0,Q11-M11-M10)*(1-F12) | R12: =N12+N11+N10+MAX(0,R11-N11-N10)*(1-F12) | S12: =SUM(O$5:O12) | T12: =SUM(P$5:P12) | U12: =Q12+R12+S12+T12 | V12: =Q12*PriceEssMonthly*E12+R12*PricePremMonthly*E12+S12*PriceEssAnnual*E12/12+T12*PricePremAnnual*E12/12 | W12: =V12*12 | X12: =Q12*PriceEssMonthly*E12+R12*PricePremMonthly*E12 | Y12: =O12*PriceEssAnnual*E12+P12*PricePremAnnual*E12 | Z12: =0+0 | AA12: =X12+Y12+Z12 | AB12: =SUM(AA$5:AA12) | AC12: =OR(AC11,AB12>=VATThreshold) | AD12: =IF(AC12,AA12/(1+VATRate),AA12) | AE12: =AA12-AD12 | AF12: =IF(AC12=0,0,IF(B12=1,SUMPRODUCT(--(($C$5:$C12=$C12-1)*($B$5:$B12>=10)*($B$5:$B12<=12)),$AE$5:$AE12),IF(B12=4,SUMPRODUCT(--(($C$5:$C12=$C12)*($B$5:$B12>=1)*($B$5:$B12<=3)),$AE$5:$AE12),IF(B12=7,SUMPRODUCT(--(($C$5:$C12=$C12)*($B$5:$B12>=4)*($B$5:$B12<=6)),$AE$5:$AE12),IF(B12=10,SUMPRODUCT(--(($C$5:$C12=$C12)*($B$5:$B12>=7)*($B$5:$B12<=9)),$AE$5:$AE12),0))))) | AG12: =AG11+AE12-AF12 | AH12: =IF(ProviderDelay>=1,AD11*ProviderShare,AD12*ProviderShare) | AI12: =AA12*PaymentFee | AJ12: =U12*OpsAI | AK12: =MonthlyFixed | AL12: =I12*ReferralReward | AM12: =G12 | AN12: =AD12-AH12-AI12-AJ12-AK12-AL12-AM12 | AO12: =AO11+AA12-(AH12+AI12+AJ12+AK12+AL12+AM12+AF12) | AP12: =IF(U12>0,V12/U12,0) | AQ12: =IF(U11>0,MAX(0,(U11+J12-U12)/U11),0)
A13: 9 | B13: =MOD(A13-1+LaunchMonth-1,12)+1 | C13: =INT((A13-1+LaunchMonth-1)/12)+1 | D13: =VLOOKUP(B13,SeasonTable,2,FALSE) | E13: =(1+InflationRate)^INT((A13-1)/12) | F13: =MonthlyChurn*VLOOKUP(B13,ChurnSeasonTable,4,FALSE) | G13: =MIN(MAX(MktMin7_12,AA12*MktPct7_12),MAX(0,AO12-CashBuffer)) | H13: =IF(G13>0,MAX(1,ROUND(G13/CAC*D13,0)),0) | I13: =IF(H13>0,ROUND(H13*ReferralMix/(1-ReferralMix),0),0) | J13: =H13+I13 | K13: =ROUND(J13*(1-AnnualMix),0) | L13: =J13-K13 | M13: =ROUND(K13*EssentialMix,0) | N13: =K13-M13 | O13: =ROUND(L13*EssentialMix,0) | P13: =L13-O13 | Q13: =M13+M12+M11+MAX(0,Q12-M12-M11)*(1-F13) | R13: =N13+N12+N11+MAX(0,R12-N12-N11)*(1-F13) | S13: =SUM(O$5:O13) | T13: =SUM(P$5:P13) | U13: =Q13+R13+S13+T13 | V13: =Q13*PriceEssMonthly*E13+R13*PricePremMonthly*E13+S13*PriceEssAnnual*E13/12+T13*PricePremAnnual*E13/12 | W13: =V13*12 | X13: =Q13*PriceEssMonthly*E13+R13*PricePremMonthly*E13 | Y13: =O13*PriceEssAnnual*E13+P13*PricePremAnnual*E13 | Z13: =0+0 | AA13: =X13+Y13+Z13 | AB13: =SUM(AA$5:AA13) | AC13: =OR(AC12,AB13>=VATThreshold) | AD13: =IF(AC13,AA13/(1+VATRate),AA13) | AE13: =AA13-AD13 | AF13: =IF(AC13=0,0,IF(B13=1,SUMPRODUCT(--(($C$5:$C13=$C13-1)*($B$5:$B13>=10)*($B$5:$B13<=12)),$AE$5:$AE13),IF(B13=4,SUMPRODUCT(--(($C$5:$C13=$C13)*($B$5:$B13>=1)*($B$5:$B13<=3)),$AE$5:$AE13),IF(B13=7,SUMPRODUCT(--(($C$5:$C13=$C13)*($B$5:$B13>=4)*($B$5:$B13<=6)),$AE$5:$AE13),IF(B13=10,SUMPRODUCT(--(($C$5:$C13=$C13)*($B$5:$B13>=7)*($B$5:$B13<=9)),$AE$5:$AE13),0))))) | AG13: =AG12+AE13-AF13 | AH13: =IF(ProviderDelay>=1,AD12*ProviderShare,AD13*ProviderShare) | AI13: =AA13*PaymentFee | AJ13: =U13*OpsAI | AK13: =MonthlyFixed | AL13: =I13*ReferralReward | AM13: =G13 | AN13: =AD13-AH13-AI13-AJ13-AK13-AL13-AM13 | AO13: =AO12+AA13-(AH13+AI13+AJ13+AK13+AL13+AM13+AF13) | AP13: =IF(U13>0,V13/U13,0) | AQ13: =IF(U12>0,MAX(0,(U12+J13-U13)/U12),0)
A14: 10 | B14: =MOD(A14-1+LaunchMonth-1,12)+1 | C14: =INT((A14-1+LaunchMonth-1)/12)+1 | D14: =VLOOKUP(B14,SeasonTable,2,FALSE) | E14: =(1+InflationRate)^INT((A14-1)/12) | F14: =MonthlyChurn*VLOOKUP(B14,ChurnSeasonTable,4,FALSE) | G14: =MIN(MAX(MktMin7_12,AA13*MktPct7_12),MAX(0,AO13-CashBuffer)) | H14: =IF(G14>0,MAX(1,ROUND(G14/CAC*D14,0)),0) | I14: =IF(H14>0,ROUND(H14*ReferralMix/(1-ReferralMix),0),0) | J14: =H14+I14 | K14: =ROUND(J14*(1-AnnualMix),0) | L14: =J14-K14 | M14: =ROUND(K14*EssentialMix,0) | N14: =K14-M14 | O14: =ROUND(L14*EssentialMix,0) | P14: =L14-O14 | Q14: =M14+M13+M12+MAX(0,Q13-M13-M12)*(1-F14) | R14: =N14+N13+N12+MAX(0,R13-N13-N12)*(1-F14) | S14: =SUM(O$5:O14) | T14: =SUM(P$5:P14) | U14: =Q14+R14+S14+T14 | V14: =Q14*PriceEssMonthly*E14+R14*PricePremMonthly*E14+S14*PriceEssAnnual*E14/12+T14*PricePremAnnual*E14/12 | W14: =V14*12 | X14: =Q14*PriceEssMonthly*E14+R14*PricePremMonthly*E14 | Y14: =O14*PriceEssAnnual*E14+P14*PricePremAnnual*E14 | Z14: =0+0 | AA14: =X14+Y14+Z14 | AB14: =SUM(AA$5:AA14) | AC14: =OR(AC13,AB14>=VATThreshold) | AD14: =IF(AC14,AA14/(1+VATRate),AA14) | AE14: =AA14-AD14 | AF14: =IF(AC14=0,0,IF(B14=1,SUMPRODUCT(--(($C$5:$C14=$C14-1)*($B$5:$B14>=10)*($B$5:$B14<=12)),$AE$5:$AE14),IF(B14=4,SUMPRODUCT(--(($C$5:$C14=$C14)*($B$5:$B14>=1)*($B$5:$B14<=3)),$AE$5:$AE14),IF(B14=7,SUMPRODUCT(--(($C$5:$C14=$C14)*($B$5:$B14>=4)*($B$5:$B14<=6)),$AE$5:$AE14),IF(B14=10,SUMPRODUCT(--(($C$5:$C14=$C14)*($B$5:$B14>=7)*($B$5:$B14<=9)),$AE$5:$AE14),0))))) | AG14: =AG13+AE14-AF14 | AH14: =IF(ProviderDelay>=1,AD13*ProviderShare,AD14*ProviderShare) | AI14: =AA14*PaymentFee | AJ14: =U14*OpsAI | AK14: =MonthlyFixed | AL14: =I14*ReferralReward | AM14: =G14 | AN14: =AD14-AH14-AI14-AJ14-AK14-AL14-AM14 | AO14: =AO13+AA14-(AH14+AI14+AJ14+AK14+AL14+AM14+AF14) | AP14: =IF(U14>0,V14/U14,0) | AQ14: =IF(U13>0,MAX(0,(U13+J14-U14)/U13),0)
A15: 11 | B15: =MOD(A15-1+LaunchMonth-1,12)+1 | C15: =INT((A15-1+LaunchMonth-1)/12)+1 | D15: =VLOOKUP(B15,SeasonTable,2,FALSE) | E15: =(1+InflationRate)^INT((A15-1)/12) | F15: =MonthlyChurn*VLOOKUP(B15,ChurnSeasonTable,4,FALSE) | G15: =MIN(MAX(MktMin7_12,AA14*MktPct7_12),MAX(0,AO14-CashBuffer)) | H15: =IF(G15>0,MAX(1,ROUND(G15/CAC*D15,0)),0) | I15: =IF(H15>0,ROUND(H15*ReferralMix/(1-ReferralMix),0),0) | J15: =H15+I15 | K15: =ROUND(J15*(1-AnnualMix),0) | L15: =J15-K15 | M15: =ROUND(K15*EssentialMix,0) | N15: =K15-M15 | O15: =ROUND(L15*EssentialMix,0) | P15: =L15-O15 | Q15: =M15+M14+M13+MAX(0,Q14-M14-M13)*(1-F15) | R15: =N15+N14+N13+MAX(0,R14-N14-N13)*(1-F15) | S15: =SUM(O$5:O15) | T15: =SUM(P$5:P15) | U15: =Q15+R15+S15+T15 | V15: =Q15*PriceEssMonthly*E15+R15*PricePremMonthly*E15+S15*PriceEssAnnual*E15/12+T15*PricePremAnnual*E15/12 | W15: =V15*12 | X15: =Q15*PriceEssMonthly*E15+R15*PricePremMonthly*E15 | Y15: =O15*PriceEssAnnual*E15+P15*PricePremAnnual*E15 | Z15: =0+0 | AA15: =X15+Y15+Z15 | AB15: =SUM(AA$5:AA15) | AC15: =OR(AC14,AB15>=VATThreshold) | AD15: =IF(AC15,AA15/(1+VATRate),AA15) | AE15: =AA15-AD15 | AF15: =IF(AC15=0,0,IF(B15=1,SUMPRODUCT(--(($C$5:$C15=$C15-1)*($B$5:$B15>=10)*($B$5:$B15<=12)),$AE$5:$AE15),IF(B15=4,SUMPRODUCT(--(($C$5:$C15=$C15)*($B$5:$B15>=1)*($B$5:$B15<=3)),$AE$5:$AE15),IF(B15=7,SUMPRODUCT(--(($C$5:$C15=$C15)*($B$5:$B15>=4)*($B$5:$B15<=6)),$AE$5:$AE15),IF(B15=10,SUMPRODUCT(--(($C$5:$C15=$C15)*($B$5:$B15>=7)*($B$5:$B15<=9)),$AE$5:$AE15),0))))) | AG15: =AG14+AE15-AF15 | AH15: =IF(ProviderDelay>=1,AD14*ProviderShare,AD15*ProviderShare) | AI15: =AA15*PaymentFee | AJ15: =U15*OpsAI | AK15: =MonthlyFixed | AL15: =I15*ReferralReward | AM15: =G15 | AN15: =AD15-AH15-AI15-AJ15-AK15-AL15-AM15 | AO15: =AO14+AA15-(AH15+AI15+AJ15+AK15+AL15+AM15+AF15) | AP15: =IF(U15>0,V15/U15,0) | AQ15: =IF(U14>0,MAX(0,(U14+J15-U15)/U14),0)
A16: 12 | B16: =MOD(A16-1+LaunchMonth-1,12)+1 | C16: =INT((A16-1+LaunchMonth-1)/12)+1 | D16: =VLOOKUP(B16,SeasonTable,2,FALSE) | E16: =(1+InflationRate)^INT((A16-1)/12) | F16: =MonthlyChurn*VLOOKUP(B16,ChurnSeasonTable,4,FALSE) | G16: =MIN(MAX(MktMin7_12,AA15*MktPct7_12),MAX(0,AO15-CashBuffer)) | H16: =IF(G16>0,MAX(1,ROUND(G16/CAC*D16,0)),0) | I16: =IF(H16>0,ROUND(H16*ReferralMix/(1-ReferralMix),0),0) | J16: =H16+I16 | K16: =ROUND(J16*(1-AnnualMix),0) | L16: =J16-K16 | M16: =ROUND(K16*EssentialMix,0) | N16: =K16-M16 | O16: =ROUND(L16*EssentialMix,0) | P16: =L16-O16 | Q16: =M16+M15+M14+MAX(0,Q15-M15-M14)*(1-F16) | R16: =N16+N15+N14+MAX(0,R15-N15-N14)*(1-F16) | S16: =SUM(O$5:O16) | T16: =SUM(P$5:P16) | U16: =Q16+R16+S16+T16 | V16: =Q16*PriceEssMonthly*E16+R16*PricePremMonthly*E16+S16*PriceEssAnnual*E16/12+T16*PricePremAnnual*E16/12 | W16: =V16*12 | X16: =Q16*PriceEssMonthly*E16+R16*PricePremMonthly*E16 | Y16: =O16*PriceEssAnnual*E16+P16*PricePremAnnual*E16 | Z16: =0+0 | AA16: =X16+Y16+Z16 | AB16: =SUM(AA5:AA16) | AC16: =OR(AC15,AB16>=VATThreshold) | AD16: =IF(AC16,AA16/(1+VATRate),AA16) | AE16: =AA16-AD16 | AF16: =IF(AC16=0,0,IF(B16=1,SUMPRODUCT(--(($C$5:$C16=$C16-1)*($B$5:$B16>=10)*($B$5:$B16<=12)),$AE$5:$AE16),IF(B16=4,SUMPRODUCT(--(($C$5:$C16=$C16)*($B$5:$B16>=1)*($B$5:$B16<=3)),$AE$5:$AE16),IF(B16=7,SUMPRODUCT(--(($C$5:$C16=$C16)*($B$5:$B16>=4)*($B$5:$B16<=6)),$AE$5:$AE16),IF(B16=10,SUMPRODUCT(--(($C$5:$C16=$C16)*($B$5:$B16>=7)*($B$5:$B16<=9)),$AE$5:$AE16),0))))) | AG16: =AG15+AE16-AF16 | AH16: =IF(ProviderDelay>=1,AD15*ProviderShare,AD16*ProviderShare) | AI16: =AA16*PaymentFee | AJ16: =U16*OpsAI | AK16: =MonthlyFixed | AL16: =I16*ReferralReward | AM16: =G16 | AN16: =AD16-AH16-AI16-AJ16-AK16-AL16-AM16 | AO16: =AO15+AA16-(AH16+AI16+AJ16+AK16+AL16+AM16+AF16) | AP16: =IF(U16>0,V16/U16,0) | AQ16: =IF(U15>0,MAX(0,(U15+J16-U16)/U15),0)
A17: 13 | B17: =MOD(A17-1+LaunchMonth-1,12)+1 | C17: =INT((A17-1+LaunchMonth-1)/12)+1 | D17: =VLOOKUP(B17,SeasonTable,2,FALSE) | E17: =(1+InflationRate)^INT((A17-1)/12) | F17: =MonthlyChurn*VLOOKUP(B17,ChurnSeasonTable,4,FALSE) | G17: =MIN(MAX(MktMin13_18,AA16*MktPct13_18),MAX(0,AO16-CashBuffer)) | H17: =IF(G17>0,MAX(1,ROUND(G17/CAC*D17,0)),0) | I17: =IF(H17>0,ROUND(H17*ReferralMix/(1-ReferralMix),0),0) | J17: =H17+I17 | K17: =ROUND(J17*(1-AnnualMix),0) | L17: =J17-K17 | M17: =ROUND(K17*EssentialMix,0) | N17: =K17-M17 | O17: =ROUND(L17*EssentialMix,0) | P17: =L17-O17 | Q17: =M17+M16+M15+MAX(0,Q16-M16-M15)*(1-F17) | R17: =N17+N16+N15+MAX(0,R16-N16-N15)*(1-F17) | S17: =S16+O17-O5*(AnnualChurn*VLOOKUP(B17,ChurnSeasonTable,4,FALSE))*POWER(1-(AnnualChurn*VLOOKUP(B17,ChurnSeasonTable,4,FALSE)),0) | T17: =T16+P17-P5*(AnnualChurn*VLOOKUP(B17,ChurnSeasonTable,4,FALSE))*POWER(1-(AnnualChurn*VLOOKUP(B17,ChurnSeasonTable,4,FALSE)),0) | U17: =Q17+R17+S17+T17 | V17: =Q17*PriceEssMonthly*E17+R17*PricePremMonthly*E17+S17*PriceEssAnnual*E17/12+T17*PricePremAnnual*E17/12 | W17: =V17*12 | X17: =Q17*PriceEssMonthly*E17+R17*PricePremMonthly*E17 | Y17: =O17*PriceEssAnnual*E17+P17*PricePremAnnual*E17 | Z17: =O5*POWER(1-(AnnualChurn*VLOOKUP(B17,ChurnSeasonTable,4,FALSE)),1)*PriceEssAnnual*E17+P5*POWER(1-(AnnualChurn*VLOOKUP(B17,ChurnSeasonTable,4,FALSE)),1)*PricePremAnnual*E17 | AA17: =X17+Y17+Z17 | AB17: =SUM(AA6:AA17) | AC17: =OR(AC16,AB17>=VATThreshold) | AD17: =IF(AC17,AA17/(1+VATRate),AA17) | AE17: =AA17-AD17 | AF17: =IF(AC17=0,0,IF(B17=1,SUMPRODUCT(--(($C$5:$C17=$C17-1)*($B$5:$B17>=10)*($B$5:$B17<=12)),$AE$5:$AE17),IF(B17=4,SUMPRODUCT(--(($C$5:$C17=$C17)*($B$5:$B17>=1)*($B$5:$B17<=3)),$AE$5:$AE17),IF(B17=7,SUMPRODUCT(--(($C$5:$C17=$C17)*($B$5:$B17>=4)*($B$5:$B17<=6)),$AE$5:$AE17),IF(B17=10,SUMPRODUCT(--(($C$5:$C17=$C17)*($B$5:$B17>=7)*($B$5:$B17<=9)),$AE$5:$AE17),0))))) | AG17: =AG16+AE17-AF17 | AH17: =IF(ProviderDelay>=1,AD16*ProviderShare,AD17*ProviderShare) | AI17: =AA17*PaymentFee | AJ17: =U17*OpsAI | AK17: =MonthlyFixed | AL17: =I17*ReferralReward | AM17: =G17 | AN17: =AD17-AH17-AI17-AJ17-AK17-AL17-AM17 | AO17: =AO16+AA17-(AH17+AI17+AJ17+AK17+AL17+AM17+AF17) | AP17: =IF(U17>0,V17/U17,0) | AQ17: =IF(U16>0,MAX(0,(U16+J17-U17)/U16),0)
A18: 14 | B18: =MOD(A18-1+LaunchMonth-1,12)+1 | C18: =INT((A18-1+LaunchMonth-1)/12)+1 | D18: =VLOOKUP(B18,SeasonTable,2,FALSE) | E18: =(1+InflationRate)^INT((A18-1)/12) | F18: =MonthlyChurn*VLOOKUP(B18,ChurnSeasonTable,4,FALSE) | G18: =MIN(MAX(MktMin13_18,AA17*MktPct13_18),MAX(0,AO17-CashBuffer)) | H18: =IF(G18>0,MAX(1,ROUND(G18/CAC*D18,0)),0) | I18: =IF(H18>0,ROUND(H18*ReferralMix/(1-ReferralMix),0),0) | J18: =H18+I18 | K18: =ROUND(J18*(1-AnnualMix),0) | L18: =J18-K18 | M18: =ROUND(K18*EssentialMix,0) | N18: =K18-M18 | O18: =ROUND(L18*EssentialMix,0) | P18: =L18-O18 | Q18: =M18+M17+M16+MAX(0,Q17-M17-M16)*(1-F18) | R18: =N18+N17+N16+MAX(0,R17-N17-N16)*(1-F18) | S18: =S17+O18-O6*(AnnualChurn*VLOOKUP(B18,ChurnSeasonTable,4,FALSE))*POWER(1-(AnnualChurn*VLOOKUP(B18,ChurnSeasonTable,4,FALSE)),0) | T18: =T17+P18-P6*(AnnualChurn*VLOOKUP(B18,ChurnSeasonTable,4,FALSE))*POWER(1-(AnnualChurn*VLOOKUP(B18,ChurnSeasonTable,4,FALSE)),0) | U18: =Q18+R18+S18+T18 | V18: =Q18*PriceEssMonthly*E18+R18*PricePremMonthly*E18+S18*PriceEssAnnual*E18/12+T18*PricePremAnnual*E18/12 | W18: =V18*12 | X18: =Q18*PriceEssMonthly*E18+R18*PricePremMonthly*E18 | Y18: =O18*PriceEssAnnual*E18+P18*PricePremAnnual*E18 | Z18: =O6*POWER(1-(AnnualChurn*VLOOKUP(B18,ChurnSeasonTable,4,FALSE)),1)*PriceEssAnnual*E18+P6*POWER(1-(AnnualChurn*VLOOKUP(B18,ChurnSeasonTable,4,FALSE)),1)*PricePremAnnual*E18 | AA18: =X18+Y18+Z18 | AB18: =SUM(AA7:AA18) | AC18: =OR(AC17,AB18>=VATThreshold) | AD18: =IF(AC18,AA18/(1+VATRate),AA18) | AE18: =AA18-AD18 | AF18: =IF(AC18=0,0,IF(B18=1,SUMPRODUCT(--(($C$5:$C18=$C18-1)*($B$5:$B18>=10)*($B$5:$B18<=12)),$AE$5:$AE18),IF(B18=4,SUMPRODUCT(--(($C$5:$C18=$C18)*($B$5:$B18>=1)*($B$5:$B18<=3)),$AE$5:$AE18),IF(B18=7,SUMPRODUCT(--(($C$5:$C18=$C18)*($B$5:$B18>=4)*($B$5:$B18<=6)),$AE$5:$AE18),IF(B18=10,SUMPRODUCT(--(($C$5:$C18=$C18)*($B$5:$B18>=7)*($B$5:$B18<=9)),$AE$5:$AE18),0))))) | AG18: =AG17+AE18-AF18 | AH18: =IF(ProviderDelay>=1,AD17*ProviderShare,AD18*ProviderShare) | AI18: =AA18*PaymentFee | AJ18: =U18*OpsAI | AK18: =MonthlyFixed | AL18: =I18*ReferralReward | AM18: =G18 | AN18: =AD18-AH18-AI18-AJ18-AK18-AL18-AM18 | AO18: =AO17+AA18-(AH18+AI18+AJ18+AK18+AL18+AM18+AF18) | AP18: =IF(U18>0,V18/U18,0) | AQ18: =IF(U17>0,MAX(0,(U17+J18-U18)/U17),0)
